Workbook

Sheet Modelo dominio anémico contexto

Sheet Listado Objetos de Dominio
A1: Subdominio/Contexto:
A2: Nombre | B2: Descripción | C2: Muestreo | D2: Caracterización
A3: Calificación | B3: Objeto de dominio que representa la valoración numérica dada a un servicio | C3: ver | D3: ver | E3: 1
A4: Categoría | B4: Objeto de dominio que representa la clasificación por Categoría las motocicletas según su tipo o uso. | C4: ver | D4: ver | E4: 2
A5: Ciudad | B5: Objeto de dominio que representa la ciudad donde se encuentra ubicada la sede. | C5: ver | D5: ver | E5: 3
A6: Departamento | B6: Objeto de dominio que representa la división territorial donde se encuentra la ciudad. | C6: ver | D6: ver | E6: 4
A7: Detalle Horario | B7: Objeto de dominio que representa la información específica de los horarios de atención de la sede. | C7: ver | D7: ver | E7: 5
A8: Dia | B8: Objeto de dominio que representa cada uno de los días de la semana en que opera una sede. | C8: ver | D8: ver | E8: 6
A9: Diagnostico | B9: Objeto de dominio que representa la evaluación técnica realizada a una motocicleta por parte de una sede. | C9: ver | D9: ver | E9: 7
A10: Franquicia | B10: Objeto de dominio que representa el nombre comercial de la franquicia que ofrece servicios para motocicletas. | C10: ver | D10: ver | E10: 8
A11: Represéntate sede | B11: Objeto de dominio que representa la persona responsable de gestionar una sede específica de una sede. | C11: ver | D11: ver | E11: 9
A12: Servicio sede | B12: Objeto de dominio que representa la relación entre una sede y los servicios que ofrece. | C12: ver | D12: ver | E12: 10
A13: Estado Servicio Realizado | B13: Objeto de dominio que representa el estado actual de un servicio en proceso o finalizado. | C13: ver | D13: ver | E13: 11
A14: Excepción Horario | B14: Objeto de dominio que representa las excepciones o casos especiales en los horarios de atención. | C14: ver | D14: ver | E14: 12
... A32: Transición Estado Servicio Realizado | B32: Objeto de dominio que gestiona las transiciones de estados de un servicio | C32: ver | D32: ver | E32: 30

Sheet Caracterizacion
A2: Tipo de Dato | B2: Longitud | C2: Precisión | D2: Rango | E2: Formato | F2: Valor por defecto | G2: Regla especial | H2: SI y No | I2: UUID
A3: Alfanumérico | B3: 0 | C3: 1 | D3: 50 | E3: DD/MM/YYYY | F3: 31/12/2028 | H3: SI
A4: Numérico entero | B4: 1 | C4: 2 | D4: 201 | E4: DD-MM-YYYY | H4: NO | J4: Valor | K4: 0.1 | L4: 0.2 | M4: 0.3
A5: Numérico decimal | B5: 2 | C5: 3 | D5: 401 | E5: YYYY-MM-DD (ISO 8601) | J5: 25 | K5: =ROUNDUP($J$5*K4,0) -> 3 | L5: =ROUNDUP($J$5*L4,0) -> 5 | M5: =ROUNDUP($J$5*M4,0) -> 8
A6: Texto | B6: 3 | C6: 4 | D6: 200 | E6: DD/MM/YYYY HH:mm:ss | J6: 7 | K6: =ROUND($J$6*K4,0) -> 1 | L6: =ROUND($J$6*L4,0) -> 1 | M6: =ROUND($J$6*M4,0) -> 2
A7: Carácter | B7: 4 | C7: 5 | D7: 400 | E7: HH:mm:ss (24 horas)
A8: Booleano | B8: 5 | C8: 6 | D8: 3000 | E8: HH:mm:ss.SSS (con milisegundos)
A9: Fecha | B9: 6 | C9: 7 | D9: 1 | E9: hh:mm:ss a (12 horas con AM/PM) | U9: UUID 9
A10: Hora | B10: 7 | C10: 8 | D10: 2 | E10: UUID | U10: UUID 10
A11: Fecha/Hora | B11: 8 | C11: 9 | D11: 3 | E11: UPPERCASE | U11: UUID 11
A12: Array | B12: 9 | C12: 10 | D12: 4 | E12: lowercase | U12: UUID 12
A13: Objeto | B13: 10 | C13: 11 | D13: 5 | E13: Título Case | U13: UUID 13
A14: UUID | B14: 11 | C14: 12 | D14: 0 | E14: camelCase | U14: UUID 14
A15: calificacion | B15: 12 | C15: 13 | E15: snake_case | U15: UUID 15
A16: categoria | B16: 13 | C16: 14 | E16: kebab-case | U16: UUID 16
A17: ciudad | B17: 14 | C17: 15 | E17: PascalCase | U17: UUID 17
A18: departamento | B18: 15 | C18: 28 | E18: Teléfono (+XX XXX XXX XXXX) | U18: UUID 18
A19: detalleHorario | B19: 16 | C19: 90 | E19: Email (usuario@dominio.com) | U19: UUID 19
A20: dia | B20: 17 | C20: -90 | E20: URL (https://www.dominio.com) | U20: UUID 20
A21: diagnostico | B21: 18 | C21: 180 | U21: UUID 21
A22: franquicia | B22: 19 | C22: -180 | U22: UUID 22
A23: sedeServicio | B23: 20 | U23: UUID 23
A24: estadoServicioRealizado | B24: 21 | U24: UUID 24
A25: excepcion | B25: 22 | U25: UUID 25
A26: evidencia fotográfica | B26: 23 | U26: UUID 26
A27: horarioSede | B27: 24 | U27: UUID 27
A28: imagen | B28: 25 | U28: UUID 28
A29: linea | B29: 26 | U29: UUID 29
A30: lineaCategoria | B30: 27 | U30: UUID 30
A31: marca | B31: 28 | U31: UUID 31
A32: referencia | B32: 29 | U32: UUID 32
A33: motocicleta | B33: 30 | U33: UUID 33
A34: rangoCalificacion | B34: 31 | U34: UUID 34
... A43: sede | B43: 40 | U43: UUID 43
B44: 41 | U44: UUID 44
B45: 42 | U45: UUID 45
B46: 43 | U46: UUID 46
B47: 44 | U47: UUID 47
B48: 45 | U48: UUID 48
B49: 46 | U49: UUID 49
...

Sheet Valores
A1: Tipo Objeto Dominio
A2: Tipo | B2: Descripción
A3: Propio | B3: Cuando el objeto de dominio es parte del contexto actual
A4: Referenciado | B4: Cuando el objeto de dominio es parte de otro contexto

Sheet Categoría Muestreo
A2: Corresponde al identificador único que va a permitir diferenciar cada una de las categorías de motocicletas en el sistema | B2: Corresponde al atributo que clasifica una motocicleta por categoría según sus características y uso principal | C2: El nombre de la categoría no debe de tener duplicidad en el registro de categorías de motocicletas
A3: id | B3: nombre | C3: Combinación única
A4: 51f36e6d-904d-49d4-958b-074d134a40c5 | B4: Automáticas y Semiautomáticas | C4: Automáticas y Semiautomáticas
A5: 3c5fb5ab-c8a1-40ac-bfd2-c34dc5dadd62 | B5: Urbana | C5: Urbana
A6: dd2cf3d4-9df7-4656-ba06-42c052cceaef | B6: Todoterreno | C6: Todoterreno
A7: 7c81b48c-5547-4ada-95b9-5b829b7cadf1 | B7: Deportiva | C7: Deportiva
A8: 86ed717d-8489-4860-80c7-e4f9f24c1e08 | B8: SuperDeportiva | C8: SuperDeportiva
A9: 29618b5d-4716-4c09-b8e9-cd1f196e8ec4 | B9: Adventure | C9: Adventure
A10: b08af03b-7556-45a6-9caa-eae411cd0702 | B10: Sport Heritage | C10: Sport Heritage
A11: 375e0b5f-951a-4037-9eda-c9de98dc84da | B11: Motocross y Enduro | C11: Motocross y Enduro
A12: da9dc0cf-01fb-4396-ad33-c961ecddf7a4 | B12: Electrica | C12: Electrica

Sheet Categoría Caracterización
A1: <-Volver al inicio
A2: Objeto de Dominio: | B2: ='Listado Objetos de Dominio'!$A$4 -> Categoría
A3: Descripción: | B3: ='Listado Objetos de Dominio'!B4 -> Objeto de dominio que representa la clasificación por Categoría las motocicletas según su tipo o uso.
A4: Atributo | B4: Tipo de Dato | C4: Longitud mínima | D4: Longitud máxima | E4: Precisión | F4: Rango Inicial | G4: Rango Final | H4: Formato | I4: Descripción Formato | J4: Valor por defecto | K4: Regla especial | L4: ¿Quitar espacios en blanco al inicio? | M4: ¿Quitar espacios en blanco al final? | N4: ¿Auto generado? | O4: ¿Calculado? | P4: ¿Obligatorio? | Q4: ¿Sensible? | R4: ¿Identifica al registro? | S4: Descripción | T4: =A17 -> Consultar la Información de la Categoría | U4: =B17 -> Consultar la Información de una Categoría Motocicleta
A5: ='Categoría Muestreo'!A3 -> id | B5: Alfanumérico | C5: 36 | D5: 36 | H5: xxxxxxxx-xxxx-xxxx-xxxx-xxxxxxxxxxxx | I5: Donde cada x es cualquier carácter que puede ir de( 0-9, a-f) | L5: NO | M5: NO | N5: SI | O5: NO | P5: SI | Q5: NO | R5: SI | S5: ='Categoría Muestreo'!A2 -> Corresponde al identificador único que va a permitir diferenciar cada una de las categorías de motocicletas en el sistema | T5: Filtro/Listar/No Mostrar | U5: Requerido / No Modificable
A6: ='Categoría Muestreo'!B3 -> nombre | B6: Alfanumérico | C6: 1 | D6: 166 | H6: x | I6: Donde x puede ser una cadena que incluye caracteres alfanuméricos, espacios ( ), letras mayúsculas (A-Z), minúsculas (a-z) y tildes (á, é, í, ó, ú) | L6: NO | M6: NO | N6: NO | O6: NO | P6: SI | Q6: NO | R6: NO | S6: ='Categoría Muestreo'!B2 -> Corresponde al atributo que clasifica una motocicleta por categoría según sus características y uso principal | T6: Filtro/Listar/Mostrar[BusquedaGeneral{SI}/Ordenador{No}/Reordenamiento{NO}] | U6: Requerido / Modificable
A11: Combinaciones únicas
A12: Nombre combinación | B12: Descripción | C12: Atributos
A13: Categoría única | B13: ='Categoría Muestreo'!C2 -> El nombre de la categoría no debe de tener duplicidad en el registro de categorías de motocicletas | C13: =A6 -> nombre
A15: Responsabilidad | B15: Descripción | D15: Entradas | K15: Salida | N15: Políticas (Reglas de Negocio)
D16: Parámetro | H16: Tipo de dato | I16: Descripción | J16: Tipo de Dato | K16: Descripción | N16: Política | O16: Descripción | Q16: Detalle | S16: ¿Qué hago?
A17: Consultar la Información de la Categoría | B17: Consultar la Información de una Categoría Motocicleta | D17: Filtro | H17: categoría | I17: Contiene información de todas las categorías que se enviarán como base para llevar a cabo el filtro de consulta | J17: Lista<Categoría> | K17: Contiene información de las categorías que cumplen con los criterios de búsqueda | N17: Categoría POL-0002 | O17: Asegurar que los datos que fueron enviados como filtro para llevar a cabo la acción sean válidos a nivel de tipo de dato, longitud, obligatoriedad, formato y rango. | Q17: Generar una excepción indicándole al usuario que hay problemas con los datos ingresados y de ser posible indicarle cómo solucionarlos | S17: Detener Operación
A18: Editar la Información de la Categoría Motocicleta | B18: Permite actualizar la información de una categoría de motocicleta. | D18: datos | H18: categoría | I18: Contiene información de todas las categorías que se enviarán como base para llevar a cabo la actualización | N18: Categoría POL-0001 | O18: Asegurar la validación de los datos para llevar a cabo la acción a nivel de tipo de dato, longitud, obligatoriedad, formato y rango. | Q18: Generar una excepción indicándole al usuario que hay problemas con los datos ingresados y de ser posible indicarle cómo solucionarlos | S18: Detener Operación
A20: Valor | B20: 0.1 | C20: 0.2 | D20: 0.3
A21: 2 | B21: =ROUNDUP($A$21*$B$20,0) -> 1 | C21: =ROUNDUP($A$21*$C$20,0) -> 1 | D21: =ROUNDUP($A$21*$D$20,0) -> 1
A22: 128 | B22: =ROUND($A$22*$B$20,0) -> 13 | C22: =ROUND($A$22*$C$20,0) -> 26 | D22: =ROUND($A$22*$D$20,0) -> 38

Sheet Calificación Muestreo
D1: dato calculado
A2: Corresponde al identificador único que identifica cada calificación realizada por un usuario a un servicio. | B2: Corresponde al ServicioRealizado que identifica el servicio que fue realizado y puede ser calificado. | C2: Corresponde al atributo que indica la fecha en que el usuario realizó la calificación del servicio. | D2: Corresponde al rangoCalificacion que indica la calificación otorgada un servicio. | E2: Corresponde al atributo que permite al usuario expresar su opinión detallada sobre el servicio recibido. | F2: Corresponde al atributo que indica si el comentario contiene contenido ofensivo | G2: La calificación no debe tener duplicidad en la combinación del servicio realizado y la fecha de calificación.
A3: id | B3: servicioRealizado | C3: fechaCalificacion | D3: calificación | E3: comentario | F3: comentarioOfensivo | G3: Combinación única
A4: 7946c16d-8570-45c7-8000-157828a7b089 | B4: Baike universe - Cambio de aceite y filtros - Finalizado - 12/12/2024 - 12/12/2024 - MRC35E | C4: 13/12/2024 | D4: Excelente 5-5 | E4: El Servicio me pareció excelente, en todo sentido | F4: No | G4: Baike universe - Cambio de aceite y filtros - Finalizado - 12/12/2024 - 12/12/2024 - MRC35E - 13/12/2024
A5: d92e7939-dfea-490a-848e-a8dd596a5997 | B5: Dos Ruedas - Revisión/ajuste de frenos - Cancelado - 13/12/2024 - 13/12/2024 - YBR67A | C5: 14/12/2024 | D5: 0 | G5: Dos Ruedas - Revisión/ajuste de frenos - Cancelado - 13/12/2024 - 13/12/2024 - YBR67A - 14/12/2024

Sheet Calificación Caracterización
A1: <-Volver al inicio
A2: Objeto de Dominio: | B2: ='Listado Objetos de Dominio'!$A$3 -> Calificación
A3: Descripción: | B3: ='Listado Objetos de Dominio'!$B$3 -> Objeto de dominio que representa la valoración numérica dada a un servicio
A4: Atributo | B4: Tipo de Dato | C4: Longitud mínima | D4: Longitud máxima | E4: Precisión | F4: Rango Inicial | G4: Rango Final | H4: Formato | I4: Descripción Formato | J4: Valor por defecto | K4: Regla especial | L4: ¿Quitar espacios en blanco al inicio? | M4: ¿Quitar espacios en blanco al final? | N4: ¿Auto generado? | O4: ¿Calculado? | P4: ¿Obligatorio? | Q4: ¿Modificable? | R4: ¿Sensible? | S4: ¿Identifica al registro? | T4: Descripción | U4: =A23 -> Registrar información de la Calificación | V4: =A27 -> Modificar Información de la Calificación | W4: =A31 -> Consultar Información de la calificación
A5: ='Calificación Muestreo'!A3 -> id | B5: Alfanumérico | C5: 36 | D5: 36 | H5: xxxxxxxx-xxxx-xxxx-xxxx-xxxxxxxxxxxx | I5: Donde cada x es cualquier carácter que puede ir de( 0-9, a-f) | L5: NO | M5: NO | N5: SI | O5: NO | P5: SI | Q5: NO | R5: NO | S5: SI | T5: ='Calificación Muestreo'!A2 -> Corresponde al identificador único que identifica cada calificación realizada por un usuario a un servicio. | U5: Requerido | V5: Requerido / No Modificable | W5: Filtro/Listar/ No Mostrar
A6: ='Calificación Muestreo'!B3 -> servicioRealizado | B6: servicioRealizado | L6: NO | M6: NO | N6: NO | O6: NO | P6: SI | Q6: SI | R6: NO | S6: NO | T6: ='Calificación Muestreo'!B2 -> Corresponde al ServicioRealizado que identifica el servicio que fue realizado y puede ser calificado. | U6: Requerido | V6: Requerido / Modificable | W6: Filtro/Listar/Mostrar[Orden{1}/CriterioOrdenamiento{1, ASC}/BusquedaGeneral{NO}/Ordenador{NO}/Reordenamiento{NO} /PropiedadesMostrar{ servicioRealizado.motocicleta.usuario}]
A7: ='Calificación Muestreo'!C3 -> fechaCalificacion | B7: Fecha | L7: NO | M7: NO | N7: NO | O7: NO | P7: SI | Q7: SI | R7: NO | S7: NO | T7: ='Calificación Muestreo'!C2 -> Corresponde al atributo que indica la fecha en que el usuario realizó la calificación del servicio. | U7: Requerido | V7: Requerido / Modificable | W7: Filtro/Listar/Mostrar[Orden{2}/BusquedaGeneral{NO}/Ordenador{NO}/Reordenamiento{NO} ]
A8: ='Calificación Muestreo'!D3 -> calificación | B8: rangoCalificacion | L8: NO | M8: NO | N8: NO | O8: NO | P8: SI | Q8: SI | R8: NO | S8: NO | T8: ='Calificación Muestreo'!D2 -> Corresponde al rangoCalificacion que indica la calificación otorgada un servicio. | U8: Requerido | V8: Requerido / Modificable | W8: Filtro/Listar/Mostrar[Orden{3}/BusquedaGeneral{NO}/Ordenador{NO}/Reordenamiento{NO} / PropiedadesMostrar{ reangoCalificacion.valorMaximo, rangoCalificacion.etiqueta}]
A9: ='Calificación Muestreo'!E3 -> comentario | B9: Alfanumérico | C9: 1 | D9: 200 | H9: x | I9: Donde x puede ser una cadena que incluye caracteres alfanuméricos, espacios ( ), letras mayúsculas (A-Z), minúsculas (a-z) y tildes (á, é, í, ó, ú) | L9: SI | M9: SI | N9: NO | O9: NO | P9: SI | Q9: SI | R9: SI | S9: NO | T9: ='Calificación Muestreo'!E2 -> Corresponde al atributo que permite al usuario expresar su opinión detallada sobre el servicio recibido. | U9: Requerido | V9: Requerido / Modificable | W9: Filtro/Listar/Mostrar[Orden{4}/BusquedaGeneral{NO}/Ordenador{NO}/Reordenamiento{NO} ]
A10: ='Calificación Muestreo'!F3 -> comentarioOfensivo | B10: Booleano | L10: NO | M10: NO | N10: NO | O10: NO | P10: SI | Q10: SI | R10: SI | S10: NO | T10: ='Calificación Muestreo'!F2 -> Corresponde al atributo que indica si el comentario contiene contenido ofensivo | U10: Requerido | V10: Requerido / Modificable | W10: Filtro/Listar/Mostrar[Orden{4}/BusquedaGeneral{NO}/Ordenador{NO}/Reordenamiento{NO} ]
A12: Combinaciones únicas
A13: Nombre combinación | B13: Descripción | C13: Atributos
A14: servicio realizado y fecha de calificación únicos | B14: ='Calificación Muestreo'!G2 -> La calificación no debe tener duplicidad en la combinación del servicio realizado y la fecha de calificación. | C14: =A6 -> servicioRealizado
C15: =A7 -> fechaCalificacion
A21: Responsabilidad | C21: Descripción | G21: Entradas | J21: Salida | N21: Políticas (Reglas de Negocio) | R21: Excepción
E22: Parámetro | F22: Tipo de dato | H22: Descripción | I22: Tipo de Dato | K22: Descripción | M22: Política | O22: Descripción | Q22: Detalle | S22: ¿Qué hago?
A23: Registrar información de la Calificación | C23: Permite valorar un servicio realizado | E23: datos | F23: calificación | G23: Contiene la calificación del servicio brindado. | M23: Calificación POL-0003 | N23: Solo se permite una calificación por usuario a un servicio realizado por alguna sede | Q23: Generar una excepción indicándole al usuario que hay problemas con los datos ingresados y de ser posible indicarle cómo solucionarlos | S23: Detener la operación
M24: Calificación POL - 0004 | N24: No debe existir otra calificación de un servicio con el mismo identificador. | Q24: Generar un nuevo identificador hasta garantizar que no exista | S24: Continuar la operación
M25: Calificación POL - 0005 | N25: Se debe asegurar que la información a comentar no sean información sensible | Q25: "Se debe reportar un problema indicando que los datos no son válidos, entregando el detalle de cuáles son las normas que está infringiendo y cómo puede remediarse el problema de ser posible. " | S25: Detener y abortar el proceso actual.
A27: Modificar Información de la Calificación | C27: Permite modificar una calificación echa a un servicio realizado | E27: datos | F27: calificación | G27: Contiene la calificación para actualizar | M27: Calificación POL-0002 | N27: La calificación debe estar previamente registrada | Q27: Generar una excepción indicándole al usuario que hay problemas con los datos ingresados y de ser posible indicarle cómo solucionarlos | S27: Detener la operación
M28: Calificación POL-0001 | N28: Asegurar que los datos requeridos para llevar a cabo la acción sean válidos a nivel de tipo de dato, longitud, obligatoriedad, formato y rango. | Q28: Generar una excepción indicándole al usuario que hay problemas con los datos ingresados y de ser posible indicarle cómo solucionarlos | S28: Detener la operación
E29: id | F29: Alfanumérico | G29: Contiene el identificador de la calificación para actualizar | M29: Calificación POL - 0005 | N29: Se debe asegurar que la información a comentar no sean información sensible | Q29: Generar una excepción indicándole al usuario que hay problemas con los datos ingresados y de ser posible indicarle cómo solucionarlos | S29: Detener la operación
A31: Consultar Información de la calificación | C31: Permite ver las calificaciones registradas | E31: filtro | F31: Lista<calificación> | G31: Contiene información de los filtros que se enviaran como base para llevar a cabo la consulta | I31: Lista<calificación> | J31: Contiene información de la calificación que cumple con el filtro | M31: Calificación POL - 0006 | N31: Asegurar que los datos que fueron enviados como filtro para llevar a cabo la acción sean válidos a nivel de tipo de dato, longitud, obligatoriedad, formato y rango. | Q31: Generar una excepción indicándole al usuario que hay problemas con los datos ingresados y de ser posible indicarle cómo solucionarlos | S31: Detener la operación

Sheet Ciudad Muestreo
A2: Corresponde al identificador único que identifica cada ciudad en el sistema. | B2: Corresponde al atributo nombre que contiene el nombre de la ciudad | C2: Corresponde al departamento al que pertenece la ciudad. | D2: La ciudad no existan ciudades con nombres duplicados en el sistema. | E2: La ciudad no debe tener duplicidad en la combinación de su nombre y departamento
A3: id | B3: nombre | C3: departamento | D3: Combinación única | E3: Combinación única
A4: 63dedd71-ff65-4c46-9723-64c29ee2ba8a | B4: Bogotá | C4: Cundinamarca | D4: Bogotá | E4: Bogotá ,Cundinamarca
A5: 6160eb47-e560-49a6-a49c-f8990a53e423 | B5: Medellín | C5: Antioquia | D5: Medellín | E5: Medellín ,Antioquia
A6: 91812cb6-b51b-4845-8adc-8ec50ae154dc | B6: Cali | C6: Valle del Cauca | D6: Cali | E6: Cali ,Valle del Cauca
A7: 5643d1d9-f9f0-4b50-805d-b54870b27db2 | B7: Barranquilla | C7: Atlántico | D7: Barranquilla | E7: Barranquilla ,Atlántico
A8: d7275c10-fd10-4e01-bfcb-f996c00a3ffe | B8: Cartagena | C8: Bolívar | D8: Cartagena | E8: Cartagena ,Bolívar
A9: 4a1907e4-df8e-4269-be6e-8ca86a8497eb | B9: Cúcuta | C9: Norte de Santander | D9: Cúcuta | E9: Cúcuta ,Norte de Santander
A10: f38f8524-2d54-4731-a372-d687b426e360 | B10: Soledad | C10: Atlántico | D10: Soledad | E10: Soledad ,Atlántico
A11: 7d1ab9fa-213d-4428-8eca-a33828d4a04f | B11: Ibagué | C11: Tolima | D11: Ibagué | E11: Ibagué ,Tolima
A12: cc892516-445b-4cbc-b6dd-b77ea49058d5 | B12: Bucaramanga | C12: Santander | D12: Bucaramanga | E12: Bucaramanga ,Santander
A13: 5b5989e1-8fe7-4484-a747-6223e22829b6 | B13: Soacha | C13: Cundinamarca | D13: Soacha | E13: Soacha ,Cundinamarca
... A80: 80e27e56-286f-4a3c-98d5-6c3ca7ad7d2f | B80: San Vicente del Caguán | C80: Caquetá | D80: San Vicente del Caguán | E80: San Vicente del Caguán ,Caquetá

Sheet Ciudad Caracterización
A1: <-Volver al inicio
A2: Objeto de Dominio: | B2: ='Listado Objetos de Dominio'!$A$5 -> Ciudad
A3: Descripción: | B3: ='Listado Objetos de Dominio'!$B$5 -> Objeto de dominio que representa la ciudad donde se encuentra ubicada la sede.
A4: Atributo | B4: Tipo de Dato | C4: Longitud mínima | D4: Longitud máxima | E4: Precisión | F4: Rango Inicial | G4: Rango Final | H4: Formato | I4: Descripción Formato | J4: Valor por defecto | K4: Regla especial | L4: ¿Quitar espacios en blanco al inicio? | M4: ¿Quitar espacios en blanco al final? | N4: ¿Auto generado? | O4: ¿Calculado? | P4: ¿Obligatorio? | Q4: ¿Modificable? | R4: ¿Sensible? | S4: ¿Identifica al registro? | T4: Descripción | U4: =A21 -> Consultar Información de la ciudad
A5: ='Ciudad Muestreo'!A3 -> id | B5: Alfanumérico | C5: 36 | D5: 36 | H5: xxxxxxxx-xxxx-xxxx-xxxx-xxxxxxxxxxxx | I5: Donde cada x es cualquier carácter que puede ir de( 0-9, a-f) | L5: NO | M5: NO | N5: SI | O5: NO | P5: SI | Q5: NO | R5: NO | S5: SI | T5: ='Ciudad Muestreo'!A2 -> Corresponde al identificador único que identifica cada ciudad en el sistema. | U5: Filtro/Listar/ No Mostrar
A6: ='Ciudad Muestreo'!B3 -> nombre | B6: horarioEstablecimiento | L6: NO | M6: NO | N6: NO | O6: NO | P6: SI | Q6: NO | R6: NO | S6: NO | T6: ='Ciudad Muestreo'!B2 -> Corresponde al atributo nombre que contiene el nombre de la ciudad | U6: Filtro/Listar/Mostrar[Orden{1}/CriterioOrdenamiento{1, ASC}/BusquedaGeneral{SI}/Ordenador{SI}/Reordenamiento{NO}]
A7: ='Ciudad Muestreo'!C3 -> departamento | B7: departamento | L7: NO | M7: NO | N7: NO | O7: NO | P7: SI | Q7: NO | R7: NO | S7: NO | T7: ='Ciudad Muestreo'!C2 -> Corresponde al departamento al que pertenece la ciudad. | U7: Filtro/Listar/Mostrar[Orden{1}/CriterioOrdenamiento{1, ASC}/BusquedaGeneral{SI}/Ordenador{SI}/Reordenamiento{NO} /PropiedadesMostrar{ departamento.nombre}]
A12: Combinaciones únicas
A13: Nombre combinación | B13: Descripción | C13: Atributos
A14: fecha y hora de inicio únicos | B14: ='Ciudad Muestreo'!D2 -> La ciudad no existan ciudades con nombres duplicados en el sistema. | C14: =A6 -> nombre
A16: fecha y hora de fin únicos | B16: ='Ciudad Muestreo'!E2 -> La ciudad no debe tener duplicidad en la combinación de su nombre y departamento | C16: =A7 -> departamento
A19: Responsabilidad | B19: Descripción | D19: Entradas | K19: Salida | N19: Políticas (Reglas de Negocio) | R19: Excepción
D20: Parámetro | H20: Tipo de dato | I20: Descripción | J20: Tipo de Dato | K20: Descripción | N20: Política | O20: Descripción | Q20: Detalle | S20: ¿Qué hago?
A21: Consultar Información de la ciudad | B21: Permite visualizar la información de una ciudad | D21: filtro | H21: ciudad | I21: Contiene información de las diferentes ciudades que se enviarán como base para llevar a cabo el filtro de la consulta | J21: Lista<ciudad> | K21: Contiene información de las diferentes ciudades que cumplen con los criterios de búsqueda | N21: Ciudad POL-0001 | O21: Asegurar que los datos que fueron enviados como filtro para llevar a cabo la acción sean válidos a nivel de tipo de dato, longitud, obligatoriedad, formato y rango.. | Q21: Generar una excepción indicándole al usuario que hay problemas con los datos ingresados y de ser posible indicarle cómo solucionarlos | S21: Detener Operación

Sheet Departamento Muestreo
A2: Corresponde al identificador único que identifica cada departamento en el sistema. | B2: Corresponde al atributo que indica el nombre del departamento | C2: El departamento no debe tener duplicidad en su nombre
A3: id | B3: nombre | C3: Combinación única
A4: baf7686f-548f-4886-a9d4-8dd650774176 | B4: Cundinamarca | C4: Cundinamarca
A5: 9da583ae-03a6-4eee-9654-f976aa153cae | B5: Antioquia | C5: Antioquia
A6: 7968baa5-d516-4f83-8ede-77dfc0abc1c8 | B6: Atlántico | C6: Atlántico
A7: 2d0e3ae6-0b6b-46d0-aab0-3bac8e480472 | B7: Bolívar | C7: Bolívar
A8: 192df308-16f9-46a1-b341-ec84f49d015b | B8: Boyacá | C8: Boyacá
A9: 0aebf2b6-e8f5-40fd-9669-cc8fee49c810 | B9: Caldas | C9: Caldas
A10: 6e24bf5f-e874-4c20-9750-cf8ebdc03a8b | B10: Caquetá | C10: Caquetá
A11: fe86dac9-02f6-4c38-aacc-bc2e82d6a733 | B11: Casanare | C11: Casanare
A12: 44dbc677-d935-438b-ab73-429504f7209c | B12: Cauca | C12: Cauca
A13: f5f6cdfc-c61d-4a34-bdf5-47884bcaf1b2 | B13: Cesar | C13: Cesar
... A29: 270786c6-60d6-4297-9198-20fc738483e1 | B29: Valle del Cauca | C29: Valle del Cauca

Sheet Departamento Caracterización 
A1: <-Volver al inicio
A2: Objeto de Dominio: | B2: ='Listado Objetos de Dominio'!$A$6 -> Departamento
A3: Descripción: | B3: ='Listado Objetos de Dominio'!$B$6 -> Objeto de dominio que representa la división territorial donde se encuentra la ciudad.
A4: Atributo | B4: Tipo de Dato | C4: Longitud mínima | D4: Longitud máxima | E4: Precisión | F4: Rango Inicial | G4: Rango Final | H4: Formato | I4: Descripción Formato | J4: Valor por defecto | K4: Regla especial | L4: ¿Quitar espacios en blanco al inicio? | M4: ¿Quitar espacios en blanco al final? | N4: ¿Auto generado? | O4: ¿Calculado? | P4: ¿Obligatorio? | Q4: ¿Modificable? | R4: ¿Sensible? | S4: ¿Identifica al registro? | T4: Descripción | U4: =A14 -> Consultar Información del Departamento
A5: ='Departamento Muestreo'!A3 -> id | B5: Alfanumérico | C5: 36 | D5: 36 | H5: xxxxxxxx-xxxx-xxxx-xxxx-xxxxxxxxxxxx | I5: Donde cada x es cualquier carácter que puede ir de( 0-9, a-f) | L5: NO | M5: NO | N5: SI | O5: NO | P5: SI | Q5: NO | R5: NO | S5: SI | T5: ='Departamento Muestreo'!A2 -> Corresponde al identificador único que identifica cada departamento en el sistema. | U5: Filtro/Listar/No Mostrar
A6: ='Departamento Muestreo'!B3 -> nombre | B6: Alfanumérico | C6: 1 | D6: 50 | H6: x | I6: Donde x puede ser una cadena que incluye caracteres alfanuméricos,espacios( ), letras mayúsculas (A-Z), minúsculas (a-z) y tildes (á, é, í, ó, ú) | L6: NO | M6: NO | N6: NO | O6: NO | P6: SI | Q6: NO | R6: NO | S6: NO | T6: ='Departamento Muestreo'!B2 -> Corresponde al atributo que indica el nombre del departamento | U6: Filtro/Listar/Mostrar[Orden{1}/CriterioOrdenamiento{1, ASC}/BusquedaGeneral{SI}/Ordenador{NO}/Reordenamiento{NO}]
A8: Combinaciones únicas
A9: Nombre combinación | B9: Descripción | C9: Atributos
A10: nombre del departamento único | B10: ='Departamento Muestreo'!C2 -> El departamento no debe tener duplicidad en su nombre | C10: =A6 -> nombre
A12: Responsabilidad | B12: Descripción | D12: Entradas | K12: Salida | N12: Políticas (Reglas de Negocio) | R12: Excepción
D13: Parámetro | H13: Tipo de dato | I13: Descripción | J13: Tipo de Dato | K13: Descripción | N13: Política | O13: Descripción | Q13: Detalle | S13: ¿Qué hago?
A14: Consultar Información del Departamento | B14: Permite visualizar la información de un departamento | D14: filtro | H14: departamento | I14: Contiene información de los diferentes departamentos que se enviarán como base para llevar a cabo el filtro de la consulta | J14: Lista<departamento> | K14: Contiene información de los diferentes departamentos que cumplen con los criterios de búsqueda | N14: Departamento POL-0001 | O14: Asegurar que los datos que fueron enviados como filtro para llevar a cabo la acción sean válidos a nivel de tipo de dato, longitud, obligatoriedad, formato y rango.. | Q14: Generar una excepción indicándole al usuario que hay problemas con los datos ingresados y de ser posible indicarle cómo solucionarlos | S14: Detener Operación

Sheet Detalle Horario Muestreo 
A2: Corresponde al identificador único que identifica cada detalle de horario de operación del establecimiento en el sistema | B2: Corresponde al horarioEstablecimeinto vigente al que le pertenece este horario de operación. | C2: Corresponde al día de la semana en que opera el establecimiento. Si un día no está registrado, significa que el establecimiento no opera ese día | D2: Corresponde al atributo que indica la hora en que inicia la operación del establecimiento. | E2: Corresponde al atributo que indica la hora en que finaliza la operación del establecimiento | F2: El detalle horario no debe tener duplicidad en la combinación del horario establecimiento, día y rango horario de operación
A3: id | B3: horarioSede | C3: día | D3: horaInicio | E3: horaFin | F3: Combinación única
A4: 63dedd71-ff65-4c46-9723-64c29ee2ba8a | B4: Baike universe - 01/01/2024 -06/12/2028 | C4: Lunes | D4: 7:00 a. m. | E4: 12:00 p. m. | F4: Baike universe - 01/01/2024 -06/12/2028 - Lunes - 07:00-12:00
A5: 6160eb47-e560-49a6-a49c-f8990a53e423 | B5: Baike universe - 01/01/2024 -06/12/2028 | C5: Lunes | D5: 1:00 p. m. | E5: 5:00 p. m. | F5: Baike universe - 01/01/2024 -06/12/2028 - Lunes - 13:00-17:00
A6: 91812cb6-b51b-4845-8adc-8ec50ae154dc | B6: Baike universe - 01/01/2024 -06/12/2028 | C6: Martes | D6: 7:00 a. m. | E6: 12:00 p. m. | F6: Baike universe - 01/01/2024 -06/12/2028 - Martes - 07:00-12:00
A7: 5643d1d9-f9f0-4b50-805d-b54870b27db2 | B7: Baike universe - 01/01/2024 -06/12/2028 | C7: Martes | D7: 1:30 p. m. | E7: 5:30 p. m. | F7: Baike universe - 01/01/2024 -06/12/2028 - Martes - 13:30-17:30
A8: d7275c10-fd10-4e01-bfcb-f996c00a3ffe | B8: Baike universe - 01/01/2024 -06/12/2028 | C8: Miércoles | D8: 7:00 a. m. | E8: 12:00 p. m. | F8: Baike universe - 01/01/2024 -06/12/2028 - Miércoles - 07:00-12:00
A9: 4a1907e4-df8e-4269-be6e-8ca86a8497eb | B9: Baike universe - 01/01/2024 -06/12/2028 | C9: Miércoles | D9: 1:30 p. m. | E9: 5:30 p. m. | F9: Baike universe - 01/01/2024 -06/12/2028 - Miércoles - 13:30-17:30
A10: f38f8524-2d54-4731-a372-d687b426e360 | B10: Baike universe - 01/01/2024 -06/12/2028 | C10: Jueves | D10: 7:00 a. m. | E10: 12:00 p. m. | F10: Baike universe - 01/01/2024 -06/12/2028 - Jueves - 07:00-12:00
A11: 7d1ab9fa-213d-4428-8eca-a33828d4a04f | B11: Baike universe - 01/01/2024 -06/12/2028 | C11: Jueves | D11: 1:30 p. m. | E11: 5:30 p. m. | F11: Baike universe - 01/01/2024 -06/12/2028 - Jueves - 13:30-17:30
A12: cc892516-445b-4cbc-b6dd-b77ea49058d5 | B12: Baike universe - 01/01/2024 -06/12/2028 | C12: Viernes | D12: 7:00 a. m. | E12: 12:00 p. m. | F12: Baike universe - 01/01/2024 -06/12/2028 - Viernes - 07:00-12:00
A13: 5b5989e1-8fe7-4484-a747-6223e22829b6 | B13: Baike universe - 01/01/2024 -06/12/2028 | C13: Viernes | D13: 1:30 p. m. | E13: 5:30 p. m. | F13: Baike universe - 01/01/2024 -06/12/2028 - Viernes - 13:30-17:30
... A24: 2d8d0582-4413-410c-bdb4-d38aba475803 | B24: Dos Ruedas - 01/01/2020 -05/16/2022 | C24: Viernes | D24: 1:30 p. m. | E24: 5:30 p. m. | F24: Dos Ruedas - 01/01/2020 -05/16/2022 - Viernes - 13:30-17:30

Sheet Detalle horari Caracterización
A1: <-Volver al inicio
A2: Objeto de Dominio: | B2: ='Listado Objetos de Dominio'!$A$7 -> Detalle Horario
A3: Descripción: | B3: ='Listado Objetos de Dominio'!$B$7 -> Objeto de dominio que representa la información específica de los horarios de atención de la sede.
A4: Atributo | B4: Tipo de Dato | C4: Longitud mínima | D4: Longitud máxima | E4: Precisión | F4: Rango Inicial | G4: Rango Final | H4: Formato | I4: Descripción Formato | J4: Valor por defecto | K4: Regla especial | L4: ¿Quitar espacios en blanco al inicio? | M4: ¿Quitar espacios en blanco al final? | N4: ¿Auto generado? | O4: ¿Calculado? | P4: ¿Obligatorio? | Q4: ¿Modificable? | R4: ¿Sensible? | S4: ¿Identifica al registro? | T4: Descripción | U4: =A28 -> Registrar Información del Detalle Horario | V4: =A32 -> Modificar Información del Detalle Horario | W4: =A36 -> Eliminar Información del Detalle Horario | X4: =A40 -> Consultar Información del Detalle Horario
A5: ='Detalle Horario Muestreo '!A3 -> id | B5: Alfanumérico | C5: 36 | D5: 36 | H5: xxxxxxxx-xxxx-xxxx-xxxx-xxxxxxxxxxxx | I5: Donde cada x es cualquier carácter que puede ir de( 0-9, a-f) | L5: NO | M5: NO | N5: SI | O5: NO | P5: SI | Q5: NO | R5: NO | S5: SI | T5: ='Detalle Horario Muestreo '!A2 -> Corresponde al identificador único que identifica cada detalle de horario de operación del establecimiento en el sistema | U5: Requerido | V5: Requerido / No Modificable | W5: Requerido | X5: Filtro/Listar/ No Mostrar
A6: ='Detalle Horario Muestreo '!B3 -> horarioSede | B6: horarioSede | L6: NO | M6: NO | N6: NO | O6: NO | P6: SI | Q6: NO | R6: NO | S6: NO | T6: ='Detalle Horario Muestreo '!B2 -> Corresponde al horarioEstablecimeinto vigente al que le pertenece este horario de operación. | U6: Requerido | V6: Requerido / Modificable | W6: No requerido | X6: Filtro/Listar/Mostrar[Orden{1}/CriterioOrdenamiento{1, ASC}/BusquedaGeneral{NO}/Ordenador{NO}/Reordenamiento{NO} /PropiedadesMostrar{ horarioSede.sede}]
A7: ='Detalle Horario Muestreo '!C3 -> día | B7: día | L7: NO | M7: NO | N7: NO | O7: NO | P7: SI | Q7: NO | R7: NO | S7: NO | T7: ='Detalle Horario Muestreo '!C2 -> Corresponde al día de la semana en que opera el establecimiento. Si un día no está registrado, significa que el establecimiento no opera ese día | U7: Requerido | V7: Requerido / Modificable | W7: No requerido | X7: Filtro/Listar/Mostrar[Orden{2}/BusquedaGeneral{NO}/Ordenador{NO}/Reordenamiento{NO} ]
A8: ='Detalle Horario Muestreo '!D3 -> horaInicio | B8: Hora | L8: NO | M8: NO | N8: NO | O8: NO | P8: SI | Q8: NO | R8: NO | S8: NO | T8: ='Detalle Horario Muestreo '!D2 -> Corresponde al atributo que indica la hora en que inicia la operación del establecimiento. | U8: Requerido | V8: Requerido / Modificable | W8: No requerido | X8: Filtro/Listar/Mostrar[Orden{3}/BusquedaGeneral{NO}/Ordenador{NO}/Reordenamiento{NO} ]
A9: ='Detalle Horario Muestreo '!E3 -> horaFin | B9: Hora | L9: NO | M9: NO | N9: NO | O9: NO | P9: SI | Q9: NO | R9: NO | S9: NO | T9: ='Detalle Horario Muestreo '!E2 -> Corresponde al atributo que indica la hora en que finaliza la operación del establecimiento | U9: Requerido | V9: Requerido / Modificable | W9: No requerido | X9: Filtro/Listar/Mostrar[Orden{4}/BusquedaGeneral{NO}/Ordenador{NO}/Reordenamiento{NO} ]
A12: Combinaciones únicas
A13: Nombre combinación | B13: Descripción | C13: Atributos
A14: El horario del establecimiento, día, hora de inicio y de fin son únicos | B14: ='Detalle Horario Muestreo '!F2 -> El detalle horario no debe tener duplicidad en la combinación del horario establecimiento, día y rango horario de operación | C14: =A6 -> horarioSede
C15: =A7 -> día
C16: =A8 -> horaInicio
C17: =A9 -> horaFin
A26: Responsabilidad | C26: Descripción | G26: Entradas | J26: Salida | N26: Políticas (Reglas de Negocio) | R26: Excepción
E27: Parámetro | F27: Tipo de dato | H27: Descripción | I27: Tipo de Dato | K27: Descripción | M27: Política | O27: Descripción | Q27: Detalle | S27: ¿Qué hago?
A28: Registrar Información del Detalle Horario | C28: Permite registrar los detalles de los horarios y días de operación de una sede | E28: datos | F28: detalleHorario | G28: Contiene información requerida para llevar a cabo el registro del nuevo detalle horario | M28: Detalle Horario POL-0004 | N28: La sede debe estar previamente registrada | Q28: Generar una excepción indicándole al usuario que hay problemas con los datos ingresados y de ser posible indicarle como solucionarlos | S28: Detener la operación
M29: Detalle Horario POL-0003 | N29: El día debe estar Registrado. | Q29: Generar una excepción indicándole al usuario que hay problemas con los datos ingresados y de ser posible indicarle como solucionarlos | S29: Detener la operación
M30: Detalle Horario POL-0001 | N30: Asegurar que los datos requeridos para llevar a cabo la acción sean válidos a nivel de tipo de dato, longitud, obligatoriedad, formato y rango. | Q30: Generar una excepción indicándole al usuario que hay problemas con los datos ingresados y de ser posible indicarle como solucionarlos | S30: Detener la operación
M31: Detalle Horario POL-0002 | N31: No debe existir otro detalle horario con el mismo identificador. | Q31: Generar un nuevo identificador hasta garantizar que no exista | S31: Continuar la operación
A32: Modificar Información del Detalle Horario | C32: Permite actualizar la información de los detalles de horarios y días de operación de una sede | E32: datos | F32: detalleHorario | G32: Contiene información de los datos del Detalle Horario a modificar | M32: Detalle Horario POL-0005 | N32: La sede y el día deben estar previamente asociados. | Q32: Validar que todos los campos cumplan con las especificaciones requeridas antes de procesar la información | S32: Detener la operación
E33: id | F33: Alfanumérico | G33: Contiene el identificador del detalle horario a modificar la información | M33: Detalle Horario POL-0001 | N33: Asegurar que los datos requeridos para llevar a cabo la acción sean válidos a nivel de tipo de dato, longitud, obligatoriedad, formato y rango. | Q33: Generar una excepción indicándole al usuario que hay problemas con los datos ingresados y de ser posible indicarle como solucionarlos | S33: Detener la operación
A36: Eliminar Información del Detalle Horario | C36: Permite eliminar un detalle horario específico de una sede | E36: id | F36: Alfanumérico | G36: Contiene el identificador del detalle horario a eliminar | M36: Detalle Horario POL-0006 | N36: Asegurarse que el detalle horario a eliminar no se encuentre asociado a una sede | Q36: Generar una excepción indicándole al usuario que hay problemas con los datos ingresados y de ser posible indicarle cómo solucionarlos | S36: Detener la operación
P37: Detener la operación
M38: Detalle Horario POL-0001 | N38: Asegurar que los datos requeridos para llevar a cabo la acción sean válidos a nivel de tipo de dato, longitud, obligatoriedad, formato y rango. | Q38: Generar una excepción indicándole al usuario que hay problemas con los datos ingresados y de ser posible indicarle cómo solucionarlos | S38: Detener la operación
A40: Consultar Información del Detalle Horario | C40: Permite consultar los detalles horarios configurados para una sede | E40: filtro | F40: Lista<detalleHorario> | G40: Contiene información de los filtros que se enviaran como base para llevar a cabo la consulta | I40: Lista<detalleHorario> | J40: Contiene información del detalle horario que cumple con el filtro | M40: Detalle Horario POL - 0007 | N40: Asegurar que los datos que fueron enviados como filtro para llevar a cabo la acción sean válidos a nivel de tipo de dato, longitud, obligatoriedad, formato y rango. | Q40: Asegurar que los datos que fueron enviados como filtro para llevar a cabo la acción sean válidos a nivel de tipo de dato, longitud, obligatoriedad, formato y rango. | S40: Detener la operación

Sheet Dia Muestreo
A2: Corresponde al identificador único que identifica cada día en el sistema | B2: Corresponde al atributo que indica el nombre del día | C2: El día no debe tener duplicidad en su nombre
A3: id | B3: nombre | C3: Combinación única
A4: 9a63d7fa-7c97-4374-b574-63bd41586441 | B4: Lunes | C4: Lunes
A5: c2686453-5d4b-4690-9259-f575b6276153 | B5: Martes | C5: Martes
A6: 3376d24a-7d86-4ddf-89ee-e7d03cd736ff | B6: Miércoles | C6: Miércoles
A7: 5e2e836e-f39e-444b-9673-3efb066c4e1d | B7: Jueves | C7: Jueves
A8: 8f761fdc-5488-4cb6-a225-85451f2003ed | B8: Viernes | C8: Viernes
A9: 70a42e6d-f733-4d73-95cf-359b99319d80 | B9: Sábado | C9: Sábado
A10: 088c83a2-7138-4a2e-98df-5d8e810faafd | B10: Domingo | C10: Domingo
A12: `

Sheet Dia Caracterización
A1: <-Volver al inicio
A2: Objeto de Dominio: | B2: ='Listado Objetos de Dominio'!$A$8 -> Dia
A3: Descripción: | B3: ='Listado Objetos de Dominio'!$B$8 -> Objeto de dominio que representa cada uno de los días de la semana en que opera una sede.
A4: Atributo | B4: Tipo de Dato | C4: Longitud mínima | D4: Longitud máxima | E4: Precisión | F4: Rango Inicial | G4: Rango Final | H4: Formato | I4: Descripción Formato | J4: Valor por defecto | K4: Regla especial | L4: ¿Quitar espacios en blanco al inicio? | M4: ¿Quitar espacios en blanco al final? | N4: ¿Auto generado? | O4: ¿Calculado? | P4: ¿Obligatorio? | Q4: ¿Modificable? | R4: ¿Sensible? | S4: ¿Identifica al registro? | T4: Descripción | U4: =A14 -> Consultar Información del Día
A5: ='Dia Muestreo'!A3 -> id | B5: Alfanumérico | C5: 36 | D5: 36 | H5: xxxxxxxx-xxxx-xxxx-xxxx-xxxxxxxxxxxx | I5: Donde cada x es cualquier carácter que puede ir de( 0-9, a-f) | L5: NO | M5: NO | N5: SI | O5: NO | P5: SI | Q5: NO | R5: NO | S5: SI | T5: ='Dia Muestreo'!A2 -> Corresponde al identificador único que identifica cada día en el sistema | U5: Filtro/Listar/ No Mostrar
A6: ='Dia Muestreo'!B3 -> nombre | B6: Alfanumérico | C6: 1 | D6: 10 | H6: x | I6: Donde x puede ser una cadena que incluye caracteres alfanuméricos, espacios( ), letras mayúsculas (A-Z), minúsculas (a-z) y tildes (á, é, í, ó, ú) | L6: SI | M6: SI | N6: NO | O6: NO | P6: SI | Q6: NO | R6: NO | S6: NO | T6: ='Dia Muestreo'!B2 -> Corresponde al atributo que indica el nombre del día | U6: Filtro/Listar/Mostrar[Orden{1}/BusquedaGeneral{SI}/Ordenador{NO}/Reordenamiento{NO} ]
A8: Combinaciones únicas
A9: Nombre combinación | B9: Descripción | C9: Atributos
A10: nombre del día único | B10: ='Dia Muestreo'!C2 -> El día no debe tener duplicidad en su nombre | C10: =A6 -> nombre
A12: Responsabilidad | B12: Descripción | D12: Entradas | K12: Salida | N12: Políticas (Reglas de Negocio) | R12: Excepción
D13: Parámetro | H13: Tipo de dato | I13: Descripción | J13: Tipo de Dato | K13: Descripción | N13: Política | O13: Descripción | Q13: Detalle | S13: ¿Qué hago?
A14: Consultar Información del Día | B14: Permite ver la información del día de la semana | D14: filtro | H14: día | I14: Contiene información de los diferentes días que se enviarán como base para llevar a cabo el filtro de la consulta | J14: Lista<día> | K14: Contiene información de los diferentes días que cumplen con los criterios de búsqueda | N14: Día POL-0001 | O14: Asegurar que los datos que fueron enviados como filtro para llevar a cabo la acción sean válidos a nivel de tipo de dato, longitud, obligatoriedad, formato y rango. | Q14: Generar una excepción indicándole al usuario que hay problemas con los datos ingresados y de ser posible indicarle cómo solucionarlos | S14: Detener Operación

Sheet Diagnotico Muestreo 
A2: Corresponde al identificador único que identifica cada diagnóstico realizado a una motocicleta. | B2: Corresponde al atributo que indica la fecha en que se realizó el diagnóstico. | C2: Corresponde al atributo que describe el problema reportado o encontrado en la motocicleta. | D2: Corresponde al atributo que indica la posible solución técnica al problema diagnosticado. | E2: Corresponde al motocicleta diagnosticada e indica la matricula. | F2: Corresponde a la sede donde se realizó el diagnóstico.
A3: id | B3: fecha | C3: descripcionProblema | D3: posibleSolucion | E3: motocicleta | F3: sede
A4: 7946c16d-8570-45c7-8000-157828a7b089 | B4: 24/12/2024 | C4: Cambio no Funciona | D4: Cambiar huaya del Clusth | E4: MRC35E | F4: Sede A - Baike universe
A5: d92e7939-dfea-490a-848e-a8dd596a5997 | B5: 45302 | C5: Motor Con sonido raro | D5: Cambio de Aceite | E5: YBR67A | F5: Sede A - Dos Ruedas

Sheet Diagnostico Caracterización
A1: <-Volver al inicio
A2: Objeto de Dominio: | B2: ='Listado Objetos de Dominio'!$A$9 -> Diagnostico
A3: Descripción: | B3: ='Listado Objetos de Dominio'!$B$9 -> Objeto de dominio que representa la evaluación técnica realizada a una motocicleta por parte de una sede.
A4: Atributo | B4: Tipo de Dato | C4: Longitud mínima | D4: Longitud máxima | E4: Precisión | F4: Rango Inicial | G4: Rango Final | H4: Formato | I4: Descripción Formato | J4: Valor por defecto | K4: Regla especial | L4: ¿Quitar espacios en blanco al inicio? | M4: ¿Quitar espacios en blanco al final? | N4: ¿Auto generado? | O4: ¿Calculado? | P4: ¿Obligatorio? | Q4: ¿Modificable? | R4: ¿Sensible? | S4: ¿Identifica al registro? | T4: Descripción | U4: =A24 -> Registrar Información del Diagnóstico | V4: =A28 -> Modificar Información del Diagnóstico | W4: =A31 -> Eliminar Información del Diagnóstico | X4: =A33 -> Consultar Información del Diagnóstico
A5: ='Diagnotico Muestreo '!A3 -> id | B5: Alfanumérico | C5: 36 | D5: 36 | H5: xxxxxxxx-xxxx-xxxx-xxxx-xxxxxxxxxxxx | I5: Donde cada x es cualquier carácter que puede ir de( 0-9, a-f) | L5: NO | M5: NO | N5: SI | O5: NO | P5: SI | Q5: NO | R5: NO | S5: SI | T5: ='Diagnotico Muestreo '!A2 -> Corresponde al identificador único que identifica cada diagnóstico realizado a una motocicleta. | U5: Requerido | V5: Requerido / No Modificable | W5: Requerido | X5: Filtro/Listar/ No Mostrar
A6: ='Diagnotico Muestreo '!B3 -> fecha | B6: Fecha | L6: NO | M6: NO | N6: NO | O6: NO | P6: SI | Q6: SI | R6: NO | S6: NO | T6: ='Diagnotico Muestreo '!B2 -> Corresponde al atributo que indica la fecha en que se realizó el diagnóstico. | U6: Requerido | V6: Requerido / Modificable | W6: No Requerido | X6: Filtro/Listar/Mostrar[Orden{1}/BusquedaGeneral{NO}/Ordenador{NO}/Reordenamiento{NO}]
A7: ='Diagnotico Muestreo '!C3 -> descripcionProblema | B7: Alfanumérico | C7: 1 | D7: 250 | H7: x | I7: Donde x puede ser una cadena que incluye caracteres alfanuméricos, espacios ( ), letras mayúsculas (A-Z), minúsculas (a-z) y tildes (á, é, í, ó, ú) | L7: SI | M7: SI | N7: NO | O7: NO | P7: SI | Q7: SI | R7: NO | S7: NO | T7: ='Diagnotico Muestreo '!C2 -> Corresponde al atributo que describe el problema reportado o encontrado en la motocicleta. | U7: Requerido | V7: Requerido / Modificable | W7: No Requerido | X7: Filtro/Listar/Mostrar[Orden{2}/BusquedaGeneral{NO}/Ordenador{NO}/Reordenamiento{NO}]
A8: ='Diagnotico Muestreo '!D3 -> posibleSolucion | B8: Alfanumérico | C8: 1 | D8: 250 | H8: x | I8: Donde x puede ser una cadena que incluye caracteres alfanuméricos, espacios ( ), letras mayúsculas (A-Z), minúsculas (a-z) y tildes (á, é, í, ó, ú) | L8: SI | M8: SI | N8: NO | O8: NO | P8: SI | Q8: SI | R8: NO | S8: NO | T8: ='Diagnotico Muestreo '!D2 -> Corresponde al atributo que indica la posible solución técnica al problema diagnosticado. | U8: Requerido | V8: Requerido / Modificable | W8: No Requerido | X8: Filtro/Listar/Mostrar[Orden{3}/BusquedaGeneral{NO}/Ordenador{NO}/Reordenamiento{NO}]
A9: ='Diagnotico Muestreo '!E3 -> motocicleta | B9: motocicleta | L9: NO | M9: NO | N9: NO | O9: NO | P9: SI | Q9: NO | R9: SI | S9: NO | T9: ='Diagnotico Muestreo '!E2 -> Corresponde al motocicleta diagnosticada e indica la matricula. | U9: Requerido | V9: Requerido / No Modificable | W9: No Requerido | X9: Filtro/Listar/Mostrar[Orden{4}/CriterioOrdenamiento{1, ASC}/BusquedaGeneral{SI}/Ordenador{SI}/Reordenamiento{NO} /PropiedadesMostrar{ motocicleta.matricula}]
A10: ='Diagnotico Muestreo '!F3 -> sede | B10: sede | L10: NO | M10: NO | N10: NO | O10: NO | P10: SI | Q10: SI | R10: NO | S10: NO | T10: ='Diagnotico Muestreo '!F2 -> Corresponde a la sede donde se realizó el diagnóstico. | U10: Requerido | V10: Requerido / Modificable | W10: No Requerido | X10: Filtro/Listar/Mostrar[Orden{4}/CriterioOrdenamiento{2, ASC}/BusquedaGeneral{SI}/Ordenador{SI}/Reordenamiento{NO} /PropiedadesMostrar{ sede.nombre}]
A14: Combinaciones únicas
A15: Nombre combinación | B15: Descripción | C15: Atributos
A22: Responsabilidad | C22: Descripción | G22: Entradas | J22: Salida | N22: Políticas (Reglas de Negocio) | R22: Excepción
E23: Parámetro | F23: Tipo de dato | H23: Descripción | I23: Tipo de Dato | K23: Descripción | M23: Política | O23: Descripción | Q23: Detalle | S23: ¿Qué hago?
A24: Registrar Información del Diagnóstico | C24: Permite crear un nuevo diagnóstico técnico | E24: datos | F24: diagnóstico | G24: Contiene la información de un nuevo diagnóstico que se hace a una motocicleta | M24: Diagnostico POL - 0001 | N24: Asegurar que los datos requeridos para llevar a cabo la acción sean válidos a nivel de tipo de dato, longitud, obligatoriedad, formato y rango. | Q24: Generar una excepción indicándole al usuario que hay problemas con los datos ingresados y de ser posible indicarle cómo solucionarlos | S24: Detener Operación
M25: Diagnostico POL - 0002 | N25: La sede debe estar previamente registrada | Q25: Generar una excepción indicando al usuario que la sede debe estar asociada al diagnóstico | S25: Detener Operación
M26: Diagnostico POL - 0003 | N26: La motocicleta debe estar previamente registrada | Q26: Generar una excepción indicando al usuario que debe de asociar una motocicleta para realizar el diagnostico | S26: Detener Operación
M27: Diagnostico POL - 0004 | N27: No puede existir otro diagnostico con el mismo identificador. | Q27: Generar un nuevo identificador hasta garantizar que no exista | S27: Contuar Operacion
A28: Modificar Información del Diagnóstico | C28: Permite actualizar un diagnóstico existente | E28: id | F28: Alfanumérico | G28: Contiene el identificador del diagnóstico para actualizar | M28: Diagnostico POL - 0001 | N28: Asegurar que los datos requeridos para llevar a cabo la acción sean válidos a nivel de tipo de dato, longitud, obligatoriedad, formato y rango. | Q28: Generar una excepción indicándole al usuario que hay problemas con los datos ingresados y de ser posible indicarle cómo solucionarlos | S28: Detener Operación
E29: datos | F29: diagnóstico | G29: Contiene información del diagnóstico para actualizar
A31: Eliminar Información del Diagnóstico | C31: Permite eliminar un diagnóstico | E31: filtro | F31: Lista<diagnosticó> | G31: Contiene información de los filtros que se enviaran como base para llevar a cabo la consulta | I31: Lista<diagnóstico> | J31: Contiene información del diagnóstico que cumple con el filtro | M31: Diagnostico POL - 0001 | N31: Asegurar que los datos requeridos para llevar a cabo la acción sean válidos a nivel de tipo de dato, longitud, obligatoriedad, formato y rango. | P31: Detener la operación | Q31: Generar una excepción indicándole al usuario que hay problemas con los datos ingresados y de ser posible indicarle cómo solucionarlos | S31: Detener la operación
M32: Diagnostico POL - 0005 | N32: Asegurar que el diagnostico a eliminar no tenga dependencias. | Q32: Generar una excepción indicando al usuario que no es posible eliminar el diagnostico | S32: Detener Operación
A33: Consultar Información del Diagnóstico | C33: Permite ver los diagnósticos registrados | E33: id | F33: Alfanumérico | G33: Contiene el identificador del diagnóstico a eliminar | M33: Diagnostico POL - 0006 | N33: Asegurar que los datos que fueron enviados como filtro para llevar a cabo la acción sean válidos a nivel de tipo de dato, longitud, obligatoriedad, formato y rango. | Q33: Generar una excepción indicándole al usuario que hay problemas con los datos ingresados y de ser posible indicarle cómo solucionarlos | S33: Detener Operación

Sheet Estad servicio Realiz Muestreo 
A2: Corresponde al identificador único que identifica cada estado posible de un servicio realizado en el sistema | B2: Corresponde al atributo que indica el nombre del estado que puede tener un servicio realizado | C2: El estado del servicio realizado no debe tener duplicidad en el nombre del estado
A3: id | B3: nombre | C3: Combinación única
A4: 7946c16d-8570-45c7-8000-157828a7b089 | B4: Pendiente | C4: Pendiente
A5: d92e7939-dfea-490a-848e-a8dd596a5997 | B5: En Proceso | C5: En Proceso
A6: f6383318-5077-4e22-a6d5-3a21bea35515 | B6: Finalizado | C6: Finalizado
A7: 98414d62-96f5-4826-bfa1-b0a883c86a29 | B7: Cancelado | C7: Cancelado

Sheet Estad servicio RealCaracterizac
A2: Objeto de Dominio: | B2: ='Listado Objetos de Dominio'!$A$13 -> Estado Servicio Realizado
A3: Descripción: | B3: ='Listado Objetos de Dominio'!$B$13 -> Objeto de dominio que representa el estado actual de un servicio en proceso o finalizado.
A4: Atributo | B4: Tipo de Dato | C4: Longitud mínima | D4: Longitud máxima | E4: Precisión | F4: Rango Inicial | G4: Rango Final | H4: Formato | I4: Descripción Formato | J4: Valor por defecto | K4: Regla especial | L4: ¿Quitar espacios en blanco al inicio? | M4: ¿Quitar espacios en blanco al final? | N4: ¿Auto generado? | O4: ¿Calculado? | P4: ¿Obligatorio? | Q4: ¿Modificable? | R4: ¿Sensible? | S4: ¿Identifica al registro? | T4: Descripción | U4: =A23 -> Consultar Información del Estado del Servicio Realizado
A5: ='Estad servicio Realiz Muestreo '!A3 -> id | B5: Alfanumérico | C5: 36 | D5: 36 | H5: xxxxxxxx-xxxx-xxxx-xxxx-xxxxxxxxxxxx | I5: Donde cada x es cualquier carácter que puede ir de( 0-9, a-f) | L5: NO | M5: NO | N5: SI | O5: NO | P5: SI | Q5: NO | R5: NO | S5: SI | T5: ='Estad servicio Realiz Muestreo '!A2 -> Corresponde al identificador único que identifica cada estado posible de un servicio realizado en el sistema | U5: Requerido
A6: ='Estad servicio Realiz Muestreo '!B3 -> nombre | B6: Alfanumérico | C6: 1 | D6: 15 | H6: x | I6: Donde x puede ser una cadena que incluye caracteres alfanuméricos, espacios ( ), letras mayúsculas (A-Z), minúsculas (a-z) y tildes (á, é, í, ó, ú) | L6: SI | M6: SI | N6: NO | O6: NO | P6: SI | Q6: NO | R6: NO | S6: NO | T6: ='Estad servicio Realiz Muestreo '!B2 -> Corresponde al atributo que indica el nombre del estado que puede tener un servicio realizado | U6: Requerido
A12: Combinaciones únicas
A13: Nombre combinación | B13: Descripción | C13: Atributos
A14: Nombre del estado del servicio único | B14: ='Estad servicio Realiz Muestreo '!C2 -> El estado del servicio realizado no debe tener duplicidad en el nombre del estado | C14: =A6 -> nombre
A21: Responsabilidad | C21: Descripción | G21: Entradas | J21: Salida | N21: Políticas (Reglas de Negocio) | R21: Excepción
E22: Parámetro | F22: Tipo de dato | H22: Descripción | I22: Tipo de Dato | K22: Descripción | M22: Política | O22: Descripción | Q22: Detalle | S22: ¿Qué hago?
A23: Consultar Información del Estado del Servicio Realizado | C23: Permite crear un nuevo diagnóstico técnico | E23: datos | F23: estadoServicioRealizado | G23: Contiene información de los filtros que se enviaran como base para llevar a cabo la consulta | I23: Lista<estadoServicioRealizado> | J23: Contiene información del Servicio que cumple con el filtro | M23: Estado Servicio Realizado POL - 0001 | N23: Asegurar que los datos que fueron enviados como filtro para llevar a cabo la acción sean válidos a nivel de tipo de dato, longitud, obligatoriedad, formato y rango. | Q23: Generar una excepción indicando al Servicio que el número de cédula ya está registrado. | S23: Detener la operación

Sheet Evidencia Fotográfica Muestreo
A2: Corresponde al identificador único que identifica cada evidencia fotográfica asociada a una motocicleta. | B2: Corresponde al atributo que indica el ángulo de la evidencia fotográfica de la motocicleta. | C2: Corresponde al atributo que indica la placa de la motocicleta a la que pertenece la evidencia fotográfica. | D2: La evidencia fotográfica de la motocicleta no debe tener duplicidad en la combinación del tipo de evidencia fotográfica y la placa de la motocicleta
A3: id | B3: anguloEvidencia | C3: motocicleta | D3: Combinación única
A4: a4d59da0-cbf2-484a-8424-f228b9f028ad | B4: Frontal | C4: MRC35E | D4: =B4 & " - "&C4 -> Frontal - MRC35E
A5: 25047435-2dbd-4f3e-80c8-d5910a1d6f28 | B5: Lateral | C5: MRC35E | D5: =B5 & " - "&C5 -> Lateral - MRC35E
A6: d876e9f8-f80a-44ab-943a-463e036f8686 | B6: Trasera | C6: MRC35E | D6: =B6 & " - "&C6 -> Trasera - MRC35E
A7: 61fa4cf1-d604-4872-b0a3-eba819e3a2d9 | B7: Frontal | C7: AXA66N | D7: =B7 & " - "&C7 -> Frontal - AXA66N
A8: 3d6cefcb-74cd-46c5-9853-4617845c35bb | B8: Lateral | C8: AXA66N | D8: =B8 & " - "&C8 -> Lateral - AXA66N
A9: 5290f01b-cfcb-4db2-8750-1f1a0064defb | B9: Trasera | C9: AXA66N | D9: =B9 & " - "&C9 -> Trasera - AXA66N

Sheet Evidencia Foto Caracterizació 
A1: Inicio
A2: Objeto de Dominio: | B2: ='Listado Objetos de Dominio'!$A$15 -> Evidencia Fotográfica
A3: Descripción: | B3: ='Listado Objetos de Dominio'!$B$15 -> Objeto de dominio que representa las imágenes asociadas a una motocicleta.
A4: Atributo | B4: Tipo de Dato | C4: Longitud mínima | D4: Longitud máxima | E4: Precisión | F4: Rango Inicial | G4: Rango Final | H4: Formato | I4: Descripción Formato | J4: Valor por defecto | K4: Regla especial | L4: ¿Quitar espacios en blanco al inicio? | M4: ¿Quitar espacios en blanco al final? | N4: ¿Auto generado? | O4: ¿Calculado? | P4: ¿Obligatorio? | Q4: ¿Modificable? | R4: ¿Sensible? | S4: ¿Identifica al registro? | T4: Descripción | U4: =A20 -> Cargar evidencia fotográfica de la Motocicleta | V4: =A23 -> Actualizar evidencia fotográfica de la Motocicleta | W4: =A27 -> Eliminar evidencia fotográfica de la Motocicleta | X4: =A25 -> Consultar evidencia fotográfica de la Motocicleta
A5: ='Evidencia Fotográfica Muestreo'!A3 -> id | B5: Alfanumérico | C5: 36 | D5: 36 | H5: xxxxxxxx-xxxx-xxxx-xxxx-xxxxxxxxxxxx | I5: Donde cada x es cualquier carácter que puede ir de( 0-9, a-f) | L5: NO | M5: NO | N5: SI | O5: NO | P5: SI | Q5: NO | R5: NO | S5: SI | T5: ='Evidencia Fotográfica Muestreo'!B2 -> Corresponde al atributo que indica el ángulo de la evidencia fotográfica de la motocicleta. | U5: Requerido | V5: Requerido / No Modificable | W5: Requerido | X5: Filtro/Listar/No Mostrar
A6: ='Evidencia Fotográfica Muestreo'!B3 -> anguloEvidencia | B6: Alfanumérico | C6: 7 | D6: 15 | H6: x | I6: Donde x puede ser una cadena que incluye caracteres alfanuméricos, espacios ( ), letras mayúsculas (A-Z), minúsculas (a-z) y tildes (á, é, í, ó, ú) | L6: NO | M6: NO | N6: NO | O6: NO | P6: SI | Q6: SI | R6: NO | S6: NO | T6: ='Evidencia Fotográfica Muestreo'!B2 -> Corresponde al atributo que indica el ángulo de la evidencia fotográfica de la motocicleta. | U6: Requerido | V6: Requerido / No Modificable | W6: No Requerido | X6: Filtro/Listar/Mostrar[Orden{1}//BusquedaGeneral{NO}/Ordenador{NO}/Reordenamiento{NO}
A7: ='Evidencia Fotográfica Muestreo'!C3 -> motocicleta | B7: motocicleta | L7: NO | M7: NO | N7: NO | O7: NO | P7: SI | Q7: SI | R7: SI | S7: NO | T7: ='Evidencia Fotográfica Muestreo'!C2 -> Corresponde al atributo que indica la placa de la motocicleta a la que pertenece la evidencia fotográfica. | U7: Requerido | V7: Requerido / No Modificable | W7: No Requerido | X7: Filtro/Listar/Mostrar[Orden{2}/CriterioOrdenamiento{1, ASC}/BusquedaGeneral{SI}/Ordenador{SI}/Reordenamiento{NO} /PropiedadesMostrar{ motocicleta.matricula}]
A11: Combinaciones únicas
A12: Nombre combinación | B12: Descripción | C12: Atributos
A13: Angulo y matricula única | B13: ='Evidencia Fotográfica Muestreo'!D2 -> La evidencia fotográfica de la motocicleta no debe tener duplicidad en la combinación del tipo de evidencia fotográfica y la placa de la motocicleta | C13: =A6 -> anguloEvidencia
C14: =A7 -> motocicleta
A18: Responsabilidad | C18: Descripción | G18: Entradas | J18: Salida | N18: Políticas (Reglas de Negocio) | R18: Excepción
E19: Parámetro | F19: Tipo de dato | H19: Descripción | I19: Tipo de Dato | K19: Descripción | M19: Política | O19: Descripción | Q19: Detalle | S19: ¿Qué hago?
A20: Cargar evidencia fotográfica de la Motocicleta | C20: Permite cargar una nueva evidencia fotografía de una motocicleta | E20: Datos | F20: evidenciaFotografica | G20: Contiene información de los datos de la evidencia foto a registrar | M20: Evidencia Fotográfica POL-0002 | N20: Asegurar que los datos requeridos para llevar a cabo la acción sean válidos a nivel de tipo de dato, longitud, obligatoriedad, formato y rango. | Q20: Generar una excepción indicándole al usuario que hay problemas con los datos ingresados y de ser posible indicarle como solucionarlos | S20: Detener Operación
