Workbook

Sheet Flujo de eventos en el tiempo

Sheet Listado Objetos de Dominio
A1: Nombre contexto
A2: Nombre | B2: Descripción | C2: Muestreo
A3: Calificación | B3: Objeto de dominio que representa la valoración numérica dada a un servicio | C3: ver
A4: Categoría | B4: Objeto de dominio que representa la clasificación por Categoría las motocicletas según su tipo o uso. | C4: ver
A5: Ciudad | B5: Objeto de dominio que representa la ciudad donde se encuentra ubicada la sede. | C5: ver
A6: Departamento | B6: Objeto de dominio que representa la división territorial donde se encuentra la ciudad. | C6: ver
A7: Detalle Horario | B7: Objeto de dominio que representa la información específica de los horarios de atención de la sede. | C7: ver
A8: Dia | B8: Objeto de dominio que representa cada uno de los días de la semana en que opera el establecimiento. | C8: ver
A9: Diagnostico | B9: Objeto de dominio que representa la evaluación técnica realizada a una motocicleta por parte de una sede. | C9: ver
A10: Sede | B10: Objeto de dominio que representa el local comercial que ofrece servicios para motocicletas. | C10: ver
A11: Represéntate sede | B11: Objeto de dominio que representa la persona responsable de gestionar una sede específica del establecimiento. | C11: ver
A12: Servicio sede | B12: Objeto de dominio que representa la relación entre una sede y los servicios que ofrece. | C12: ver
A13: Estado Servicio Realizado | B13: Objeto de dominio que representa el estado actual de un servicio en proceso o finalizado. | C13: ver
... A32: Transición Estado Servicio Realizado | B32: Objeto de dominio que gestiona las transiciones de estados de un servicio | C32: ver

Sheet Categoria
A1: <-Volver al inicio
A2: Objeto de Dominio: | B2: ='Listado Objetos de Dominio'!A4 -> Categoría
A3: Descripción: | B3: ='Listado Objetos de Dominio'!B4 -> Objeto de dominio que representa la clasificación por Categoría las motocicletas según su tipo o uso.
A4: Actor | B4: Action/Command | D4: Entity/Aggregate/Object domain | E4: Read Model | G4: Business Rule/Policy | I4: External System | J4: Domain Event | K4: Hotspot/questions/Risk | L4: Eventos Previos | M4: Comandos Posteriores
A5: Actor | B5: Acción | C5: Descripción | D5: Objeto de dominio | E5: Información externa | G5: Políticas | I5: Sistema Externo | J5: Evento | K5: Aspectos por solucionar
E6: Información | F6: Descripción | G6: Número | H6: Descripción
A7: Administrador | B7: Editar la Información de una Categoría Motocicleta | C7: Permite actualizar la información de una categoría de motocicleta. | D7: Categoría | J7: Categoría de Motocicleta Editada | L7: Categoría Motocicleta Consultada | M7: Consultar Categoría Motocicleta
G8: Categoría POL-0001 | H8: Asegurar que los datos requeridos para llevar a cabo la acción sean válidos a nivel de tipo de dato, longitud, obligatoriedad, formato y rango.
A10: Usuario/Representante | B10: Consultar la Información de una Categoría Motocicleta | C10: Permite buscar una categoría de motocicleta. | D10: Categoría | G10: Categoría POL-0002 | H10: Asegurar que los datos que fueron enviados como filtro para llevar a cabo la acción sean válidos a nivel de tipo de dato, longitud, obligatoriedad, formato y rango.. | J10: Categoría de Motocicleta Consultada | L10: Categoría Motocicleta Modificada | M10: Modificar Categoría Motocicleta

Sheet Calificacion
A1: <-Volver al inicio
A2: Objeto de Dominio: | B2: ='Listado Objetos de Dominio'!$A$3 -> Calificación
A3: Descripción: | B3: ='Listado Objetos de Dominio'!$B$3 -> Objeto de dominio que representa la valoración numérica dada a un servicio
A4: Actor | B4: Action/Command | D4: Entity/Aggregate/Object domain | E4: Read Model | G4: Business Rule/Policy | I4: External System | J4: Domain Event | K4: Hotspot/questions/Risk | L4: Eventos Previos | M4: Comandos Posteriores
A5: Actor | B5: Acción | C5: Descripción | D5: Objeto de dominio | E5: Información externa | G5: Políticas | I5: Sistema Externo | J5: Evento | K5: Aspectos por solucionar
E6: Información | F6: Descripción | G6: Número | H6: Descripción
A8: Usuario | B8: Registrar Información de la Calificación | C8: Permite valorar un servicio realizado | D8: Calificación | E8: Información del Servicio Realizado | F8: Información del servicio realizado que fue calificado | G8: Calificación POL - 0004 | H8: No debe existir otra calificación de un servicio con el mismo identificador. | J8: Calificación Registrada | L8: Calificación Consultada | M8: Consultar Calificación
E9: Información del Rango de Calificación | F9: Información que indica el valor de la calificación de un servicio realizado | G9: Calificación POL-0001 | H9: Asegurar que los datos requeridos para llevar a cabo la acción sean válidos a nivel de tipo de dato, longitud, obligatoriedad, formato y rango. | M9: Eliminar Calificación
G10: Calificación POL - 0005 | H10: Se debe asegurar que la información a comentar no sean información sensible
A15: Usuario | B15: Modificar Información de la Calificación | C15: Permite modificar una calificación echa a un servicio realizado | D15: Calificación | E15: Información del Servicio Realizado | F15: Información del servicio realizado que fue calificado y puede ser eliminado | G15: Calificación POL-0002 | H15: La calificación debe estar previamente registrada | J15: Calificación Modificada | L15: Calificación Registrada | M15: Consultar Calificación
G16: Calificación POL - 0005 | H16: Se debe asegurar que la información a comentar no sean información sensible
E17: Información del Rango de Calificación | F17: Información que indica el valor de la calificación de un servicio realizado que puede ser eliminado | G17: Calificación POL-0001 | H17: Asegurar que los datos requeridos para llevar a cabo la acción sean válidos a nivel de tipo de dato, longitud, obligatoriedad, formato y rango. | L17: Calificación Consultada | M17: Eliminar Calificación
L21: Calificación Modificada | M21: Modificar Calificación
A22: Usuario/Representante Sede | B22: Consultar Información de la Calificación | C22: Permite ver las calificaciones registradas | D22: Calificación | E22: Información del Servicio Realizado | F22: Información del servicio realizado que fue calificado | G22: Calificación POL-0006 | H22: Asegurar que los datos que fueron enviados como filtro para llevar a cabo la acción sean válidos a nivel de tipo de dato, longitud, obligatoriedad, formato y rango. | I22: Sistema de Calificaciones | J22: Calificación Consultada | L22: Calificación Registrada | M22: Registrar Calificación
E23: Información del Rango de Calificación | F23: Información que indica el valor de la calificación de un servicio realizado | L23: Calificación Consultada | M23: Consultar Calificación
L24: Calificación Eliminada | M24: Eliminar Calificación

Sheet Ciudad
A1: <-Volver al inicio
A2: Objeto de Dominio: | B2: ='Listado Objetos de Dominio'!A5 -> Ciudad
A3: Descripción: | B3: ='Listado Objetos de Dominio'!B5 -> Objeto de dominio que representa la ciudad donde se encuentra ubicada la sede.
A4: Actor | B4: Action/Command | D4: Entity/Aggregate/Object domain | E4: Read Model | G4: Business Rule/Policy | I4: External System | J4: Domain Event | K4: Hotspot/questions/Risk | L4: Eventos Previos | M4: Comandos Posteriores
A5: Actor | B5: Acción | C5: Descripción | D5: Objeto de dominio | E5: Información externa | G5: Políticas | I5: Sistema Externo | J5: Evento | K5: Aspectos por solucionar
E6: Información | F6: Descripción | G6: Número | H6: Descripción
A8: Usuario/Representante Sede | B8: Consultar Información de la Ciudad | C8: Permite visualizar la información de una ciudad | D8: Ciudad | E8: Departamento | F8: Información que indica a que departamento pertenece una ciudad | G8: Ciudad POL-0001 | H8: Asegurar que los datos que fueron enviados como filtro para llevar a cabo la acción sean válidos a nivel de tipo de dato, longitud, obligatoriedad, formato y rango. | J8: Ciudad Consultada

Sheet Departa
A1: <-Volver al inicio
A2: Objeto de Dominio: | B2: ='Listado Objetos de Dominio'!A6 -> Departamento
A3: Descripción: | B3: ='Listado Objetos de Dominio'!B6 -> Objeto de dominio que representa la división territorial donde se encuentra la ciudad.
A4: Actor | B4: Action/Command | D4: Entity/Aggregate/Object domain | E4: Read Model | G4: Business Rule/Policy | I4: External System | J4: Domain Event | K4: Hotspot/questions/Risk | L4: Eventos Previos | M4: Comandos Posteriores
A5: Actor | B5: Acción | C5: Descripción | D5: Objeto de dominio | E5: Información externa | G5: Políticas | I5: Sistema Externo | J5: Evento | K5: Aspectos por solucionar
E6: Información | F6: Descripción | G6: Número | H6: Descripción
A7: Usuario/Representante Sede | B7: Consultar Información del Departamento | C7: Permite visualizar la información de un departamento | D7: Departamento | G7: Departamento POL-0001 | H7: Asegurar que los datos que fueron enviados como filtro para llevar a cabo la acción sean válidos a nivel de tipo de dato, longitud, obligatoriedad, formato y rango. | J7: Departamento Consultado

Sheet Detalle Horario
A1: <-Volver al inicio
A2: Objeto de Dominio: | B2: ='Listado Objetos de Dominio'!$A$7 -> Detalle Horario
A3: Descripción: | B3: ='Listado Objetos de Dominio'!$B$7 -> Objeto de dominio que representa la información específica de los horarios de atención de la sede.
A4: Actor | B4: Action/Command | D4: Entity/Aggregate/Object domain | E4: Read Model | G4: Business Rule/Policy | I4: External System | J4: Domain Event | K4: Hotspot/questions/Risk | L4: Eventos Previos | M4: Comandos Posteriores
A5: Actor | B5: Acción | C5: Descripción | D5: Objeto de dominio | E5: Información externa | G5: Políticas | I5: Sistema Externo | J5: Evento | K5: Aspectos por solucionar
E6: Información | F6: Descripción | G6: Número | H6: Descripción
A8: Representante Sede | B8: Registrar Información del Detalle Horario | C8: Permite registrar los detalles de los horarios y días de operación de una sede | D8: Detalle Horario | E8: Información de la Sede | F8: Información que indica cuál es la sede a la que se le crea el horario | G8: Detalle Horario POL-0004 | H8: La sede debe estar previamente registrada. | J8: Detalle Horario Registrado | L8: Detalle Horario Consultado | M8: Consultar Detalle Horario
E9: Información del Día | F9: Información que indica cual es el día que se puede asociar a la sede y al horario | G9: Detalle Horario POL-0003 | H9: El día debe estar Registrado. | M9: Modificar Detalle Horario
G10: Detalle Horario POL-0001 | H10: Asegurar que los datos requeridos para llevar a cabo la acción sean válidos a nivel de tipo de dato, longitud, obligatoriedad, formato y rango. | M10: Eliminar Detalle horario
G11: Detalle Horario POL-0002 | H11: No debe existir otro detalle horario con el mismo identificador.
A14: Representante Sede | B14: Modificar Información del Detalle Horario | C14: Permite actualizar la información de los detalles de horarios y días de operación de una sede | D14: Detalle Horario | E14: Información de la Sede | F14: Información que indica cuál es la sede a la que se le puede modificar el horario | G14: Detalle Horario POL-0005 | H14: La sede y el día deben estar previamente asociados. | J14: Detalle Horario Modificado | L14: Detalle Horario Registrado | M14: Consultar Detalle Horario
E15: Información del Día | F15: Información que indica cual es el día que se puede modificar a la sede y al horario | G15: Detalle Horario POL-0001 | H15: Asegurar que los datos requeridos para llevar a cabo la acción sean válidos a nivel de tipo de dato, longitud, obligatoriedad, formato y rango. | L15: Detalle Horario Consultado | M15: Eliminar Detalle Horario
A20: Representante Sede | B20: Eliminar Información del Detalle Horario | C20: Permite eliminar un detalle horario específico de una sede | D20: Detalle Horario | E20: Información de la Sede | F20: Información que indica cuál es la sede a la que se le puede eliminar el horario | G20: Detalle Horario POL-0006 | H20: Asegurarse que el detalle horario a eliminar no se encuentre asociado a una sede | J20: Detalle Horario Eliminado | L20: Detalle Horario Registrado | M20: Consultar Detalle Horario
E21: Información del Día | F21: Información que indica cual es el día que se puede eliminar la sede y al horario | G21: Detalle Horario POL-0001 | H21: Asegurar que los datos requeridos para llevar a cabo la acción sean válidos a nivel de tipo de dato, longitud, obligatoriedad, formato y rango. | L21: Detalle Horario Consultado
L22: Detalle Horario Modificado | M22: Registrar Detalle Horario
A26: Usuario/Representante Sede | B26: Consultar Información del Detalle Horario | C26: Permite consultar los detalles horarios configurados para una sede | D26: Detalle Horario | E26: Información de la Sede | F26: Información que indica cuál es la sede asociada al detalle horario | G26: Detalle Horario POL-0007 | H26: Asegurar que los datos que fueron enviados como filtro para llevar a cabo la acción sean válidos a nivel de tipo de dato, longitud, obligatoriedad, formato y rango. | J26: Detalle Horario Consultado | L26: Detalle Horario Registrado | M26: Registrar Detalle Horario
E27: Información del Día | F27: Información que indica cual es el día asociado al detalle horario | L27: Detalle Horario Modificado | M27: Modificar Detalle Horario
L28: Detalle Horario Eliminado | M28: Eliminar Detalle Horario

Sheet Dia
A1: <-Volver al inicio
A2: Objeto de Dominio: | B2: ='Listado Objetos de Dominio'!A8 -> Dia
A3: Descripción: | B3: ='Listado Objetos de Dominio'!B8 -> Objeto de dominio que representa cada uno de los días de la semana en que opera el establecimiento.
A4: Actor | B4: Action/Command | D4: Entity/Aggregate/Object domain | E4: Read Model | G4: Business Rule/Policy | I4: External System | J4: Domain Event | K4: Hotspot/questions/Risk | L4: Eventos Previos | M4: Comandos Posteriores
A5: Actor | B5: Acción | C5: Descripción | D5: Objeto de dominio | E5: Información externa | G5: Políticas | I5: Sistema Externo | J5: Evento | K5: Aspectos por solucionar
E6: Información | F6: Descripción | G6: Número | H6: Descripción
A8: Usuario/Representante Sede | B8: Consultar Información del Día | C8: Permite ver la información del día de la semana | D8: Día | G8: Día POL-0001 | H8: Asegurar que los datos que fueron enviados como filtro para llevar a cabo la acción sean válidos a nivel de tipo de dato, longitud, obligatoriedad, formato y rango. | J8: Día Consultado

Sheet Diagnostico
A1: <-Volver al inicio
A2: Objeto de Dominio: | B2: ='Listado Objetos de Dominio'!$A$15 -> Evidencia Fotográfica
A3: Descripción: | B3: ='Listado Objetos de Dominio'!$B$15 -> Objeto de dominio que representa las imágenes asociadas a una motocicleta.
A4: Actor | B4: Action/Command | D4: Entity/Aggregate/Object domain | E4: Read Model | G4: Business Rule/Policy | I4: External System | J4: Domain Event | K4: Hotspot/questions/Risk | L4: Eventos Previos | M4: Comandos Posteriores
A5: Actor | B5: Acción | C5: Descripción | D5: Objeto de dominio | E5: Información externa | G5: Políticas | I5: Sistema Externo | J5: Evento | K5: Aspectos por solucionar
E6: Información | F6: Descripción | G6: Número | H6: Descripción
A8: Representante Sede | B8: Registrar Información del Diagnóstico | C8: Permite crear un nuevo diagnóstico técnico | D8: Diagnóstico | E8: Información de la Motocicleta | F8: Información que indica cuál es la motocicleta a la que se le está realizando el diagnóstico | G8: Diagnostico POL - 0001 | H8: Asegurar que los datos requeridos para llevar a cabo la acción sean válidos a nivel de tipo de dato, longitud, obligatoriedad, formato y rango. | L8: Diagnóstico Consultado | M8: Consultar Diagnóstico
E9: Información de la Sede | F9: Información que indica cuales la sede que está haciendo el diagnóstico | G9: Diagnostico POL - 0002 | H9: La sede debe estar previamente registrada | M9: Editar Diagnóstico
G10: Diagnostico POL - 0003 | H10: La motocicleta debe estar previamente registrada | M10: Eliminar Diagnóstico
G11: Diagnostico POL - 0004 | H11: No puede existir otro diagnostico con el mismo identificador.
A15: Representante Sede | B15: Modificar Información del Diagnóstico | C15: Permite actualizar un diagnóstico existente | D15: Diagnóstico | E15: Información de la Motocicleta | F15: Información que indica cuál es la motocicleta a la que se le puede modificar el diagnóstico | G15: Diagnostico POL - 0001 | H15: Asegurar que los datos requeridos para llevar a cabo la acción sean válidos a nivel de tipo de dato, longitud, obligatoriedad, formato y rango. | L15: Diagnóstico Registrado | M15: Consultar Diagnóstico
E16: Información de la Sede | F16: Información que indica cuales la sede que está modificando el diagnóstico | L16: Diagnóstico Consultado | M16: Eliminar Diagnóstico
A21: Representante Sede | B21: Eliminar Información del Diagnóstico | C21: Permite eliminar un diagnóstico | D21: Diagnóstico | E21: Información de la Motocicleta | F21: Información que indica cuál es la motocicleta a la que se le puede eliminar el diagnóstico | G21: Diagnostico POL - 0001 | H21: Asegurar que los datos requeridos para llevar a cabo la acción sean válidos a nivel de tipo de dato, longitud, obligatoriedad, formato y rango. | J21: Detener la operación | L21: Diagnóstico Registrado | M21: Consultar Diagnóstico
E22: Información de la Sede | F22: Información que indica cuales la sede que está registrada en el diagnóstico a eliminar | G22: Diagnostico POL - 0005 | H22: Asegurar que el diagnostico a eliminar no tenga dependencias. | L22: Diagnóstico Consultado | M22: Registrar Diagnóstico
L23: Diagnóstico Editado
L26: Diagnóstico Consultado | M26: Consultar Diagnóstico
A27: Representante Sede/Usuario | B27: Consultar Información del Diagnóstico | C27: Permite ver los diagnósticos registrados | D27: Diagnóstico | E27: Información de la Motocicleta | F27: Información que indica cuál es la motocicleta a la que se le hizo diagnóstico | G27: Diagnostico POL - 0006 | H27: Asegurar que los datos que fueron enviados como filtro para llevar a cabo la acción sean válidos a nivel de tipo de dato, longitud, obligatoriedad, formato y rango. | L27: Diagnóstico Registrado | M27: Registrar Diagnóstico
E28: Información de la Sede | F28: Información que indica cuales la sede que hizo el diagnóstico | L28: Diagnóstico Editado | M28: Editar Diagnóstico
L29: Diagnóstico Eliminado | M29: Eliminar Diagnóstico

Sheet Estado Servicio Realizado
A1: <-Volver al inicio
A2: Objeto de Dominio: | B2: Estado Servicio Realizado
A3: Descripción: | B3: Objeto de dominio que representa el estado actual de un servicio en proceso o finalizado.
A4: Actor | B4: Action/Command | D4: Entity/Aggregate/Object domain | E4: Read Model | G4: Business Rule/Policy | I4: External System | J4: Domain Event | K4: Hotspot/questions/Risk | L4: Eventos Previos | M4: Comandos Posteriores
A5: Actor | B5: Acción | C5: Descripción | D5: Objeto de dominio | E5: Información externa | G5: Políticas | I5: Sistema Externo | J5: Evento | K5: Aspectos por solucionar
E6: Información | F6: Descripción | G6: Número | H6: Descripción
A7: Usuario/Representante Sede | B7: Consultar Información del Estado del Servicio Realizado | C7: Permite ver el estado actual de un servicio | D7: Estado Servicio | G7: Estado Servicio Realizado POL-0001 | H7: Asegurar que los datos que fueron enviados como filtro para llevar a cabo la acción sean válidos a nivel de tipo de dato, longitud, obligatoriedad, formato y rango. | J7: Estado Servicio Consultado

Sheet Evidencia Fotografica
A1: <-Volver al inicio
A2: Objeto de Dominio: | B2: ='Listado Objetos de Dominio'!$A$15 -> Evidencia Fotográfica
A3: Descripción: | B3: ='Listado Objetos de Dominio'!$B$15 -> Objeto de dominio que representa las imágenes asociadas a una motocicleta.
A4: Actor | B4: Action/Command | D4: Entity/Aggregate/Object domain | E4: Read Model | G4: Business Rule/Policy | I4: External System | J4: Domain Event | K4: Hotspot/questions/Risk | L4: Eventos Previos | M4: Comandos Posteriores
A5: Actor | B5: Acción | C5: Descripción | D5: Objeto de dominio | E5: Información externa | G5: Políticas | I5: Sistema Externo | J5: Evento | K5: Aspectos por solucionar
E6: Información | F6: Descripción | G6: Número | H6: Descripción
M7: Actualizar evidencia fotográfica Motocicleta
A8: Usuario | B8: Cargar Evidencia Fotográfica de la Motocicleta | C8: Permite cargar una nueva evidencia fotografía de una motocicleta | D8: evidencia fotográfica | E8: Información de la Motocicleta | F8: Información que identifica la imagen que pertenece a la motocicleta a cargar | G8: Evidencia Foto POL-0002 | H8: Asegurar que los datos requeridos para llevar a cabo la acción sean válidos a nivel de tipo de dato, longitud, obligatoriedad, formato y rango. | J8: evidencia fotográfica Capturada | K8: Definir estándares específicos de calidad | L8: evidencia fotográfica Consultada | M8: Consultar evidencia fotográfica Motocicleta
E9: Información de la imagen | F9: Información que indica cuales son las evidencias fotográficas que conforman la imagen a cargar | G9: Evidencia Foto POL-0003 | H9: La evidencia fotográfica debe de estar previamente verificada | K9: Gestión de permisos | M9: Eliminar evidencia fotográfica Motocicleta
G10: Evidencia Foto POL-0005 | H10: No puede existir otra evidencia fotográfica con el mismo identificador. | M10: Guardar evidencia fotográfica Motocicleta
A12: Usuario | B12: Actualizar Evidencia Fotográfica de la Motocicleta | C12: Permite hacer cambios en la evidencia fotográfica de motocicleta | D12: evidencia fotográfica | E12: Información de la Motocicleta | F12: Información que identifica la imagen que pertenece a la motocicleta a guardar | G12: Evidencia Foto POL-0002 | H12: Asegurar que los datos requeridos para llevar a cabo la acción sean válidos a nivel de tipo de dato, longitud, obligatoriedad, formato y rango. | J12: evidencia fotográfica Guardada | K12: Gestión de almacenamiento | L12: evidencia fotográfica Capturada | M12: Consultar evidencia fotográfica Motocicleta
E13: Información de la imagen | F13: Información que indica cuales son las evidencias fotográficas que conforman la imagen a guardar | G13: Evidencia Foto POL-0003 | H13: La evidencia fotográfica debe de estar previamente verificada | L13: evidencia fotográfica Consultada | M13: Eliminar evidencia fotográfica Motocicleta
M14: Capturar evidencia fotográfica Motocicleta
L15: evidencia fotográfica Guardada | M15: Eliminar evidencia fotográfica Motocicleta
A16: Usuario/Representante Sede | B16: Consultar Evidencia Fotográfica de la Motocicleta | C16: Permite visualizar una evidencia fotográfica específica de una motocicleta | D16: evidencia fotográfica | E16: Información de la Motocicleta | F16: Información que identifica la imagen que pertenece a la motocicleta a consultar | G16: Evidencia Foto POL-0006 | H16: Asegurar que los datos que fueron enviados como filtro para llevar a cabo la acción sean válidos a nivel de tipo de dato, longitud, obligatoriedad, formato y rango. | J16: evidencia fotográfica Consultada | L16: evidencia fotográfica Capturada | M16: Guardar evidencia fotográfica Motocicleta
E17: Información de la imagen | F17: Información que indica cuales son las evidencias fotográficas que conforman la imagen a consultar | L17: evidencia fotográfica Eliminada | M17: Capturar evidencia fotográfica Motocicleta
A18: Usuario | B18: Eliminar Evidencia Fotográfica de la Motocicleta | C18: Permite eliminar una evidencia fotográfica existente del sistema | D18: evidencia fotográfica | E18: Información de la Motocicleta | F18: Información que identifica la imagen que pertenece a la motocicleta a eliminar | G18: Evidencia Foto POL-0004 | H18: La evidencia fotográfica por eliminar debe existir | J18: evidencia fotográfica Eliminada | L18: evidencia fotográfica Consultada | M18: Capturar evidencia fotográfica Motocicleta
E19: Información de la imagen | F19: Información que indica cuales son las evidencias fotográficas que conforman la imagen a eliminar | L19: evidencia fotográfica Capturada | M19: Consultar evidencia fotográfica Motocicleta
L20: evidencia fotográfica Guardada

Sheet Excepcion Horario
A1: <-Volver al inicio
A2: Objeto de Dominio: | B2: ='Listado Objetos de Dominio'!$A$14 -> Excepción Horario
A3: Descripción: | B3: ='Listado Objetos de Dominio'!$B$14 -> Objeto de dominio que representa las excepciones o casos especiales en los horarios de atención.
A4: Actor | B4: Action/Command | D4: Entity/Aggregate/Object domain | E4: Read Model | G4: Business Rule/Policy | I4: External System | J4: Domain Event | K4: Hotspot/questions/Risk | L4: Eventos Previos | M4: Comandos Posteriores
A5: Actor | B5: Acción | C5: Descripción | D5: Objeto de dominio | E5: Información externa | G5: Políticas | I5: Sistema Externo | J5: Evento | K5: Aspectos por solucionar
E6: Información | F6: Descripción | G6: Número | H6: Descripción
M7: Activar Excepción Horario
A8: Representante Sede | B8: Registrar Información de la Excepción de Horario | C8: Permite crear una nueva excepción en el horario regular | D8: Excepción Horario | E8: Información de Horario Sede | F8: Información que indica cual es la sede a la que se va a registrar una excepción en el horario ya establecido | G8: Excepción Horario POL- 0004 | H8: La excepción de horario debe ser programada con mínimo 24 horas de anticipación y no puede ser programada para una fecha que esté antes de la actual | L8: Consultar Excepción horario | M8: Consultar Excepción Horario
G9: Excepción Horario POL- 0003 | H9: La excepción debe estar dentro del horario regular | M9: Eliminar Excepción Horario
G10: Excepción Horario POL- 0002 | H10: No debe existir una excepción horario con el mismo identificador. | M10: Editar Excepción Horario
G11: Excepción Horario POL- 0001 | H11: Asegurar que los datos requeridos para llevar a cabo la acción sean válidos a nivel de tipo de dato, longitud, obligatoriedad, formato y rango. | M11: Desactivar Excepción Horario
L13: Excepción Horario Desactivada | M13: Eliminar Excepción Horario
L14: Excepción Horario Consultada | M14: Activar Excepción Horario
A15: Representante Sede | B15: Modificar Información de la Excepción Horario | C15: Permite actualizar una excepción existente | D15: Excepción Horario | E15: Información de Horario Sede | F15: Información que indica la sede y los detalles de la excepción que se va a modificar en el horario establecido | G15: Excepción Horario POL-0005 | H15: Solo se pueden modificar excepciones futuras | J15: Excepción Horario Modificada | L15: Excepción Horario Registrada | M15: Consultar Excepción Horario
G16: Excepción Horario POL-0001 | H16: Asegurar que los datos requeridos para llevar a cabo la acción sean válidos a nivel de tipo de dato, longitud, obligatoriedad, formato y rango. | L16: Excepción Horario Activada | M16: Desactivar Excepción Horario
L20: Excepción Horario Desactivada
A21: Representante Sede | B21: Eliminar Información de la Excepción Horario | C21: Permite eliminar una excepción de horario | D21: Excepción Horario | E21: Información de Horario Sede | F21: Información que identifica la sede y la excepción específica que se desea eliminar del horario | G21: Excepción Horario POL-0006 | H21: Solo se pueden eliminar excepciones futuras | J21: Excepción Horario Eliminada | L21: Excepción Horario Registrada | M21: Consultar Excepción Horario
G22: Excepción Horario POL-0001 | H22: Asegurar que los datos requeridos para llevar a cabo la acción sean válidos a nivel de tipo de dato, longitud, obligatoriedad, formato y rango. | L22: Excepción Horario Consultada | M22: Registrar Excepción Horario
L23: Excepción Horario Modificada
M25: Eliminar Excepción Horario
L26: Excepción Horario Activada | M26: Activar Excepción Horario
A27: Representante Sede | B27: Consultar Información de la Excepción Horario | C27: Permite ver las excepciones programadas | D27: Excepción Horario | E27: Información de Horario Sede | F27: Información que permite identificar la sede y los criterios de búsqueda para consultar las excepciones de horario | G27: Excepción Horario POL-0007 | H27: Asegurar que los datos que fueron enviados como filtro para llevar a cabo la acción sean válidos a nivel de tipo de dato, longitud, obligatoriedad, formato y rango. | J27: Excepción Horario Consultada | L27: Excepción Horario Registrada | M27: Registrar Excepción Horario
L28: Excepción Horario Modificada | M28: Modificar Excepción Horario
L29: Excepción Horario Desactivada | M29: Desactivar Excepción Horario
L32: Excepción Horario Consultada | M32: Desactivar Excepción Horario
A33: Representante Sede | B33: Activar la Excepción Horario | C33: Permite activar una excepción de horario | D33: Excepción Horario | E33: Información de Horario Sede | F33: Información que identifica la sede y la excepción a activar | G33: Excepción Horario POL-0001 | H33: Asegurar que los datos requeridos para llevar a cabo la acción sean válidos a nivel de tipo de dato, longitud, obligatoriedad, formato y rango. | J33: Excepción Horario Activada | L33: Excepción Horario Registrada | M33: Consultar Excepción Horario
G34: Excepción Horario POL - 0008 | H34: la excepción horario debe estar previamente desactivado | L34: Excepción Horario Modificada | M34: Modificar Excepción Horario
L35: Excepción Horario Desactivada
L38: Excepción Horario Desactivada | M38: Activar Excepción Horario
A39: Representante Sede | B39: Desactivar la Excepción Horario | C39: Permite desactivar una excepción de horario | D39: Excepción Horario | E39: Información de Horario Sede | F39: Información que identifica la sede y la excepción a desactivar | G39: Excepción Horario POL-0001 | H39: Asegurar que los datos requeridos para llevar a cabo la acción sean válidos a nivel de tipo de dato, longitud, obligatoriedad, formato y rango. | J39: Excepción Horario Desactivada | L39: Excepción Horario Modificada | M39: Consultar Excepción Horario
G40: Excepción Horario POL - 0009 | H40: la excepción horario debe estar previamente activado | L40: Excepción Horario Consultada | M40: Modificar Excepción Horario
L41: Excepción Horario Registrada | M41: Eliminar Excepción Horario

Sheet Franquicia
A1: <-Volver al inicio
A2: Objeto de Dominio: | B2: Franquicia
A3: Descripción: | B3: Objeto de dominio que representa el local comercial que ofrece servicios para motocicletas.
A4: Actor | B4: Action/Command | D4: Entity/Aggregate/Object domain | E4: Read Model | G4: Business Rule/Policy | I4: External System | J4: Domain Event | K4: Hotspot/questions/Risk | L4: Eventos Previos | M4: Comandos Posteriores
A5: Actor | B5: Acción | C5: Descripción | D5: Objeto de dominio | E5: Información externa | G5: Políticas | I5: Sistema Externo | J5: Evento | K5: Aspectos por solucionar
E6: Información | F6: Descripción | G6: Número | H6: Descripción
G7: Franquicia-POL-001 | H7: Asegurar que los datos requeridos para llevar a cabo la acción sean válidos a nivel de tipo de dato, longitud, obligatoriedad, formato y rango. | L7: Franquicia Consultada | M7: Modificar Franquicia
A8: Representante Sede | B8: Registrar Información de la Franquicia | C8: Permite crear un nuevo Franquicia en el sistema | D8: Franquicia | G8: Franquicia- POL-0002 | H8: No debe existir una franquicia previamente registrada con el mismo nombre. | J8: Franquicia Registrada | M8: Eliminar Franquicia
G9: Franquicia- POL-0003 | H9: No puede existir otra franquicia con el mismo identificador. | M9: Consultar Franquicia
L10: Franquicia Agregada | M10: Eliminar Franquicia
A11: Representante Sede | B11: Modificar Información de la Franquicia | C11: Permite modificar la información del Franquicia | D11: Franquicia | G11: Franquicia-POL-0001 | H11: Asegurar que los datos requeridos para llevar a cabo la acción sean válidos a nivel de tipo de dato, longitud, obligatoriedad, formato y rango. | J11: Franquicia Modificada | L11: Franquicia Consultada | M11: Consultar Franquicia
L13: Franquicia Consultada
A14: Representante Sede | B14: Eliminar Información de la Franquicia | C14: Permite dar de baja a un Franquicia | D14: Franquicia | G14: Franquicia- POL-0004 | H14: La Franquicia a eliminar no debe de tener sedes asociadas | J14: Franquicia Actualizado | L14: Franquicia Editada | M14: Consultar Franquicia
L15: Franquicia Agregada | M15: Agregar Franquicia
A16: Representante Sede | B16: Consultar Información de la Franquicia | C16: Permite ver la información del Franquicia y sus sedes | D16: Franquicia | G16: Franquicia-POL-0005 | H16: Asegurar que los datos que fueron enviados como filtro para llevar a cabo la acción sean válidos a nivel de tipo de dato, longitud, obligatoriedad, formato y rango. | J16: Franquicia Consultada | L16: Franquicia Agregada | M16: Modificar Franquicia
L17: Franquicia Editado | M17: Agregar Franquicia
L18: Franquicia Eliminada | M18: Eliminar Franquicia

Sheet Horario Sede
A1: <-Volver al inicio
A2: Objeto de Dominio: | B2: Horario Sede
A3: Descripción: | B3: Objeto de dominio que representa los horarios generales de operación de cada una de las sedes
A4: Actor | B4: Action/Command | D4: Entity/Aggregate/Object domain | E4: Read Model | G4: Business Rule/Policy | I4: External System | J4: Domain Event | K4: Hotspot/questions/Risk | L4: Eventos Previos | M4: Comandos Posteriores
A5: Actor | B5: Acción | C5: Descripción | D5: Objeto de dominio | E5: Información externa | G5: Políticas | I5: Sistema Externo | J5: Evento | K5: Aspectos por solucionar
E6: Información | F6: Descripción | G6: Número | H6: Descripción
G8: Horario Sede POL-0004 | H8: La sede debe estar previamente registrada | M8: Consultar Horario sede
G9: Horario Sede POL-0003 | H9: Los horarios no se deben de solapar entre sí | M9: Modificar Horario Sede
A10: Representante Sede | B10: Registrar Información del Horario Sede | C10: Permite registrar los horarios de operación regulares de una sede | D10: Horario Sede | E10: Información de la sede | F10: Información que indica cual es la sede a la que se le crea el horario | G10: Horario Sede POL-0001 | H10: Asegurar que los datos requeridos para llevar a cabo la acción sean válidos a nivel de tipo de dato, longitud, obligatoriedad, formato y rango. | J10: Horario Sede Registrado | L10: Horario Sede Consultado | M10: Activar Horario Sede
G11: Horario Sede POL-0002 | H11: No debe haber horarios repetidos para una misma sede | M11: Desactivar Horario Sede
G12: Horario Sede POL-0005 | H12: No debe haber horarios registrados con el mismo identificador | M12: Eliminar horario Sede
A14: Representante Sede | B14: Modificar Información del Horario Sede | C14: Permite actualizar los horarios existentes de una sede | D14: Horario Sede | E14: Información de la sede | F14: Información que indica a cual sede se le puede modificar el horario | G14: Horario Sede POL-0001 | H14: Asegurar que los datos requeridos para llevar a cabo la acción sean válidos a nivel de tipo de dato, longitud, obligatoriedad, formato y rango. | J14: Horario Sede Modificado | L14: Horario Sede Consultado | M14: Consultar Horario sede
G15: Horario Sede POL-0003 | H15: Los horarios no se deben de solapar | L15: Horario Sede Creado | M15: Eliminar horario Sede
G16: Horario Sede POL-0006 | H16: Debe existir una sede previamente asociada a un horario | L16: Horario Sede Desactivado | M16: Activar Horario Sede
L17: Horario Sede Activado | M17: Desactivar Horario Sede
L19: Horario Sede Creado | M19: Crear Horario Sede
A20: Representante Sede | B20: Consultar Información del Horario Sede | C20: Permite ver los horarios de una sede | D20: Horario Sede | E20: Información de la sede | F20: Información que indica a que sede está asociado el horario | G20: Horario Sede POL-0007 | H20: Asegurar que los datos que fueron enviados como filtro para llevar a cabo la acción sean válidos a nivel de tipo de dato, longitud, obligatoriedad, formato y rango. | J20: Horario Sede Consultado | L20: Horario Sede Activado | M20: Activar Horario Sede
L21: Horario Sede Desactivado | M21: Desactivar Horario Sede
L22: Horario Sede Modificado | M22: Modificar Horario Sede
L23: Horario Sede Eliminado | M23: Eliminar horario Sede
A26: Representante Sede | B26: Eliminar Información del Horario Sede | C26: Permite dar de baja a horarios de una sede. | D26: Horario Sede | E26: Información de la sede | F26: Información que indica a que sede está asociado el horario a eliminar | G26: Horario Sede POL-0008 | H26: El horario Sede debe estar previamente desactivado | J26: Horario Sede Eliminado | L26: Horario Sede Consultado | M26: Crear Horario Sede
G27: Horario Sede POL-0009 | H27: El horario sede a eliminar no debe de estar vinculado a una sede | L27: Horario Sede Desactivado | M27: Consultar Horario sede
G28: Horario Sede POL-0001 | H28: Asegurar que los datos requeridos para llevar a cabo la acción sean válidos a nivel de tipo de dato, longitud, obligatoriedad, formato y rango. | L28: Horario Sede Modificado
L32: Horario Sede Consultado | M32: Consultar Horario sede
A33: Representante Sede | B33: Activar el Horario Sede | C33: Permite mostrar los horarios disponibles de una sede | D33: Horario Sede | E33: Información de la sede | F33: Información que indica a que sede está asociado el horario a habilitar | G33: Horario Sede POL-0008 | H33: El horario Sede debe estar previamente desactivado | J33: Horario Sede Activado | L33: Horario Sede Desactivado | M33: Desactivar Horario Sede
G34: Horario Sede POL-0001 | H34: Asegurar que los datos requeridos para llevar a cabo la acción sean válidos a nivel de tipo de dato, longitud, obligatoriedad, formato y rango. | L34: Horario Sede Creado | M34: Modificar Horario Sede
L35: Horario Sede Modificado
L38: Horario Sede Activado | M38: Activar Horario Sede
A39: Representante Sede | B39: Desactivar el Horario Sede | C39: Permite ocultar los horarios disponibles de una sede | D39: Horario Sede | E39: Información de la sede | F39: Información que indica a que sede está asociado el horario a desactivar | G39: Horario Sede POL-0011 | H39: El horario Sede debe estar previamente activado | J39: Horario Sede Desactivado | L39: Horario Sede Consultado | M39: Consultar Horario sede
G40: Horario Sede POL-0001 | H40: Asegurar que los datos requeridos para llevar a cabo la acción sean válidos a nivel de tipo de dato, longitud, obligatoriedad, formato y rango. | L40: Horario Sede Creado | M40: Modificar Horario Sede
L41: Horario Sede Modificado | M41: Eliminar horario Sede

Sheet Imagen
A1: <-Volver al inicio
A2: Objeto de Dominio: | B2: Imagen
A3: Descripción: | B3: Objeto de dominio que representa los recursos visuales asociados a motocicletas
A4: Actor | B4: Action/Command | D4: Entity/Aggregate/Object domain | E4: Read Model | G4: Business Rule/Policy | I4: External System | J4: Domain Event | K4: Hotspot/questions/Risk | L4: Eventos Previos | M4: Comandos Posteriores
A5: Actor | B5: Acción | C5: Descripción | D5: Objeto de dominio | E5: Información externa | G5: Políticas | I5: Sistema Externo | J5: Evento | K5: Aspectos por solucionar
E6: Información | F6: Descripción | G6: Número | H6: Descripción
G7: Imagen POL-0001 | H7: Asegurar que los datos requeridos para llevar a cabo la acción sean válidos a nivel de tipo de dato, longitud, obligatoriedad, formato y rango.
A8: Usuario | B8: Agregar la imagen de la Motocicleta | C8: Permite añadir una nueva imagen de una motocicleta | D8: Imagen | G8: Imagen POL-0002 | H8: La imagen debe cumplir con un formato permitido | L8: Imagen Consultada | M8: Consultar Imagen Motocicleta
G9: Imagen POL-0003 | H9: La imagen no debe exceder un tamaño máximo definido | M9: Eliminar Imagen Motocicleta
G10: Imagen POL-0004 | H10: No puede existir otra Imagen con el mismo identificador. | M10: Actualizar Imagen Motocicleta
A12: Usuario | B12: Actualizar la Imagen de la Motocicleta | C12: Permite actualizar una Imagen de motocicleta | D12: Imagen | G12: Imagen POL-0001 | H12: Asegurar que los datos requeridos para llevar a cabo la acción sean válidos a nivel de tipo de dato, longitud, obligatoriedad, formato y rango. | J12: Imagen Actualizada | L12: Imagen Agregada | M12: Consultar Imagen Motocicleta
L13: Imagen Consultada | M13: Eliminar Imagen Motocicleta
M14: Agregar Imagen Motocicleta
L15: Imagen Actualizada | M15: Eliminar Imagen Motocicleta
A16: Usuario | B16: Consultar la Imagen de la Motocicleta | C16: Permite visualizar una Imagen específica de una motocicleta | D16: Imagen | G16: Imagen POL-0005 | H16: Asegurar que los datos que fueron enviados como filtro para llevar a cabo la acción sean válidos a nivel de tipo de dato, longitud, obligatoriedad, formato y rango. | J16: Imagen Consultada | L16: Imagen Agregada | M16: Actualizar Imagen Motocicleta
L17: Imagen Eliminada | M17: Agregar Imagen Motocicleta
A18: Usuario | B18: Eliminar la Imagen de la Motocicleta | C18: Permite eliminar una Imagen existente del sistema | D18: Imagen | G18: Imagen POL-0001 | H18: Asegurar que los datos requeridos para llevar a cabo la acción sean válidos a nivel de tipo de dato, longitud, obligatoriedad, formato y rango. | I18: Sistema de Almacenamiento | J18: Imagen Eliminada | L18: Imagen Consultada | M18: Agregar Imagen Motocicleta
L19: Imagen Agregada | M19: Consultar Imagen Motocicleta
L20: Imagen Actualizada

Sheet Linea
A1: <-Volver al inicio
A2: Objeto de Dominio: | B2: Línea
A3: Descripción: | B3: ='Listado Objetos de Dominio'!B18 -> Objeto de dominio que representa la familia o serie específica de motocicletas dentro de una marca.
A4: Actor | B4: Action/Command | D4: Entity/Aggregate/Object domain | E4: Read Model | G4: Business Rule/Policy | I4: External System | J4: Domain Event | K4: Hotspot/questions/Risk | L4: Eventos Previos | M4: Comandos Posteriores
A5: Actor | B5: Acción | C5: Descripción | D5: Objeto de dominio | E5: Información externa | G5: Políticas | I5: Sistema Externo | J5: Evento | K5: Aspectos por solucionar
E6: Información | F6: Descripción | G6: Número | H6: Descripción
A8: Usuario/Representante Sede | B8: Consultar Información de las líneas de una marca de motocicletas | C8: Permite ver la información de las líneas de una marca de motocicleta | D8: Línea | E8: Información de la Marca | F8: Información que indica cual es la marca de motocicleta a la que se puede consultar las líneas | G8: Línea POL-0001 | H8: Asegurar que los datos que fueron enviados como filtro para llevar a cabo la acción sean válidos a nivel de tipo de dato, longitud, obligatoriedad, formato y rango. | J8: Línea Consultada | L8: Línea de Motocicleta Creada | M8: Crear Línea de Motocicleta
O9: Crear la Línea de una Marca de Motocicleta
G10: Línea POL-0002 | H10: No puede existir otro representante sede con el mismo identificador.
A11: Administrador | B11: Crear la Línea de una Marca de Motocicleta | C11: Permite crear líneas dentro de una marca de motocicleta | D11: Línea | E11: Información de la Marca | F11: Información que indica cual es la marca de motocicleta a la que se puede agregar las líneas | G11: Línea POL-00003 | H11: La línea a registrar no debe de estar previamente registrada en la misma línea | J11: Línea Creada | L11: Línea de Motocicleta Consultada | M11: Consultar Línea de Motocicleta
G12: Línea POL-0001 | H12: Asegurar la validación de los datos para llevar a cabo la acción a nivel de tipo de dato, longitud, obligatoriedad, formato y rango.

Sheet Linea Categoria
A1: <-Volver al inicio
A2: Objeto de Dominio: | B2: ='Listado Objetos de Dominio'!$A$19 -> Línea Categoría
A3: Descripción: | B3: ='Listado Objetos de Dominio'!$B$19 -> Objeto de dominio que representa la relación entre una línea de motocicletas y su categoría.
A4: Actor | B4: Action/Command | D4: Entity/Aggregate/Object domain | E4: Read Model | G4: Business Rule/Policy | I4: External System | J4: Domain Event | K4: Hotspot/questions/Risk | L4: Eventos Previos | M4: Comandos Posteriores
A5: Actor | B5: Acción | C5: Descripción | D5: Objeto de dominio | E5: Información externa | G5: Políticas | I5: Sistema Externo | J5: Evento | K5: Aspectos por solucionar
E6: Información | F6: Descripción | G6: Número | H6: Descripción
A8: Usuario/Representante Sede | B8: Consultar Información de la Línea Categoría | C8: Permite ver la relación entre línea y categoría | D8: Línea Categoría | E8: Información de la línea | F8: Información que indica cual es la asociación de la línea con la categoría | G8: Línea Categoría POL-0001 | H8: Asegurar que los datos que fueron enviados como filtro para llevar a cabo la acción sean válidos a nivel de tipo de dato, longitud, obligatoriedad, formato y rango. | J8: Línea Categoría Consultada | L8: Línea Categoría Creada | M8: Crear Línea Categoría
E9: Información de la categoría | F9: Información que indica cual es la asociación de la categoría con la línea
A10: Administrador | B10: Crear asociación de la Línea Categoría | C10: Permite crear una nueva relación entre línea y categoría | D10: Línea Categoría | E10: Información de la línea | F10: Información que indica culés serán las asociaciones de la línea con la categoría | G10: Línea Categoría POL-0002 | H10: Asegurar la validación de los datos para llevar a cabo la acción a nivel de tipo de dato, longitud, obligatoriedad, formato y rango. | J10: Línea Categoría Creada | L10: Línea Categoría Consultada | M10: Consultar Línea Categoría
E11: Información de la categoría | F11: Información que indica cual será la asociación de la categoría con la línea | G11: Línea Categoría POL-0003 | H11: No puede existir otra línea categoría con el mismo identificador
G12: Línea Categoría POL-0004 | H12: No puede existir otra línea categoría con el mismo nombre

Sheet Marca
A1: <-Volver al inicio
A2: Objeto de Dominio: | B2: ='Listado Objetos de Dominio'!A20 -> Marca
A3: Descripción: | B3: ='Listado Objetos de Dominio'!B20 -> Objeto de dominio que representa cada uno de los fabricantes de motocicletas.
A4: Actor | B4: Action/Command | D4: Entity/Aggregate/Object domain | E4: Read Model | G4: Business Rule/Policy | I4: External System | J4: Domain Event | K4: Hotspot/questions/Risk | L4: Eventos Previos | M4: Comandos Posteriores
A5: Actor | B5: Acción | C5: Descripción | D5: Objeto de dominio | E5: Información externa | G5: Políticas | I5: Sistema Externo | J5: Evento | K5: Aspectos por solucionar
E6: Información | F6: Descripción | G6: Número | H6: Descripción
A7: Usuario/Representante Sede | B7: Consultar Información de las Marcas de Motocicletas | C7: Permite buscar marcas de motocicleta | D7: Marca | G7: Marca POL-0001 | H7: Asegurar que los datos que fueron enviados como filtro para llevar a cabo la acción sean válidos a nivel de tipo de dato, longitud, obligatoriedad, formato y rango. | J7: Marca de Motocicleta Consultada | L7: Maraca de Motocicleta Agregada | M7: Agregar Marca de Motocicleta
G10: Marca POL-0004 | H10: Asegurar que los datos requeridos para llevar a cabo la acción sean válidos a nivel de tipo de dato, longitud, obligatoriedad, formato y rango.
A11: Administrador | B11: Agregar Información de la Marca de Motocicleta | C11: Permite agregar una nueva marca de motocicleta | D11: Marca | G11: Marca POL-0002 | H11: No puede existir otra marca de motocicleta con el mismo nombre | J11: Marca de Motocicleta Consultada | L11: Maraca de Motocicleta Consultada | M11: Consultar Marca Motocicleta
G12: Marca POL-0003 | H12: No puede existir otra marca de motocicleta con el mismo identificador

Sheet Motocicleta
A1: <-Volver al inicio
A2: Objeto de Dominio: | B2: ='Listado Objetos de Dominio'!$A$22 -> Motocicleta
A3: Descripción: | B3: ='Listado Objetos de Dominio'!$B$22 -> Objeto de dominio que representa el vehículo de dos ruedas con sus características específicas.
A4: Actor | B4: Action/Command | D4: Entity/Aggregate/Object domain | E4: Read Model | G4: Business Rule/Policy | I4: External System | J4: Domain Event | K4: Hotspot/questions/Risk | L4: Eventos Previos | M4: Comandos Posteriores
A5: Actor | B5: Acción | C5: Descripción | D5: Objeto de dominio | E5: Información externa | G5: Políticas | I5: Sistema Externo | J5: Evento | K5: Aspectos por solucionar
E6: Información | F6: Descripción | G6: Número | H6: Descripción
A8: Usuario | B8: Registrar Información de la Motocicleta | C8: Permite registrar una nueva motocicleta | D8: Motocicleta | E8: Información del Modelo | F8: Información que indica cual es el modelo de la motocicleta a registrar | G8: Motocicleta POL-0001 | H8: Asegurar que los datos requeridos para llevar a cabo la acción sean válidos a nivel de tipo de dato, longitud, obligatoriedad, formato y rango. | J8: Motocicleta Registrada | L8: Motocicleta Consultada | M8: Consultar Motocicleta
E9: Información del Usuario | F9: Información que indica cual es el propietario de la motocicleta | G9: Motocicleta POL-0002 | H9: El propietario debe estar previamente registrado | M9: Eliminar Motocicleta
G10: Motocicleta POL-0003 | H10: La matrícula de la motocicleta que se desea registrar no debe de existir en el sistema. | M10: Modificar Motocicleta
G11: Motocicleta POL-0004 | H11: No puede existir otra matricula con el mismo identificador.
A14: Usuario | B14: Modificar Información de la Motocicleta | C14: Permite actualizar la información de una motocicleta | D14: Motocicleta | E14: Información del Modelo | F14: Información que indica cual es el modelo de la motocicleta a modificar | G14: Motocicleta POL-0001 | H14: Asegurar que los datos requeridos para llevar a cabo la acción sean válidos a nivel de tipo de dato, longitud, obligatoriedad, formato y rango. | J14: Motocicleta Modificada | L14: Motocicleta Consultada | M14: Consultar Motocicleta
E15: Información del Usuario | F15: Información que indica cual es el propietario de la motocicleta a modificar | L15: Motocicleta Registrada | M15: Eliminar Motocicleta
A20: Usuario | B20: Eliminar Información de la Motocicleta | C20: Permite eliminar una motocicleta | D20: Motocicleta | E20: Información del Modelo | F20: Información que indica cual es el modelo de la motocicleta a eliminar | G20: Motocicleta POL-0005 | H20: Asegurar que la motocicleta a eliminar no tenga dependencias | J20: Motocicleta Eliminada | L20: Motocicleta Consultada | M20: Consultar Motocicleta
E21: Información del Usuario | F21: Información que indica cual es el propietario de la motocicleta a eliminar | L21: Motocicleta Registrada | M21: Registrar Motocicleta
L22: Motocicleta Modificada
A26: Usuario | B26: Consultar Información de la Motocicleta | C26: Permite consultar la información de una motocicleta | D26: Motocicleta | E26: Información del Modelo | F26: Información que indica cual es el modelo de la motocicleta a consultar | G26: Motocicleta POL-0006 | H26: Asegurar que los datos que fueron enviados como filtro para llevar a cabo la acción sean válidos a nivel de tipo de dato, longitud, obligatoriedad, formato y rango. | J26: Motocicleta Consultada | L26: Motocicleta Registrada | M26: Modificar Motocicleta
E27: Información del Usuario | F27: Información que indica cual es el propietario de la motocicleta a consultar | L27: Motocicleta Consultada | M27: Eliminar Motocicleta
L28: Motocicleta Modificada | M28: Registrar Motocicleta
L29: Motocicleta Eliminada
A32: Representante Sede | B32: Consultar Información General de la Motocicleta | C32: Permite consultar la información general de una motocicleta | D32: Motocicleta | E32: Información del Modelo | F32: Información que indica cual es el modelo de la motocicleta a consultar | G32: Motocicleta POL-0006 | H32: Asegurar que los datos que fueron enviados como filtro para llevar a cabo la acción sean válidos a nivel de tipo de dato, longitud, obligatoriedad, formato y rango. | J32: Motocicleta Consultada | L32: Motocicleta Registrada | M32: Modificar Motocicleta
E33: Información del Usuario | F33: Información que indica cual es el propietario de la motocicleta a consultar | L33: Motocicleta Consultada | M33: Eliminar Motocicleta
L34: Motocicleta Modificada | M34: Registrar Motocicleta
L35: Motocicleta Eliminada

Sheet Rango Calificacion
A1: <-Volver al inicio
A2: Objeto de Dominio: | B2: ='Listado Objetos de Dominio'!A23 -> Rango Calificación
A3: Descripción: | B3: ='Listado Objetos de Dominio'!B23 -> Objeto de dominio que representa los intervalos de valoración permitidos para las calificaciones
A4: Actor | B4: Action/Command | D4: Entity/Aggregate/Object domain | E4: Read Model | G4: Business Rule/Policy | I4: External System | J4: Domain Event | K4: Hotspot/questions/Risk | L4: Eventos Previos | M4: Comandos Posteriores
A5: Actor | B5: Acción | C5: Descripción | D5: Objeto de dominio | E5: Información externa | G5: Políticas | I5: Sistema Externo | J5: Evento | K5: Aspectos por solucionar
E6: Información | F6: Descripción | G6: Número | H6: Descripción
A8: Usuario | B8: Consultar Información del Rango Calificación | C8: Permite ver los rangos de calificación disponibles | D8: Rango Calificación | G8: Rango Calificación POL-0001 | H8: Asegurar que los datos que fueron enviados como filtro para llevar a cabo la acción sean válidos a nivel de tipo de dato, longitud, obligatoriedad, formato y rango. | J8: Rango Calificación consultado

Sheet Rango cilindraje
A1: <-Volver al inicio
A2: Objeto de Dominio: | B2: ='Listado Objetos de Dominio'!A24 -> Rango Cilindraje
A3: Descripción: | B3: ='Listado Objetos de Dominio'!B26 -> Objeto de dominio que representa un servicio específico completado en una motocicleta.
A4: Actor | B4: Action/Command | D4: Entity/Aggregate/Object domain | E4: Read Model | G4: Business Rule/Policy | I4: External System | J4: Domain Event | K4: Hotspot/questions/Risk | L4: Eventos Previos | M4: Comandos Posteriores
A5: Actor | B5: Acción | C5: Descripción | D5: Objeto de dominio | E5: Información externa | G5: Políticas | I5: Sistema Externo | J5: Evento | K5: Aspectos por solucionar
E6: Información | F6: Descripción | G6: Número | H6: Descripción
A7: Usuario/Representante Sede | B7: Consultar Información del Rango Cilindraje | C7: Permite filtrar motocicletas por su rango de cilindraje | D7: Rango Cilindraje | G7: Rango Cilindraje POL-0001 | H7: Asegurar que los datos que fueron enviados como filtro para llevar a cabo la acción sean válidos a nivel de tipo de dato, longitud, obligatoriedad, formato y rango. | J7: Rango Cilindraje Consultado
G8: Rango Cilindraje POL-0002 | H8: El cilindraje debe ser un número positivo y estar dentro de los rangos permitidos

Sheet Referencia
A1: <-Volver al inicio
A2: Objeto de Dominio: | B2: Referencia
A3: Descripción: | B3: Objeto de dominio que representa las diferentes variantes o versiones de motocicletas disponibles en el sistema.
A4: Actor | B4: Action/Command | D4: Entity/Aggregate/Object domain | E4: Read Model | G4: Business Rule/Policy | I4: External System | J4: Domain Event | K4: Hotspot/questions/Risk | L4: Eventos Previos | M4: Comandos Posteriores
A5: Actor | B5: Acción | C5: Descripción | D5: Objeto de dominio | E5: Información externa | G5: Políticas | I5: Sistema Externo | J5: Evento | K5: Aspectos por solucionar
E6: Información | F6: Descripción | G6: Número | H6: Descripción
E7: Información de la línea Categoría | F7: Información que indica cual es la línea categoría que hay dentro de un Referencia de una motocicleta | G7: Referencia POL-0004 | H7: Asegurar que los datos que fueron enviados como filtro para llevar a cabo la acción sean válidos a nivel de tipo de dato, longitud, obligatoriedad, formato y rango.
A8: Usuario/Representante Sede | B8: Consultar Información de la Referencia Motocicleta | C8: Permite visualizar las referencias de motocicleta disponibles. | D8: Referencia | E8: Información de Rango Cilindraje | F8: Información que indica cual es el rango de cilindraje dentro del Referencia de una motocicleta | J8: Referencia consultada | L8: Referencia Agregada | M8: Agregar Referencia Motocicleta
E10: Información de la línea Categoría | F10: Información que indica cual es la línea categoría que hay dentro de un Referencia de una motocicleta | G10: Referencia POL-0001 | H10: Asegurar la validación de los datos para llevar a cabo la acción a nivel de tipo de dato, longitud, obligatoriedad, formato y rango.
A11: Administrador | B11: Agregar Información de la Referencia de la Motocicleta | C11: Permite agregar referencias de motocicleta. | D11: Referencia | E11: Información de Rango Cilindraje | F11: Información que indica cual es el rango de cilindraje dentro del Referencia de una motocicleta | G11: Referencia POL-0002 | H11: La referencia a registrar no debe estar previamente registrada. | J11: Referencias Agregada | L11: Referencia Motocicleta Agregada | M11: Agregar Referencia Motocicleta
G12: Referencia POL-0003 | H12: No debe existir otra referencia con el mismo identificador.

Sheet Representante Sede
A1: <-Volver al inicio
A2: Objeto de Dominio: | B2: Representante sede
A3: Descripción: | B3: ='[1]Listado Objetos de Dominio'!$B$11 -> Objeto de dominio que representa la persona responsable de gestionar una sede específica de una sede.
A4: Actor | B4: Action/Command | D4: Entity/Aggregate/Object domain | E4: Read Model | G4: Business Rule/Policy | I4: External System | J4: Donan Event | K4: Hotspot/questions/Risk | L4: Eventos Previos | M4: Comandos Posteriores
A5: Actor | B5: Acción | C5: Descripción | D5: Objeto de dominio | E5: Información externa | G5: Políticas | I5: Sistema Externo | J5: Evento | K5: Aspectos por solucionar
E6: Información | F6: Descripción | G6: Número | H6: Descripción
G7: Representante Sede POL - 0005 | H7: Correo electrónico del representante sede debe ser único | M7: Editar Representante sede
G8: Representante Sede POL-0004 | H8: Número de celular del representante sede debe ser único | M8: Eliminar Representante Sede
A9: Representante Sede | B9: Registrar Información del Representante Sede | C9: Permite registrar un nuevo representante para una sede específica | D9: Representante Sede | G9: Representante Sede POL - 0003 | H9: Número de cédula del representante sede debe ser único | L9: Representante Sede Consultado | M9: Consultar Representante Sede
G10: Representante Sede POL-0002 | H10: No puede existir otro representante sede con el mismo identificador. | M10: Restablecer Clave Representante Sede
G11: Representante Sede POL - 0001 | H11: Asegurar que los datos requeridos para llevar a cabo la acción sean válidos a nivel de tipo de dato, longitud, obligatoriedad, formato y rango.
G13: Representante Sede POL-0005 | H13: Correo electrónico del representante sede debe ser único | L13: Representante Sede Consultado | M13: Consultar Representante Sede
A14: Representante Sede | B14: Modificar Información del Representante Sede | C14: Permite actualizar la información de un representante existente | D14: Representante Sede | G14: Representante Sede POL-0004 | H14: Número de celular del representante sede debe ser único | L14: Representante Sede Agregado | M14: Eliminar Representante Sede
G15: Representante Sede POL-0003 | H15: Número de cédula del representante sede debe ser único | L15: Clave Representante Sede Restablecida | M15: Restablecer Clave Representante Sede
G16: Representante Sede POL-0001 | H16: Asegurar que los datos requeridos para llevar a cabo la acción sean válidos a nivel de tipo de dato, longitud, obligatoriedad, formato y rango. | L16: Clave Representante Sede Modificada | M16: Modificar Clave Representante Sede
L17: Representante Sede Consultado | M17: Consultar Representante Sede
A18: Representante Sede | B18: Eliminar Información del Representante Sede | C18: Permite dar de baja a un representante del sistema | D18: Representante Sede | G18: Representante Sede POL-0006 | H18: Asegurar que el representante sede no esté vinculado a una sede | J18: Representante Eliminado | L18: Representante Sede Agregado | M18: Agregar Representante Sede
L19: Representante Sede Modificado
L20: Clave Representante Sede Modificada
L21: Clave Representante Sede Restablecida
L22: Representante Sede Agregado | M22: Agregar Representante Sede
