Workbook

Sheet Desarrollo sprints
B1: Sprint -2 | C1: Sprint -1 | D1: Sprint 1 | E1: Sprint 2 | F1: Sprint 3 | G1: Sprint 4 | H1: Sprint 5 | I1: Sprint 6 | J1: Sprint 7 | K1: Sprint 8 | L1: Sprint 9 | M1: Sprint 10 | N1: Sprint 11 | O1: Sprint 12 | P1: Sprint 13 | Q1: Sprint 14
A2: Sprint 1 | D2: Ejecutar Sprint Infraestructura
A3: Sprint 2 | B3: Redaccion HU HU51,54,58,81,84,88 | C3: Refinamiento HU HU51,54,58,81,84,88 | E3: Ejecutar Sprint HU51,54,58,81,84,88
A4: Sprint 3 | C4: Redaccion HU HU52,55-57,82,85-87 | D4: Refinamiento HU HU52,55-57,82,85-87 | F4: Ejecutar Sprint HU52,55-57,82,85-87
A5: Sprint 4 | D5: Redaccion HU HU4,5,42,53,59-62,76-80,83 | E5: Redaccion HU HU4,5,42,53,59-62,76-80,83 | F5: Refinamiento HU HU4,5,42,53,59-62,76-80,83 | G5: Ejecutar Sprint HU4,5,42,53,59-62,76-80,83
A6: Sprint 5 | F6: Redaccion HU HU26-29 | G6: Refinamiento HU HU26-29 | H6: Ejecutar Sprint HU26-29
A7: Sprint 6 | F7: Redaccion HU HU63,67-72,75 | G7: Redaccion HU HU63,67-72,75 | H7: Refinamiento HU HU63,67-72,75 | I7: Ejecutar Sprint HU63,67-72,75
A8: Sprint 7 | H8: Redaccion HU HU10,30-35 | I8: Refinamiento HU HU10,30-35 | J8: Ejecutar Sprint HU10,30-35
A9: Sprint 8 | I9: Redaccion HU HU6-9 | J9: Refinamiento HU HU6-9 | K9: Ejecutar Sprint HU6-9
A10: Sprint 9 | I10: Redaccion HU HU20-25,43-47 | J10: Redaccion HU HU20-25,43-47 + Refinamiento HU HU20-25,43-47 | K10: Refinamiento HU HU20-25,43-47 | L10: Ejecutar Sprint HU20-25,43-47
A11: Sprint 7 | H11: Redaccion HU HU10,30-35 | I11: Refinamiento HU HU10,30-35 | J11: Ejecutar Sprint HU10,30-35
A12: Sprint 8 | I12: Redaccion HU HU6-9 | J12: Refinamiento HU HU6-9 | K12: Ejecutar Sprint HU6-9
A13: Sprint 9 | I13: Redaccion HU HU20-25,43-47 | J13: Redaccion HU HU20-25,43-47 + Refinamiento HU HU20-25,43-47 | K13: Refinamiento HU HU20-25,43-47 | L13: Ejecutar Sprint HU20-25,43-47
A14: Sprint 10 | K14: Redaccion HU HU16-19,36-39 | L14: Refinamiento HU HU16-19,36-39 | M14: Ejecutar Sprint HU16-19,36-39
A15: Sprint 11 | L15: Redaccion HU HU11-14 | M15: Refinamiento HU HU11-14 | N15: Ejecutar Sprint HU11-14
A16: Sprint 12 | M16: Redaccion HU HU1,41,48,49,89 | N16: Refinamiento HU HU1,41,48,49,89 | O16: Ejecutar Sprint HU1,41,48,49,89
A17: Sprint 13 | N17: Redaccion HU HU15,64-66,73,74 | O17: Refinamiento HU HU15,64-66,73,74 | P17: Ejecutar Sprint HU15,64-66,73,74
A18: Sprint 14 | O18: Redaccion HU HU2,3 | P18: Refinamiento HU HU2,3 | Q18: Ejecutar Sprint HU2,3

Sheet Plan de liberaciones (2)
A1: Historia de usuario | C1: Release | E1: Horas | F1: Acumulado horas Release | G1: Acumulado horas Release | H1: Release | R1: Identificador | S1: Talla | T1: Horas Talla | U1: HU Prioridad
A2: =R2 -> HU88 | B2: =VLOOKUP(A2,'Product Backlog HUs(1)'!A$1:M$99,2,FALSE) -> Autenticar el Usuario | D2: Release 1 | E2: =VLOOKUP(A2,R$1:U$89,3,FALSE) -> 16 | F2: =SUM(E2:E3) -> 48 | G2: =SUM(F2:F4) -> 80 | H2: Release 1 | I2: Release 1 | R2: HU88 | S2: L | T2: =VLOOKUP(S2,Tallas!A$1:D$8,4,FALSE) -> 16 | U2: 1
A3: =R3 -> HU81 | B3: =VLOOKUP(A3,'Product Backlog HUs(1)'!A$1:M$99,2,FALSE) -> Registrar Información del Usuario | D3: Release 1 | E3: =VLOOKUP(A3,R$1:U$89,3,FALSE) -> 32 | I3: Release 1 | R3: HU81 | S3: XL | T3: =VLOOKUP(S3,Tallas!A$1:D$8,4,FALSE) -> 32 | U3: 2
A4: =R4 -> HU43 | B4: =VLOOKUP(A4,'Product Backlog HUs(1)'!A$1:M$99,2,FALSE) -> Registrar Información de la Motocicleta | D4: Release 2 | E4: =VLOOKUP(A4,R$1:U$89,3,FALSE) -> 32 | F4: =E4 -> 32 | I4: Release 1 | R4: HU43 | S4: XL | T4: =VLOOKUP(S4,Tallas!A$1:D$8,4,FALSE) -> 32 | U4: 3
A5: =R5 -> HU80 | B5: =VLOOKUP(A5,'Product Backlog HUs(1)'!A$1:M$99,2,FALSE) -> Consultar Información de la Ubicación | D5: Release 3 | E5: =VLOOKUP(A5,R$1:U$89,3,FALSE) -> 48 | F5: =E5 -> 48 | G5: =SUM(F5:F9) -> 76 | H5: Release 2 | I5: Release 2 | R5: HU80 | S5: XXL | T5: =VLOOKUP(S5,Tallas!A$1:D$8,4,FALSE) -> 48 | U5: 4
A6: =R6 -> HU62 | B6: =VLOOKUP(A6,'Product Backlog HUs(1)'!A$1:M$99,2,FALSE) -> Consultar Información de la Sede | D6: Release 4 | E6: =VLOOKUP(A6,R$1:U$89,3,FALSE) -> 4 | F6: =SUM(E6:E9) -> 28 | I6: Release 2 | R6: HU62 | S6: S | T6: =VLOOKUP(S6,Tallas!A$1:D$8,4,FALSE) -> 4 | U6: 5
A7: =R7 -> HU63 | B7: =VLOOKUP(A7,'Product Backlog HUs(1)'!A$1:M$99,2,FALSE) -> Consultar Información del Servicio | D7: Release 4 | E7: =VLOOKUP(A7,R$1:U$89,3,FALSE) -> 4 | I7: Release 2 | R7: HU63 | S7: S | T7: =VLOOKUP(S7,Tallas!A$1:D$8,4,FALSE) -> 4 | U7: 6
A8: =R11 -> HU67 | B8: =VLOOKUP(A8,'Product Backlog HUs(1)'!A$1:M$99,2,FALSE) -> Crear Información del Servicio Sede | D8: Release 4 | E8: =VLOOKUP(A8,R$1:U$89,3,FALSE) -> 16 | I8: Release 2 | R8: HU70 | S8: S | T8: =VLOOKUP(S8,Tallas!A$1:D$8,4,FALSE) -> 4 | U8: 7
A9: =R14 -> HU66 | B9: =VLOOKUP(A9,'Product Backlog HUs(1)'!A$1:M$99,2,FALSE) -> Consultar Información del Servicio Realizado | D9: Release 4 | E9: =VLOOKUP(A9,R$1:U$89,3,FALSE) -> 4 | I9: Release 2 | R9: HU77 | S9: XXL | T9: =VLOOKUP(S9,Tallas!A$1:D$8,4,FALSE) -> 48 | U9: 8
A10: =R8 -> HU70 | B10: =VLOOKUP(A10,'Product Backlog HUs(1)'!A$1:M$99,2,FALSE) -> Consultar Información del Servicio Sede | D10: Release 5 | E10: =VLOOKUP(A10,R$1:U$89,3,FALSE) -> 4 | F10: =SUM(E10:E14) -> 18 | G10: =SUM(F10:F16) -> 66 | H10: Release 3 | I10: Release 3 | R10: HU59 | S10: L | T10: =VLOOKUP(S10,Tallas!A$1:D$8,4,FALSE) -> 16 | U10: 9
A11: =R20 -> HU50 | B11: =VLOOKUP(A11,'Product Backlog HUs(1)'!A$1:M$99,2,FALSE) -> Consultar Información de la Referencia Motocicleta | D11: Release 5 | E11: =VLOOKUP(A11,R$1:U$89,3,FALSE) -> 2 | I11: Release 3 | R11: HU67 | S11: L | T11: =VLOOKUP(S11,Tallas!A$1:D$8,4,FALSE) -> 16 | U11: 10
A12: =R19 -> HU40 | B12: =VLOOKUP(A12,'Product Backlog HUs(1)'!A$1:M$99,2,FALSE) -> Consultar Información de las líneas de una marca de motocicletas | D12: Release 5 | E12: =VLOOKUP(A12,R$1:U$89,3,FALSE) -> 2 | I12: Release 3 | R12: HU47 | S12: M | T12: =VLOOKUP(S12,Tallas!A$1:D$8,4,FALSE) -> 8 | U12: 11
A13: =R16 -> HU26 | B13: =VLOOKUP(A13,'Product Backlog HUs(1)'!A$1:M$99,2,FALSE) -> Registrar Información de la Franquicia | D13: Release 5 | E13: =VLOOKUP(A13,R$1:U$89,3,FALSE) -> 8 | I13: Release 3 | R13: HU46 | S13: S | T13: =VLOOKUP(S13,Tallas!A$1:D$8,4,FALSE) -> 4 | U13: 12
A14: =R30 -> HU5 | B14: =VLOOKUP(A14,'Product Backlog HUs(1)'!A$1:M$99,2,FALSE) -> Consultar Información del Departamento | D14: Release 5 | E14: =VLOOKUP(A14,R$1:U$89,3,FALSE) -> 2 | I14: Release 3 | R14: HU66 | S14: S | T14: =VLOOKUP(S14,Tallas!A$1:D$8,4,FALSE) -> 4 | U14: 13
A15: =R25 -> HU51 | B15: =VLOOKUP(A15,'Product Backlog HUs(1)'!A$1:M$99,2,FALSE) -> Registrar Información del Representante Sede | D15: Release 6 | E15: =VLOOKUP(A15,R$1:U$89,3,FALSE) -> 32 | F15: =E15 -> 32 | I15: Release 3 | R15: HU64 | S15: XL | T15: =VLOOKUP(S15,Tallas!A$1:D$8,4,FALSE) -> 32 | U15: 14
A16: =R26 -> HU58 | B16: =VLOOKUP(A16,'Product Backlog HUs(1)'!A$1:M$99,2,FALSE) -> Autenticar Información del Representante Sede | D16: Release 7 | E16: =VLOOKUP(A16,R$1:U$89,3,FALSE) -> 16 | F16: =E16 -> 16 | I16: Release 3 | R16: HU26 | S16: M | T16: =VLOOKUP(S16,Tallas!A$1:D$8,4,FALSE) -> 8 | U16: 15
A17: =R27 -> HU30 | B17: =VLOOKUP(A17,'Product Backlog HUs(1)'!A$1:M$99,2,FALSE) -> Registrar Información del Horario Sede | D17: Release 8 | E17: =VLOOKUP(A17,R$1:U$89,3,FALSE) -> 32 | F17: =E17 -> 32 | G17: =SUM(F17:F18) -> 80 | H17: Release 4 | I17: Release 4 | R17: HU1 | S17: S | T17: =VLOOKUP(S17,Tallas!A$1:D$8,4,FALSE) -> 4 | U17: 16
A18: =R9 -> HU77 | B18: =VLOOKUP(A18,'Product Backlog HUs(1)'!A$1:M$99,2,FALSE) -> Crear Información de la Ubicación | D18: Release 9 | E18: =VLOOKUP(A18,R$1:U$89,3,FALSE) -> 48 | F18: =E18 -> 48 | I18: Release 4 | R18: HU42 | S18: XS | T18: =VLOOKUP(S18,Tallas!A$1:D$8,4,FALSE) -> 2 | U18: 17
A19: =R10 -> HU59 | B19: =VLOOKUP(A19,'Product Backlog HUs(1)'!A$1:M$99,2,FALSE) -> Registrar Información de una nueva Sede | D19: Release 10 | E19: =VLOOKUP(A19,R$1:U$89,3,FALSE) -> 16 | F19: =SUM(E19:E23) -> 34 | G19: =SUM(F19:F25) -> 68 | H19: Release 5 | I19: Release 5 | R19: HU40 | S19: XS | T19: =VLOOKUP(S19,Tallas!A$1:D$8,4,FALSE) -> 2 | U19: 18
A20: =R21 -> HU49 | B20: =VLOOKUP(A20,'Product Backlog HUs(1)'!A$1:M$99,2,FALSE) -> Consultar Información del Rango Cilindraje | D20: Release 10 | E20: =VLOOKUP(A20,R$1:U$89,3,FALSE) -> 2 | I20: Release 5 | R20: HU50 | S20: XS | T20: =VLOOKUP(S20,Tallas!A$1:D$8,4,FALSE) -> 2 | U20: 19
A21: =R12 -> HU47 | B21: =VLOOKUP(A21,'Product Backlog HUs(1)'!A$1:M$99,2,FALSE) -> Consultar Información General de la Motocicleta | D21: Release 10 | E21: =VLOOKUP(A21,R$1:U$89,3,FALSE) -> 8 | I21: Release 6 | R21: HU49 | S21: XS | T21: =VLOOKUP(S21,Tallas!A$1:D$8,4,FALSE) -> 2 | U21: 20
A22: =R13 -> HU46 | B22: =VLOOKUP(A22,'Product Backlog HUs(1)'!A$1:M$99,2,FALSE) -> Consultar Información de la Motocicleta | D22: Release 10 | E22: =VLOOKUP(A22,R$1:U$89,3,FALSE) -> 4 | I22: Release 7 | R22: HU41 | S22: XS | T22: =VLOOKUP(S22,Tallas!A$1:D$8,4,FALSE) -> 2 | U22: 21
A23: =R17 -> HU1 | B23: =VLOOKUP(A23,'Product Backlog HUs(1)'!A$1:M$99,2,FALSE) -> Consultar la Información de una Categoría Motocicleta | D23: Release 10 | E23: =VLOOKUP(A23,R$1:U$89,3,FALSE) -> 4 | I23: Release 7 | R23: HU75 | S23: XS | T23: =VLOOKUP(S23,Tallas!A$1:D$8,4,FALSE) -> 2 | U23: 22
A24: =R15 -> HU64 | B24: =VLOOKUP(A24,'Product Backlog HUs(1)'!A$1:M$99,2,FALSE) -> Registrar Información del Servicio Realizado | D24: Release 11 | E24: =VLOOKUP(A24,R$1:U$89,3,FALSE) -> 32 | F24: =SUM(E24:E25) -> 34 | I24: Release 8 | R24: HU76 | S24: M | T24: =VLOOKUP(S24,Tallas!A$1:D$8,4,FALSE) -> 8 | U24: 23
A25: =R22 -> HU41 | B25: =VLOOKUP(A25,'Product Backlog HUs(1)'!A$1:M$99,2,FALSE) -> Consultar Información de la Línea Categoría | D25: Release 11 | E25: =VLOOKUP(A25,R$1:U$89,3,FALSE) -> 2 | I25: Release 8 | R25: HU51 | S25: XL | T25: =VLOOKUP(S25,Tallas!A$1:D$8,4,FALSE) -> 32 | U25: 24
A26: =R18 -> HU42 | B26: =VLOOKUP(A26,'Product Backlog HUs(1)'!A$1:M$99,2,FALSE) -> Consultar Información de las Marcas de Motocicletas | D26: Release 12 | E26: =VLOOKUP(A26,R$1:U$89,3,FALSE) -> 2 | F26: =SUM(E26:E31) -> 18 | G26: =SUM(F26:F35) -> 74 | H26: Release 6 | I26: Release 9 | R26: HU58 | S26: L | T26: =VLOOKUP(S26,Tallas!A$1:D$8,4,FALSE) -> 16 | U26: 25
A27: =R23 -> HU75 | B27: =VLOOKUP(A27,'Product Backlog HUs(1)'!A$1:M$99,2,FALSE) -> Consultar Información del Tipo Servicio | D27: Release 12 | E27: =VLOOKUP(A27,R$1:U$89,3,FALSE) -> 2 | I27: Release 9 | R27: HU30 | S27: XL | T27: =VLOOKUP(S27,Tallas!A$1:D$8,4,FALSE) -> 32 | U27: 26
A28: =R24 -> HU76 | B28: =VLOOKUP(A28,'Product Backlog HUs(1)'!A$1:M$99,2,FALSE) -> Consultar Información del Tipo Sede | D28: Release 12 | E28: =VLOOKUP(A28,R$1:U$89,3,FALSE) -> 8 | I28: Release 10 | R28: HU32 | S28: XS | T28: =VLOOKUP(S28,Tallas!A$1:D$8,4,FALSE) -> 2 | U28: 27
A29: =R28 -> HU32 | B29: =VLOOKUP(A29,'Product Backlog HUs(1)'!A$1:M$99,2,FALSE) -> Consultar Información del Horario Sede | D29: Release 12 | E29: =VLOOKUP(A29,R$1:U$89,3,FALSE) -> 2 | I29: Release 10 | R29: HU4 | S29: XS | T29: =VLOOKUP(S29,Tallas!A$1:D$8,4,FALSE) -> 2 | U29: 28
A30: =R29 -> HU4 | B30: =VLOOKUP(A30,'Product Backlog HUs(1)'!A$1:M$99,2,FALSE) -> Consultar Información de la Ciudad | D30: Release 12 | E30: =VLOOKUP(A30,R$1:U$89,3,FALSE) -> 2 | I30: Release 11 | R30: HU5 | S30: XS | T30: =VLOOKUP(S30,Tallas!A$1:D$8,4,FALSE) -> 2 | U30: 29
A31: =R31 -> HU10 | B31: =VLOOKUP(A31,'Product Backlog HUs(1)'!A$1:M$99,2,FALSE) -> Consultar Información del Día | D31: Release 12 | E31: =VLOOKUP(A31,R$1:U$89,3,FALSE) -> 2 | I31: Release 11 | R31: HU10 | S31: XS | T31: =VLOOKUP(S31,Tallas!A$1:D$8,4,FALSE) -> 2 | U31: 30
A32: =R32 -> HU15 | B32: =VLOOKUP(A32,'Product Backlog HUs(1)'!A$1:M$99,2,FALSE) -> Consultar Información del Estado del Servicio Realizado | D32: Release 13 | E32: =VLOOKUP(A32,R$1:U$89,3,FALSE) -> 32 | F32: =SUM(E32:E33) -> 40 | I32: Release 12 | R32: HU15 | S32: XL | T32: =VLOOKUP(S32,Tallas!A$1:D$8,4,FALSE) -> 32 | U32: 31
A33: =R33 -> HU84 | B33: =VLOOKUP(A33,'Product Backlog HUs(1)'!A$1:M$99,2,FALSE) -> Consultar Información Detallada del Usuario | D33: Release 13 | E33: =VLOOKUP(A33,R$1:U$89,3,FALSE) -> 8 | I33: Release 12 | R33: HU84 | S33: M | T33: =VLOOKUP(S33,Tallas!A$1:D$8,4,FALSE) -> 8 | U33: 32
A34: =R34 -> HU85 | B34: =VLOOKUP(A34,'Product Backlog HUs(1)'!A$1:M$99,2,FALSE) -> Consultar Información general del Usuario | D34: Release 14 | E34: =VLOOKUP(A34,R$1:U$89,3,FALSE) -> 8 | F34: =SUM(E34:E35) -> 16 | I34: Release 13 | R34: HU85 | S34: M | T34: =VLOOKUP(S34,Tallas!A$1:D$8,4,FALSE) -> 8 | U34: 33
A35: =R89 -> HU22 | B35: =VLOOKUP(A35,'Product Backlog HUs(1)'!A$1:M$99,2,FALSE) -> Eliminar Información de la Excepción Horario | D35: Release 14 | E35: =VLOOKUP(A35,R$1:U$89,3,FALSE) -> 8 | I35: Release 13 | R35: HU54 | S35: M | T35: =VLOOKUP(S35,Tallas!A$1:D$8,4,FALSE) -> 8 | U35: 34
A36: =R35 -> HU54 | B36: =VLOOKUP(A36,'Product Backlog HUs(1)'!A$1:M$99,2,FALSE) -> Consultar Información detallada del Representante Sede | D36: Release 15 | E36: =VLOOKUP(A36,R$1:U$89,3,FALSE) -> 8 | F36: =SUM(E36:E41) -> 32 | G36: =SUM(F36:F46) -> 72 | H36: Release 14 | I36: Release 14 | R36: HU55 | S36: XS | T36: =VLOOKUP(S36,Tallas!A$1:D$8,4,FALSE) -> 2 | U36: 35
A37: =R36 -> HU55 | B37: =VLOOKUP(A37,'Product Backlog HUs(1)'!A$1:M$99,2,FALSE) -> Consultar Información General del Representante Sede | D37: Release 15 | E37: =VLOOKUP(A37,R$1:U$89,3,FALSE) -> 2 | I37: Release 14 | R37: HU29 | S37: XS | T37: =VLOOKUP(S37,Tallas!A$1:D$8,4,FALSE) -> 2 | U37: 36
A38: =R37 -> HU29 | B38: =VLOOKUP(A38,'Product Backlog HUs(1)'!A$1:M$99,2,FALSE) -> Consultar Información de la Franquicia | D38: Release 15 | E38: =VLOOKUP(A38,R$1:U$89,3,FALSE) -> 2 | I38: Release 15 | R38: HU82 | S38: L | T38: =VLOOKUP(S38,Tallas!A$1:D$8,4,FALSE) -> 16 | U38: 37
A39: =R40 -> HU36 | B39: =VLOOKUP(A39,'Product Backlog HUs(1)'!A$1:M$99,2,FALSE) -> Agregar la imagen de la Motocicleta | D39: Release 15 | E39: =VLOOKUP(A39,R$1:U$89,3,FALSE) -> 8 | I39: Release 15 | R39: HU44 | S39: XL | T39: =VLOOKUP(S39,Tallas!A$1:D$8,4,FALSE) -> 32 | U39: 38
A40: =R41 -> HU38 | B40: =VLOOKUP(A40,'Product Backlog HUs(1)'!A$1:M$99,2,FALSE) -> Consultar la Imagen de la Motocicleta | D40: Release 15 | E40: =VLOOKUP(A40,R$1:U$89,3,FALSE) -> 4 | I40: Release 15 | R40: HU36 | S40: M | T40: =VLOOKUP(S40,Tallas!A$1:D$8,4,FALSE) -> 8 | U40: 39
...

Sheet Plan de liberaciones (3)
A1: Identificador | B1: Historia de usuario | C1: Sprint | D1: Horas | E1: Acumulado horas Sprint | F1: Acumulado horas Release | G1: Release | P1: Identificador | Q1: Talla | R1: Horas Talla | S1: HU Prioridad
A2: =P2 -> HU51 | B2: =VLOOKUP(A2,'Product Backlog HUs(1)'!A$1:M$99,2,FALSE) -> Registrar Información del Representante Sede | C2: Sprint 1 | D2: =VLOOKUP(A2,P$1:S$89,3,FALSE) -> 32 | E2: =D2 -> 32 | F2: =SUM(E2:E4) -> 68 | G2: Release 1 | P2: HU51 | Q2: XL | R2: =VLOOKUP(Q2,Tallas!A$1:D$8,4,FALSE) -> 32 | S2: 1
A3: =P3 -> HU58 | B3: =VLOOKUP(A3,'Product Backlog HUs(1)'!A$1:M$99,2,FALSE) -> Autenticar Información del Representante Sede | C3: Sprint 2 | D3: =VLOOKUP(A3,P$1:S$89,3,FALSE) -> 16 | E3: =SUM(D3:D5) -> 26 | P3: HU58 | Q3: L | R3: =VLOOKUP(Q3,Tallas!A$1:D$8,4,FALSE) -> 16 | S3: 2
A4: =P4 -> HU54 | B4: =VLOOKUP(A4,'Product Backlog HUs(1)'!A$1:M$99,2,FALSE) -> Consultar Información detallada del Representante Sede | C4: Sprint 3 | D4: =VLOOKUP(A4,P$1:S$89,3,FALSE) -> 8 | E4: =SUM(D4:D5) -> 10 | P4: HU54 | Q4: M | R4: =VLOOKUP(Q4,Tallas!A$1:D$8,4,FALSE) -> 8 | S4: 3
A5: =P5 -> HU55 | B5: =VLOOKUP(A5,'Product Backlog HUs(1)'!A$1:M$99,2,FALSE) -> Consultar Información General del Representante Sede | C5: Sprint 4 | D5: =VLOOKUP(A5,P$1:S$89,3,FALSE) -> 2 | E5: =SUM(D5:D6) -> 34 | F5: =SUM(E5:E9) -> 62 | G5: Release 2 | P5: HU55 | Q5: XS | R5: =VLOOKUP(Q5,Tallas!A$1:D$8,4,FALSE) -> 2 | S5: 4
A6: =P6 -> HU52 | B6: =VLOOKUP(A6,'Product Backlog HUs(1)'!A$1:M$99,2,FALSE) -> Modificar Información del Representante Sede | D6: =VLOOKUP(A6,P$1:S$89,3,FALSE) -> 32 | P6: HU52 | Q6: XL | R6: =VLOOKUP(Q6,Tallas!A$1:D$8,4,FALSE) -> 32 | S6: 5
A7: =P7 -> HU57 | B7: =VLOOKUP(A7,'Product Backlog HUs(1)'!A$1:M$99,2,FALSE) -> Modificar la Clave del Representante Sede | C7: Sprint 5 | D7: =VLOOKUP(A7,P$1:S$89,3,FALSE) -> 16 | E7: =SUM(D7:D9) -> 28 | P7: HU57 | Q7: L | R7: =VLOOKUP(Q7,Tallas!A$1:D$8,4,FALSE) -> 16 | S7: 6
A8: =P11 -> HU62 | B8: =VLOOKUP(A8,'Product Backlog HUs(1)'!A$1:M$99,2,FALSE) -> Consultar Información de la Sede | D8: =VLOOKUP(A8,P$1:S$89,3,FALSE) -> 4 | P8: HU56 | Q8: XL | R8: =VLOOKUP(Q8,Tallas!A$1:D$8,4,FALSE) -> 32 | S8: 7
A9: =P14 -> HU61 | B9: =VLOOKUP(A9,'Product Backlog HUs(1)'!A$1:M$99,2,FALSE) -> Eliminar Información de la Sede | D9: =VLOOKUP(A9,P$1:S$89,3,FALSE) -> 8 | P9: HU53 | Q9: L | R9: =VLOOKUP(Q9,Tallas!A$1:D$8,4,FALSE) -> 16 | S9: 8
A10: =P8 -> HU56 | B10: =VLOOKUP(A10,'Product Backlog HUs(1)'!A$1:M$99,2,FALSE) -> Restablecer la Clave del Representante Sede | C10: Sprint 6 | D10: =VLOOKUP(A10,P$1:S$89,3,FALSE) -> 32 | E10: =SUM(D10:D11) -> 48 | F10: =SUM(E10:E13) -> 70 | G10: Release 3 | P10: HU59 | Q10: L | R10: =VLOOKUP(Q10,Tallas!A$1:D$8,4,FALSE) -> 16 | S10: 9
A11: =P20 -> HU67 | B11: =VLOOKUP(A11,'Product Backlog HUs(1)'!A$1:M$99,2,FALSE) -> Crear Información del Servicio Sede | C11: Sprint 7 | D11: =VLOOKUP(A11,P$1:S$89,3,FALSE) -> 16 | E11: =SUM(D11:D13) -> 22 | P11: HU62 | Q11: S | R11: =VLOOKUP(Q11,Tallas!A$1:D$8,4,FALSE) -> 4 | S11: 10
A12: =P19 -> HU63 | B12: =VLOOKUP(A12,'Product Backlog HUs(1)'!A$1:M$99,2,FALSE) -> Consultar Información del Servicio | D12: =VLOOKUP(A12,P$1:S$89,3,FALSE) -> 4 | P12: HU76 | Q12: M | R12: =VLOOKUP(Q12,Tallas!A$1:D$8,4,FALSE) -> 8 | S12: 11
A13: =P16 -> HU29 | B13: =VLOOKUP(A13,'Product Backlog HUs(1)'!A$1:M$99,2,FALSE) -> Consultar Información de la Franquicia | D13: =VLOOKUP(A13,P$1:S$89,3,FALSE) -> 2 | P13: HU60 | Q13: L | R13: =VLOOKUP(Q13,Tallas!A$1:D$8,4,FALSE) -> 16 | S13: 12
A14: =P30 -> HU15 | B14: =VLOOKUP(A14,'Product Backlog HUs(1)'!A$1:M$99,2,FALSE) -> Consultar Información del Estado del Servicio Realizado | C14: Sprint 8 | D14: =VLOOKUP(A14,P$1:S$89,3,FALSE) -> 32 | E14: =D14 -> 32 | F14: =SUM(E14:E18) -> 64 | G14: Release 4 | P14: HU61 | Q14: M | R14: =VLOOKUP(Q14,Tallas!A$1:D$8,4,FALSE) -> 8 | S14: 13
A15: =P25 -> HU72 | B15: =VLOOKUP(A15,'Product Backlog HUs(1)'!A$1:M$99,2,FALSE) -> Desactivar el Servicio Sede | C15: Sprint 9 | D15: =VLOOKUP(A15,P$1:S$89,3,FALSE) -> 8 | E15: =SUM(D15:D18) -> 32 | P15: HU26 | Q15: M | R15: =VLOOKUP(Q15,Tallas!A$1:D$8,4,FALSE) -> 8 | S15: 14
A16: =P26 -> HU69 | B16: =VLOOKUP(A16,'Product Backlog HUs(1)'!A$1:M$99,2,FALSE) -> Eliminar Información del Servicio Sede | D16: =VLOOKUP(A16,P$1:S$89,3,FALSE) -> 4 | P16: HU29 | Q16: XS | R16: =VLOOKUP(Q16,Tallas!A$1:D$8,4,FALSE) -> 2 | S16: 15
A17: =P27 -> HU66 | B17: =VLOOKUP(A17,'Product Backlog HUs(1)'!A$1:M$99,2,FALSE) -> Consultar Información del Servicio Realizado | D17: =VLOOKUP(A17,P$1:S$89,3,FALSE) -> 4 | P17: HU27 | Q17: M | R17: =VLOOKUP(Q17,Tallas!A$1:D$8,4,FALSE) -> 8 | S17: 16
A18: =P9 -> HU53 | B18: =VLOOKUP(A18,'Product Backlog HUs(1)'!A$1:M$99,2,FALSE) -> Eliminar Información del Representante Sede | D18: =VLOOKUP(A18,P$1:S$89,3,FALSE) -> 16 | P18: HU28 | Q18: L | R18: =VLOOKUP(Q18,Tallas!A$1:D$8,4,FALSE) -> 16 | S18: 17
A19: =P10 -> HU59 | B19: =VLOOKUP(A19,'Product Backlog HUs(1)'!A$1:M$99,2,FALSE) -> Registrar Información de una nueva Sede | C19: Sprint 10 | D19: =VLOOKUP(A19,P$1:S$89,3,FALSE) -> 16 | E19: =SUM(D19:D21) -> 28 | F19: =SUM(E19:E25) -> 62 | G19: Release 5 | P19: HU63 | Q19: S | R19: =VLOOKUP(Q19,Tallas!A$1:D$8,4,FALSE) -> 4 | S19: 18
A20: =P21 -> HU70 | B20: =VLOOKUP(A20,'Product Backlog HUs(1)'!A$1:M$99,2,FALSE) -> Consultar Información del Servicio Sede | D20: =VLOOKUP(A20,P$1:S$89,3,FALSE) -> 4 | P20: HU67 | Q20: L | R20: =VLOOKUP(Q20,Tallas!A$1:D$8,4,FALSE) -> 16 | S20: 19
A21: =P12 -> HU76 | B21: =VLOOKUP(A21,'Product Backlog HUs(1)'!A$1:M$99,2,FALSE) -> Consultar Información del Tipo Sede | D21: =VLOOKUP(A21,P$1:S$89,3,FALSE) -> 8 | P21: HU70 | Q21: S | R21: =VLOOKUP(Q21,Tallas!A$1:D$8,4,FALSE) -> 4 | S21: 20
A22: =P13 -> HU60 | B22: =VLOOKUP(A22,'Product Backlog HUs(1)'!A$1:M$99,2,FALSE) -> Modificar la Información de la Sede | C22: Sprint 11 | D22: =VLOOKUP(A22,P$1:S$89,3,FALSE) -> 16 | E22: =SUM(D22:D25) -> 34 | P22: HU75 | Q22: XS | R22: =VLOOKUP(Q22,Tallas!A$1:D$8,4,FALSE) -> 2 | S22: 21
A23: =P17 -> HU27 | B23: =VLOOKUP(A23,'Product Backlog HUs(1)'!A$1:M$99,2,FALSE) -> Modificar Información de la Franquicia | D23: =VLOOKUP(A23,P$1:S$89,3,FALSE) -> 8 | P23: HU68 | Q23: M | R23: =VLOOKUP(Q23,Tallas!A$1:D$8,4,FALSE) -> 8 | S23: 22
A24: =P15 -> HU26 | B24: =VLOOKUP(A24,'Product Backlog HUs(1)'!A$1:M$99,2,FALSE) -> Registrar Información de la Franquicia | D24: =VLOOKUP(A24,P$1:S$89,3,FALSE) -> 8 | P24: HU71 | Q24: M | R24: =VLOOKUP(Q24,Tallas!A$1:D$8,4,FALSE) -> 8 | S24: 23
A25: =P22 -> HU75 | B25: =VLOOKUP(A25,'Product Backlog HUs(1)'!A$1:M$99,2,FALSE) -> Consultar Información del Tipo Servicio | D25: =VLOOKUP(A25,P$1:S$89,3,FALSE) -> 2 | P25: HU72 | Q25: M | R25: =VLOOKUP(Q25,Tallas!A$1:D$8,4,FALSE) -> 8 | S25: 24
A26: =P18 -> HU28 | B26: =VLOOKUP(A26,'Product Backlog HUs(1)'!A$1:M$99,2,FALSE) -> Eliminar Información de la Franquicia | C26: Sprint 12 | D26: =VLOOKUP(A26,P$1:S$89,3,FALSE) -> 16 | E26: =SUM(D26:D28) -> 32 | F26: =SUM(E26:E29) -> 64 | G26: Release 6 | P26: HU69 | Q26: S | R26: =VLOOKUP(Q26,Tallas!A$1:D$8,4,FALSE) -> 4 | S26: 25
A27: =P23 -> HU68 | B27: =VLOOKUP(A27,'Product Backlog HUs(1)'!A$1:M$99,2,FALSE) -> Modificar Información del Servicio Sede | D27: =VLOOKUP(A27,P$1:S$89,3,FALSE) -> 8 | P27: HU66 | Q27: S | R27: =VLOOKUP(Q27,Tallas!A$1:D$8,4,FALSE) -> 4 | S27: 26
A28: =P24 -> HU71 | B28: =VLOOKUP(A28,'Product Backlog HUs(1)'!A$1:M$99,2,FALSE) -> Activar el Servicio Sede | D28: =VLOOKUP(A28,P$1:S$89,3,FALSE) -> 8 | P28: HU64 | Q28: XL | R28: =VLOOKUP(Q28,Tallas!A$1:D$8,4,FALSE) -> 32 | S28: 27
A29: =P28 -> HU64 | B29: =VLOOKUP(A29,'Product Backlog HUs(1)'!A$1:M$99,2,FALSE) -> Registrar Información del Servicio Realizado | C29: Sprint 13 | D29: =VLOOKUP(A29,P$1:S$89,3,FALSE) -> 32 | E29: =D29 -> 32 | P29: HU65 | Q29: L | R29: =VLOOKUP(Q29,Tallas!A$1:D$8,4,FALSE) -> 16 | S29: 28
A30: =P29 -> HU65 | B30: =VLOOKUP(A30,'Product Backlog HUs(1)'!A$1:M$99,2,FALSE) -> Eliminar Información del Servicio Realizado | C30: Sprint 14 | D30: =VLOOKUP(A30,P$1:S$89,3,FALSE) -> 16 | E30: =SUM(D30:D31) -> 20 | F30: =SUM(E30:E33) -> 84 | G30: Release 7 | P30: HU15 | Q30: XL | R30: =VLOOKUP(Q30,Tallas!A$1:D$8,4,FALSE) -> 32 | S30: 29
A31: =P31 -> HU73 | B31: =VLOOKUP(A31,'Product Backlog HUs(1)'!A$1:M$99,2,FALSE) -> Consultar Información de la Transición Estado Servicio Realizado | D31: =VLOOKUP(A31,P$1:S$89,3,FALSE) -> 4 | P31: HU73 | Q31: S | R31: =VLOOKUP(Q31,Tallas!A$1:D$8,4,FALSE) -> 4 | S31: 30
A32: =P32 -> HU74 | B32: =VLOOKUP(A32,'Product Backlog HUs(1)'!A$1:M$99,2,FALSE) -> Actualizar la Información de la Transición Estado Servicio Realizado | C32: Sprint 15 | D32: =VLOOKUP(A32,P$1:S$89,3,FALSE) -> 32 | E32: =D32 -> 32 | P32: HU74 | Q32: XL | R32: =VLOOKUP(Q32,Tallas!A$1:D$8,4,FALSE) -> 32 | S32: 31
A33: =P33 -> HU30 | B33: =VLOOKUP(A33,'Product Backlog HUs(1)'!A$1:M$99,2,FALSE) -> Registrar Información del Horario Sede | C33: Sprint 16 | D33: =VLOOKUP(A33,P$1:S$89,3,FALSE) -> 32 | E33: =D33 -> 32 | P33: HU30 | Q33: XL | R33: =VLOOKUP(Q33,Tallas!A$1:D$8,4,FALSE) -> 32 | S33: 32
A34: =P34 -> HU32 | B34: =VLOOKUP(A34,'Product Backlog HUs(1)'!A$1:M$99,2,FALSE) -> Consultar Información del Horario Sede | C34: Sprint 17 | D34: =VLOOKUP(A34,P$1:S$89,3,FALSE) -> 2 | E34: =SUM(D34:D39) -> 24 | F34: =SUM(E34:E43) -> 58 | G34: Release 8 | P34: HU32 | Q34: XS | R34: =VLOOKUP(Q34,Tallas!A$1:D$8,4,FALSE) -> 2 | S34: 33
A35: =P89 -> HU48 | B35: =VLOOKUP(A35,'Product Backlog HUs(1)'!A$1:M$99,2,FALSE) -> Consultar Información del Rango Calificación | D35: =VLOOKUP(A35,P$1:S$89,3,FALSE) -> 2 | P35: HU31 | Q35: M | R35: =VLOOKUP(Q35,Tallas!A$1:D$8,4,FALSE) -> 8 | S35: 34
A36: =P35 -> HU31 | B36: =VLOOKUP(A36,'Product Backlog HUs(1)'!A$1:M$99,2,FALSE) -> Modificar Información del Horario Sede | D36: =VLOOKUP(A36,P$1:S$89,3,FALSE) -> 8 | P36: HU34 | Q36: S | R36: =VLOOKUP(Q36,Tallas!A$1:D$8,4,FALSE) -> 4 | S36: 35
A37: =P36 -> HU34 | B37: =VLOOKUP(A37,'Product Backlog HUs(1)'!A$1:M$99,2,FALSE) -> Activar el Horario Sede | D37: =VLOOKUP(A37,P$1:S$89,3,FALSE) -> 4 | P37: HU35 | Q37: S | R37: =VLOOKUP(Q37,Tallas!A$1:D$8,4,FALSE) -> 4 | S37: 36
A38: =P37 -> HU35 | B38: =VLOOKUP(A38,'Product Backlog HUs(1)'!A$1:M$99,2,FALSE) -> Desactivar el Horario Sede | D38: =VLOOKUP(A38,P$1:S$89,3,FALSE) -> 4 | P38: HU33 | Q38: M | R38: =VLOOKUP(Q38,Tallas!A$1:D$8,4,FALSE) -> 8 | S38: 37
A39: =P40 -> HU9 | B39: =VLOOKUP(A39,'Product Backlog HUs(1)'!A$1:M$99,2,FALSE) -> Consultar Información del Detalle Horario | D39: =VLOOKUP(A39,P$1:S$89,3,FALSE) -> 4 | P39: HU6 | Q39: XL | R39: =VLOOKUP(Q39,Tallas!A$1:D$8,4,FALSE) -> 32 | S39: 38
A40: =P41 -> HU7 | B40: =VLOOKUP(A40,'Product Backlog HUs(1)'!A$1:M$99,2,FALSE) -> Modificar Información del Detalle Horario | C40: Sprint 18 | D40: =VLOOKUP(A40,P$1:S$89,3,FALSE) -> 16 | E40: =SUM(D40:D43) -> 34 | P40: HU9 | Q40: S | R40: =VLOOKUP(Q40,Tallas!A$1:D$8,4,FALSE) -> 4 | S40: 39
...

Sheet Plan de liberaciones
A1: Identificador | B1: Historia de usuario | C1: Sprint | D1: Horas | E1: Acumulado horas Release | F1: Release | O1: Identificador | P1: Talla | Q1: Horas Talla | R1: HU Prioridad
A2: =O2 -> HU51 | B2: =VLOOKUP(A2,'Product Backlog HUs(1)'!A$1:M$99,2,FALSE) -> Registrar Información del Representante Sede | C2: Sprint 1 | D2: =VLOOKUP(A2,O$1:R$89,3,FALSE) -> 32 | E2: =SUM(D2:D4) -> 56 | F2: Release 1 | O2: HU51 | P2: XL | Q2: =VLOOKUP(P2,Tallas!A$1:D$8,4,FALSE) -> 32 | R2: 1
A3: =O3 -> HU58 | B3: =VLOOKUP(A3,'Product Backlog HUs(1)'!A$1:M$99,2,FALSE) -> Autenticar Información del Representante Sede | C3: Sprint 2 | D3: =VLOOKUP(A3,O$1:R$89,3,FALSE) -> 16 | F3: Release 1 | O3: HU58 | P3: L | Q3: =VLOOKUP(P3,Tallas!A$1:D$8,4,FALSE) -> 16 | R3: 2
A4: =O4 -> HU54 | B4: =VLOOKUP(A4,'Product Backlog HUs(1)'!A$1:M$99,2,FALSE) -> Consultar Información detallada del Representante Sede | C4: Sprint 3 | D4: =VLOOKUP(A4,O$1:R$89,3,FALSE) -> 8 | F4: Release 1 | O4: HU54 | P4: M | Q4: =VLOOKUP(P4,Tallas!A$1:D$8,4,FALSE) -> 8 | R4: 3
A5: =O5 -> HU55 | B5: =VLOOKUP(A5,'Product Backlog HUs(1)'!A$1:M$99,2,FALSE) -> Consultar Información General del Representante Sede | C5: Sprint 4 | D5: =VLOOKUP(A5,O$1:R$89,3,FALSE) -> 2 | E5: =SUM(D5:D8) -> 82 | F5: Release 2 | O5: HU55 | P5: XS | Q5: =VLOOKUP(P5,Tallas!A$1:D$8,4,FALSE) -> 2 | R5: 4
A6: =O6 -> HU52 | B6: =VLOOKUP(A6,'Product Backlog HUs(1)'!A$1:M$99,2,FALSE) -> Modificar Información del Representante Sede | C6: Sprint 4 | D6: =VLOOKUP(A6,O$1:R$89,3,FALSE) -> 32 | F6: Release 2 | O6: HU52 | P6: XL | Q6: =VLOOKUP(P6,Tallas!A$1:D$8,4,FALSE) -> 32 | R6: 5
A7: =O7 -> HU57 | B7: =VLOOKUP(A7,'Product Backlog HUs(1)'!A$1:M$99,2,FALSE) -> Modificar la Clave del Representante Sede | C7: Sprint 5 | D7: =VLOOKUP(A7,O$1:R$89,3,FALSE) -> 16 | F7: Release 2 | O7: HU57 | P7: L | Q7: =VLOOKUP(P7,Tallas!A$1:D$8,4,FALSE) -> 16 | R7: 6
A8: =O8 -> HU56 | B8: =VLOOKUP(A8,'Product Backlog HUs(1)'!A$1:M$99,2,FALSE) -> Restablecer la Clave del Representante Sede | C8: Sprint 5 | D8: =VLOOKUP(A8,O$1:R$89,3,FALSE) -> 32 | F8: Release 2 | O8: HU56 | P8: XL | Q8: =VLOOKUP(P8,Tallas!A$1:D$8,4,FALSE) -> 32 | R8: 7
A9: =O9 -> HU59 | B9: =VLOOKUP(A9,'Product Backlog HUs(1)'!A$1:M$99,2,FALSE) -> Registrar Información de una nueva Sede | C9: Sprint 6 | D9: =VLOOKUP(A9,O$1:R$89,3,FALSE) -> 16 | E9: =SUM(D9:D17) -> 74 | F9: Release 3 | O9: HU59 | P9: L | Q9: =VLOOKUP(P9,Tallas!A$1:D$8,4,FALSE) -> 16 | R9: 8
A10: =O10 -> HU42 | B10: =VLOOKUP(A10,'Product Backlog HUs(1)'!A$1:M$99,2,FALSE) -> Consultar Información de las Marcas de Motocicletas | C10: Sprint 6 | D10: =VLOOKUP(A10,O$1:R$89,3,FALSE) -> 2 | F10: Release 3 | O10: HU42 | P10: XS | Q10: =VLOOKUP(P10,Tallas!A$1:D$8,4,FALSE) -> 2 | R10: 9
A11: =O11 -> HU62 | B11: =VLOOKUP(A11,'Product Backlog HUs(1)'!A$1:M$99,2,FALSE) -> Consultar Información de la Sede | C11: Sprint 7 | D11: =VLOOKUP(A11,O$1:R$89,3,FALSE) -> 4 | F11: Release 3 | O11: HU62 | P11: S | Q11: =VLOOKUP(P11,Tallas!A$1:D$8,4,FALSE) -> 4 | R11: 10
A12: =O12 -> HU76 | B12: =VLOOKUP(A12,'Product Backlog HUs(1)'!A$1:M$99,2,FALSE) -> Consultar Información del Tipo Sede | C12: Sprint 7 | D12: =VLOOKUP(A12,O$1:R$89,3,FALSE) -> 8 | F12: Release 3 | O12: HU76 | P12: M | Q12: =VLOOKUP(P12,Tallas!A$1:D$8,4,FALSE) -> 8 | R12: 11
A13: =O13 -> HU5 | B13: =VLOOKUP(A13,'Product Backlog HUs(1)'!A$1:M$99,2,FALSE) -> Consultar Información del Departamento | C13: Sprint 7 | D13: =VLOOKUP(A13,O$1:R$89,3,FALSE) -> 2 | F13: Release 3 | O13: HU5 | P13: XS | Q13: =VLOOKUP(P13,Tallas!A$1:D$8,4,FALSE) -> 2 | R13: 12
A14: =O14 -> HU4 | B14: =VLOOKUP(A14,'Product Backlog HUs(1)'!A$1:M$99,2,FALSE) -> Consultar Información de la Ciudad | C14: Sprint 8 | D14: =VLOOKUP(A14,O$1:R$89,3,FALSE) -> 2 | F14: Release 3 | O14: HU4 | P14: XS | Q14: =VLOOKUP(P14,Tallas!A$1:D$8,4,FALSE) -> 2 | R14: 13
A15: =O15 -> HU60 | B15: =VLOOKUP(A15,'Product Backlog HUs(1)'!A$1:M$99,2,FALSE) -> Modificar la Información de la Sede | C15: Sprint 9 | D15: =VLOOKUP(A15,O$1:R$89,3,FALSE) -> 16 | F15: Release 3 | O15: HU60 | P15: L | Q15: =VLOOKUP(P15,Tallas!A$1:D$8,4,FALSE) -> 16 | R15: 14
A16: =O16 -> HU61 | B16: =VLOOKUP(A16,'Product Backlog HUs(1)'!A$1:M$99,2,FALSE) -> Eliminar Información de la Sede | C16: Sprint 9 | D16: =VLOOKUP(A16,O$1:R$89,3,FALSE) -> 8 | F16: Release 3 | O16: HU61 | P16: M | Q16: =VLOOKUP(P16,Tallas!A$1:D$8,4,FALSE) -> 8 | R16: 15
A17: =O17 -> HU53 | B17: =VLOOKUP(A17,'Product Backlog HUs(1)'!A$1:M$99,2,FALSE) -> Eliminar Información del Representante Sede | C17: Sprint 9 | D17: =VLOOKUP(A17,O$1:R$89,3,FALSE) -> 16 | F17: Release 3 | O17: HU53 | P17: L | Q17: =VLOOKUP(P17,Tallas!A$1:D$8,4,FALSE) -> 16 | R17: 16
A18: =O18 -> HU26 | B18: =VLOOKUP(A18,'Product Backlog HUs(1)'!A$1:M$99,2,FALSE) -> Registrar Información de la Franquicia | C18: Sprint 10 | D18: =VLOOKUP(A18,O$1:R$89,3,FALSE) -> 8 | E18: =SUM(D18:D21) -> 34 | F18: Release 4 | O18: HU26 | P18: M | Q18: =VLOOKUP(P18,Tallas!A$1:D$8,4,FALSE) -> 8 | R18: 17
A19: =O19 -> HU29 | B19: =VLOOKUP(A19,'Product Backlog HUs(1)'!A$1:M$99,2,FALSE) -> Consultar Información de la Franquicia | C19: Sprint 10 | D19: =VLOOKUP(A19,O$1:R$89,3,FALSE) -> 2 | F19: Release 4 | O19: HU29 | P19: XS | Q19: =VLOOKUP(P19,Tallas!A$1:D$8,4,FALSE) -> 2 | R19: 18
A20: =O20 -> HU27 | B20: =VLOOKUP(A20,'Product Backlog HUs(1)'!A$1:M$99,2,FALSE) -> Modificar Información de la Franquicia | C20: Sprint 10 | D20: =VLOOKUP(A20,O$1:R$89,3,FALSE) -> 8 | F20: Release 4 | O20: HU27 | P20: M | Q20: =VLOOKUP(P20,Tallas!A$1:D$8,4,FALSE) -> 8 | R20: 19
A21: =O21 -> HU28 | B21: =VLOOKUP(A21,'Product Backlog HUs(1)'!A$1:M$99,2,FALSE) -> Eliminar Información de la Franquicia | C21: Sprint 10 | D21: =VLOOKUP(A21,O$1:R$89,3,FALSE) -> 16 | F21: Release 4 | O21: HU28 | P21: L | Q21: =VLOOKUP(P21,Tallas!A$1:D$8,4,FALSE) -> 16 | R21: 20
A22: =O22 -> HU75 | B22: =VLOOKUP(A22,'Product Backlog HUs(1)'!A$1:M$99,2,FALSE) -> Consultar Información del Tipo Servicio | C22: Sprint 11 | D22: =VLOOKUP(A22,O$1:R$89,3,FALSE) -> 2 | E22: =SUM(D22:D29) -> 54 | F22: Release 5 | O22: HU75 | P22: XS | Q22: =VLOOKUP(P22,Tallas!A$1:D$8,4,FALSE) -> 2 | R22: 21
A23: =O23 -> HU63 | B23: =VLOOKUP(A23,'Product Backlog HUs(1)'!A$1:M$99,2,FALSE) -> Consultar Información del Servicio | C23: Sprint 11 | D23: =VLOOKUP(A23,O$1:R$89,3,FALSE) -> 4 | F23: Release 5 | O23: HU63 | P23: S | Q23: =VLOOKUP(P23,Tallas!A$1:D$8,4,FALSE) -> 4 | R23: 22
A24: =O24 -> HU67 | B24: =VLOOKUP(A24,'Product Backlog HUs(1)'!A$1:M$99,2,FALSE) -> Crear Información del Servicio Sede | C24: Sprint 11 | D24: =VLOOKUP(A24,O$1:R$89,3,FALSE) -> 16 | F24: Release 5 | O24: HU67 | P24: L | Q24: =VLOOKUP(P24,Tallas!A$1:D$8,4,FALSE) -> 16 | R24: 23
A25: =O25 -> HU70 | B25: =VLOOKUP(A25,'Product Backlog HUs(1)'!A$1:M$99,2,FALSE) -> Consultar Información del Servicio Sede | C25: Sprint 11 | D25: =VLOOKUP(A25,O$1:R$89,3,FALSE) -> 4 | F25: Release 5 | O25: HU70 | P25: S | Q25: =VLOOKUP(P25,Tallas!A$1:D$8,4,FALSE) -> 4 | R25: 24
A26: =O26 -> HU68 | B26: =VLOOKUP(A26,'Product Backlog HUs(1)'!A$1:M$99,2,FALSE) -> Modificar Información del Servicio Sede | C26: Sprint 12 | D26: =VLOOKUP(A26,O$1:R$89,3,FALSE) -> 8 | F26: Release 5 | O26: HU68 | P26: M | Q26: =VLOOKUP(P26,Tallas!A$1:D$8,4,FALSE) -> 8 | R26: 25
A27: =O27 -> HU69 | B27: =VLOOKUP(A27,'Product Backlog HUs(1)'!A$1:M$99,2,FALSE) -> Eliminar Información del Servicio Sede | C27: Sprint 12 | D27: =VLOOKUP(A27,O$1:R$89,3,FALSE) -> 4 | F27: Release 5 | O27: HU69 | P27: S | Q27: =VLOOKUP(P27,Tallas!A$1:D$8,4,FALSE) -> 4 | R27: 26
A28: =O28 -> HU71 | B28: =VLOOKUP(A28,'Product Backlog HUs(1)'!A$1:M$99,2,FALSE) -> Activar el Servicio Sede | C28: Sprint 12 | D28: =VLOOKUP(A28,O$1:R$89,3,FALSE) -> 8 | F28: Release 5 | O28: HU71 | P28: M | Q28: =VLOOKUP(P28,Tallas!A$1:D$8,4,FALSE) -> 8 | R28: 27
A29: =O29 -> HU72 | B29: =VLOOKUP(A29,'Product Backlog HUs(1)'!A$1:M$99,2,FALSE) -> Desactivar el Servicio Sede | C29: Sprint 13 | D29: =VLOOKUP(A29,O$1:R$89,3,FALSE) -> 8 | F29: Release 5 | O29: HU72 | P29: M | Q29: =VLOOKUP(P29,Tallas!A$1:D$8,4,FALSE) -> 8 | R29: 28
A30: =O30 -> HU30 | B30: =VLOOKUP(A30,'Product Backlog HUs(1)'!A$1:M$99,2,FALSE) -> Registrar Información del Horario Sede | C30: Sprint 14 | D30: =VLOOKUP(A30,O$1:R$89,3,FALSE) -> 32 | E30: =SUM(D30:D36) -> 60 | F30: Release 6 | O30: HU30 | P30: XL | Q30: =VLOOKUP(P30,Tallas!A$1:D$8,4,FALSE) -> 32 | R30: 29
A31: =O31 -> HU32 | B31: =VLOOKUP(A31,'Product Backlog HUs(1)'!A$1:M$99,2,FALSE) -> Consultar Información del Horario Sede | C31: Sprint 14 | D31: =VLOOKUP(A31,O$1:R$89,3,FALSE) -> 2 | F31: Release 6 | O31: HU32 | P31: XS | Q31: =VLOOKUP(P31,Tallas!A$1:D$8,4,FALSE) -> 2 | R31: 30
A32: =O32 -> HU31 | B32: =VLOOKUP(A32,'Product Backlog HUs(1)'!A$1:M$99,2,FALSE) -> Modificar Información del Horario Sede | C32: Sprint 15 | D32: =VLOOKUP(A32,O$1:R$89,3,FALSE) -> 8 | F32: Release 6 | O32: HU31 | P32: M | Q32: =VLOOKUP(P32,Tallas!A$1:D$8,4,FALSE) -> 8 | R32: 31
A33: =O33 -> HU33 | B33: =VLOOKUP(A33,'Product Backlog HUs(1)'!A$1:M$99,2,FALSE) -> Eliminar Información del Horario Sede | C33: Sprint 16 | D33: =VLOOKUP(A33,O$1:R$89,3,FALSE) -> 8 | F33: Release 6 | O33: HU33 | P33: M | Q33: =VLOOKUP(P33,Tallas!A$1:D$8,4,FALSE) -> 8 | R33: 32
A34: =O34 -> HU34 | B34: =VLOOKUP(A34,'Product Backlog HUs(1)'!A$1:M$99,2,FALSE) -> Activar el Horario Sede | C34: Sprint 17 | D34: =VLOOKUP(A34,O$1:R$89,3,FALSE) -> 4 | F34: Release 6 | O34: HU34 | P34: S | Q34: =VLOOKUP(P34,Tallas!A$1:D$8,4,FALSE) -> 4 | R34: 33
A35: =O35 -> HU35 | B35: =VLOOKUP(A35,'Product Backlog HUs(1)'!A$1:M$99,2,FALSE) -> Desactivar el Horario Sede | C35: Sprint 17 | D35: =VLOOKUP(A35,O$1:R$89,3,FALSE) -> 4 | F35: Release 6 | O35: HU35 | P35: S | Q35: =VLOOKUP(P35,Tallas!A$1:D$8,4,FALSE) -> 4 | R35: 34
A36: =O36 -> HU10 | B36: =VLOOKUP(A36,'Product Backlog HUs(1)'!A$1:M$99,2,FALSE) -> Consultar Información del Día | C36: Sprint 17 | D36: =VLOOKUP(A36,O$1:R$89,3,FALSE) -> 2 | F36: Release 6 | O36: HU10 | P36: XS | Q36: =VLOOKUP(P36,Tallas!A$1:D$8,4,FALSE) -> 2 | R36: 35
A37: =O37 -> HU6 | B37: =VLOOKUP(A37,'Product Backlog HUs(1)'!A$1:M$99,2,FALSE) -> Registrar Información del Detalle Horario | C37: Sprint 18 | D37: =VLOOKUP(A37,O$1:R$89,3,FALSE) -> 32 | E37: =SUM(D37:D40) -> 68 | F37: Release 7 | O37: HU6 | P37: XL | Q37: =VLOOKUP(P37,Tallas!A$1:D$8,4,FALSE) -> 32 | R37: 36
A38: =O38 -> HU9 | B38: =VLOOKUP(A38,'Product Backlog HUs(1)'!A$1:M$99,2,FALSE) -> Consultar Información del Detalle Horario | C38: Sprint 18 | D38: =VLOOKUP(A38,O$1:R$89,3,FALSE) -> 4 | F38: Release 7 | O38: HU9 | P38: S | Q38: =VLOOKUP(P38,Tallas!A$1:D$8,4,FALSE) -> 4 | R38: 37
A39: =O39 -> HU7 | B39: =VLOOKUP(A39,'Product Backlog HUs(1)'!A$1:M$99,2,FALSE) -> Modificar Información del Detalle Horario | C39: Sprint 18 | D39: =VLOOKUP(A39,O$1:R$89,3,FALSE) -> 16 | F39: Release 7 | O39: HU7 | P39: L | Q39: =VLOOKUP(P39,Tallas!A$1:D$8,4,FALSE) -> 16 | R39: 38
A40: =O40 -> HU8 | B40: =VLOOKUP(A40,'Product Backlog HUs(1)'!A$1:M$99,2,FALSE) -> Eliminar Información del Detalle Horario | C40: Sprint 18 | D40: =VLOOKUP(A40,O$1:R$89,3,FALSE) -> 16 | F40: Release 7 | O40: HU8 | P40: L | Q40: =VLOOKUP(P40,Tallas!A$1:D$8,4,FALSE) -> 16 | R40: 39
...

Sheet Plan de liberaciones(1)
A1: Identificador | B1: Historia de usuario | C1: Sprint | E1: Horas | F1: Acumulado horas Sprint | G1: Acumulado horas Release | H1: Release | R1: Identificador | S1: Talla | T1: Horas Talla | U1: HU Prioridad
A2: =R2 -> HU51 | B2: =VLOOKUP(A2,'Product Backlog HUs(1)'!A$1:M$99,2,FALSE) -> Registrar Información del Representante Sede | C2: Sprint 1 | D2: Sprint 1 | E2: =VLOOKUP(A2,R$1:U$89,3,FALSE) -> 16 | F2: =SUM(E2:E3) -> 48 | G2: =SUM(F2:F4) -> 80 | H2: Release 1 | I2: Release 1 | R2: HU51 | S2: L | T2: =VLOOKUP(S2,Tallas!A$1:D$8,4,FALSE) -> 16 | U2: 1
A3: =R3 -> HU58 | B3: =VLOOKUP(A3,'Product Backlog HUs(1)'!A$1:M$99,2,FALSE) -> Autenticar Información del Representante Sede | D3: Sprint 1 | E3: =VLOOKUP(A3,R$1:U$89,3,FALSE) -> 32 | I3: Release 1 | R3: HU58 | S3: XL | T3: =VLOOKUP(S3,Tallas!A$1:D$8,4,FALSE) -> 32 | U3: 2
A4: =R4 -> HU54 | B4: =VLOOKUP(A4,'Product Backlog HUs(1)'!A$1:M$99,2,FALSE) -> Consultar Información detallada del Representante Sede | C4: Sprint 2 | D4: Sprint 2 | E4: =VLOOKUP(A4,R$1:U$89,3,FALSE) -> 32 | F4: =E4 -> 32 | I4: Release 1 | R4: HU54 | S4: XL | T4: =VLOOKUP(S4,Tallas!A$1:D$8,4,FALSE) -> 32 | U4: 3
A5: =R5 -> HU55 | B5: =VLOOKUP(A5,'Product Backlog HUs(1)'!A$1:M$99,2,FALSE) -> Consultar Información General del Representante Sede | C5: Sprint 3 | D5: Sprint 3 | E5: =VLOOKUP(A5,R$1:U$89,3,FALSE) -> 48 | F5: =E5 -> 48 | G5: =SUM(F5:F9) -> 76 | H5: Release 2 | I5: Release 2 | R5: HU55 | S5: XXL | T5: =VLOOKUP(S5,Tallas!A$1:D$8,4,FALSE) -> 48 | U5: 4
A6: =R6 -> HU52 | B6: =VLOOKUP(A6,'Product Backlog HUs(1)'!A$1:M$99,2,FALSE) -> Modificar Información del Representante Sede | C6: Sprint 4 | D6: Sprint 4 | E6: =VLOOKUP(A6,R$1:U$89,3,FALSE) -> 4 | F6: =SUM(E6:E9) -> 28 | I6: Release 2 | R6: HU52 | S6: S | T6: =VLOOKUP(S6,Tallas!A$1:D$8,4,FALSE) -> 4 | U6: 5
A7: =R7 -> HU57 | B7: =VLOOKUP(A7,'Product Backlog HUs(1)'!A$1:M$99,2,FALSE) -> Modificar la Clave del Representante Sede | D7: Sprint 4 | E7: =VLOOKUP(A7,R$1:U$89,3,FALSE) -> 4 | I7: Release 2 | R7: HU57 | S7: S | T7: =VLOOKUP(S7,Tallas!A$1:D$8,4,FALSE) -> 4 | U7: 6
A8: =R11 -> HU62 | B8: =VLOOKUP(A8,'Product Backlog HUs(1)'!A$1:M$99,2,FALSE) -> Consultar Información de la Sede | D8: Sprint 4 | E8: =VLOOKUP(A8,R$1:U$89,3,FALSE) -> 16 | I8: Release 2 | R8: HU56 | S8: S | T8: =VLOOKUP(S8,Tallas!A$1:D$8,4,FALSE) -> 4 | U8: 7
A9: =R14 -> HU61 | B9: =VLOOKUP(A9,'Product Backlog HUs(1)'!A$1:M$99,2,FALSE) -> Eliminar Información de la Sede | D9: Sprint 4 | E9: =VLOOKUP(A9,R$1:U$89,3,FALSE) -> 4 | I9: Release 2 | R9: HU53 | S9: XXL | T9: =VLOOKUP(S9,Tallas!A$1:D$8,4,FALSE) -> 48 | U9: 8
A10: =R8 -> HU56 | B10: =VLOOKUP(A10,'Product Backlog HUs(1)'!A$1:M$99,2,FALSE) -> Restablecer la Clave del Representante Sede | C10: Sprint 5 | D10: Sprint 5 | E10: =VLOOKUP(A10,R$1:U$89,3,FALSE) -> 4 | F10: =SUM(E10:E14) -> 18 | G10: =SUM(F10:F16) -> 66 | H10: Release 3 | I10: Release 3 | R10: HU59 | S10: L | T10: =VLOOKUP(S10,Tallas!A$1:D$8,4,FALSE) -> 16 | U10: 9
A11: =R20 -> HU67 | B11: =VLOOKUP(A11,'Product Backlog HUs(1)'!A$1:M$99,2,FALSE) -> Crear Información del Servicio Sede | D11: Sprint 5 | E11: =VLOOKUP(A11,R$1:U$89,3,FALSE) -> 2 | I11: Release 3 | R11: HU62 | S11: L | T11: =VLOOKUP(S11,Tallas!A$1:D$8,4,FALSE) -> 16 | U11: 10
A12: =R19 -> HU63 | B12: =VLOOKUP(A12,'Product Backlog HUs(1)'!A$1:M$99,2,FALSE) -> Consultar Información del Servicio | D12: Sprint 5 | E12: =VLOOKUP(A12,R$1:U$89,3,FALSE) -> 2 | I12: Release 3 | R12: HU76 | S12: M | T12: =VLOOKUP(S12,Tallas!A$1:D$8,4,FALSE) -> 8 | U12: 11
A13: =R16 -> HU29 | B13: =VLOOKUP(A13,'Product Backlog HUs(1)'!A$1:M$99,2,FALSE) -> Consultar Información de la Franquicia | D13: Sprint 5 | E13: =VLOOKUP(A13,R$1:U$89,3,FALSE) -> 8 | I13: Release 3 | R13: HU60 | S13: S | T13: =VLOOKUP(S13,Tallas!A$1:D$8,4,FALSE) -> 4 | U13: 12
A14: =R30 -> HU15 | B14: =VLOOKUP(A14,'Product Backlog HUs(1)'!A$1:M$99,2,FALSE) -> Consultar Información del Estado del Servicio Realizado | D14: Sprint 5 | E14: =VLOOKUP(A14,R$1:U$89,3,FALSE) -> 2 | I14: Release 3 | R14: HU61 | S14: S | T14: =VLOOKUP(S14,Tallas!A$1:D$8,4,FALSE) -> 4 | U14: 13
A15: =R25 -> HU72 | B15: =VLOOKUP(A15,'Product Backlog HUs(1)'!A$1:M$99,2,FALSE) -> Desactivar el Servicio Sede | C15: Sprint 6 | D15: Sprint 6 | E15: =VLOOKUP(A15,R$1:U$89,3,FALSE) -> 32 | F15: =E15 -> 32 | I15: Release 3 | R15: HU26 | S15: XL | T15: =VLOOKUP(S15,Tallas!A$1:D$8,4,FALSE) -> 32 | U15: 14
A16: =R26 -> HU69 | B16: =VLOOKUP(A16,'Product Backlog HUs(1)'!A$1:M$99,2,FALSE) -> Eliminar Información del Servicio Sede | C16: Sprint 7 | D16: Sprint 7 | E16: =VLOOKUP(A16,R$1:U$89,3,FALSE) -> 16 | F16: =E16 -> 16 | I16: Release 3 | R16: HU29 | S16: M | T16: =VLOOKUP(S16,Tallas!A$1:D$8,4,FALSE) -> 8 | U16: 15
A17: =R27 -> HU66 | B17: =VLOOKUP(A17,'Product Backlog HUs(1)'!A$1:M$99,2,FALSE) -> Consultar Información del Servicio Realizado | C17: Sprint 8 | D17: Sprint 8 | E17: =VLOOKUP(A17,R$1:U$89,3,FALSE) -> 32 | F17: =E17 -> 32 | G17: =SUM(F17:F18) -> 80 | H17: Release 4 | I17: Release 4 | R17: HU27 | S17: S | T17: =VLOOKUP(S17,Tallas!A$1:D$8,4,FALSE) -> 4 | U17: 16
A18: =R9 -> HU53 | B18: =VLOOKUP(A18,'Product Backlog HUs(1)'!A$1:M$99,2,FALSE) -> Eliminar Información del Representante Sede | C18: Sprint 9 | D18: Sprint 9 | E18: =VLOOKUP(A18,R$1:U$89,3,FALSE) -> 48 | F18: =E18 -> 48 | I18: Release 4 | R18: HU28 | S18: XS | T18: =VLOOKUP(S18,Tallas!A$1:D$8,4,FALSE) -> 2 | U18: 17
A19: =R10 -> HU59 | B19: =VLOOKUP(A19,'Product Backlog HUs(1)'!A$1:M$99,2,FALSE) -> Registrar Información de una nueva Sede | C19: Sprint 10 | D19: Sprint 10 | E19: =VLOOKUP(A19,R$1:U$89,3,FALSE) -> 16 | F19: =SUM(E19:E23) -> 34 | G19: =SUM(F19:F25) -> 68 | H19: Release 5 | I19: Release 5 | R19: HU63 | S19: XS | T19: =VLOOKUP(S19,Tallas!A$1:D$8,4,FALSE) -> 2 | U19: 18
A20: =R21 -> HU70 | B20: =VLOOKUP(A20,'Product Backlog HUs(1)'!A$1:M$99,2,FALSE) -> Consultar Información del Servicio Sede | D20: Sprint 10 | E20: =VLOOKUP(A20,R$1:U$89,3,FALSE) -> 2 | I20: Release 5 | R20: HU67 | S20: XS | T20: =VLOOKUP(S20,Tallas!A$1:D$8,4,FALSE) -> 2 | U20: 19
A21: =R12 -> HU76 | B21: =VLOOKUP(A21,'Product Backlog HUs(1)'!A$1:M$99,2,FALSE) -> Consultar Información del Tipo Sede | D21: Sprint 10 | E21: =VLOOKUP(A21,R$1:U$89,3,FALSE) -> 8 | I21: Release 5 | R21: HU70 | S21: XS | T21: =VLOOKUP(S21,Tallas!A$1:D$8,4,FALSE) -> 2 | U21: 20
A22: =R13 -> HU60 | B22: =VLOOKUP(A22,'Product Backlog HUs(1)'!A$1:M$99,2,FALSE) -> Modificar la Información de la Sede | D22: Sprint 10 | E22: =VLOOKUP(A22,R$1:U$89,3,FALSE) -> 4 | I22: Release 5 | R22: HU75 | S22: XS | T22: =VLOOKUP(S22,Tallas!A$1:D$8,4,FALSE) -> 2 | U22: 21
A23: =R17 -> HU27 | B23: =VLOOKUP(A23,'Product Backlog HUs(1)'!A$1:M$99,2,FALSE) -> Modificar Información de la Franquicia | D23: Sprint 10 | E23: =VLOOKUP(A23,R$1:U$89,3,FALSE) -> 4 | I23: Release 5 | R23: HU68 | S23: XS | T23: =VLOOKUP(S23,Tallas!A$1:D$8,4,FALSE) -> 2 | U23: 22
A24: =R15 -> HU26 | B24: =VLOOKUP(A24,'Product Backlog HUs(1)'!A$1:M$99,2,FALSE) -> Registrar Información de la Franquicia | C24: Sprint 11 | D24: Sprint 11 | E24: =VLOOKUP(A24,R$1:U$89,3,FALSE) -> 32 | F24: =SUM(E24:E25) -> 34 | I24: Release 5 | R24: HU71 | S24: M | T24: =VLOOKUP(S24,Tallas!A$1:D$8,4,FALSE) -> 8 | U24: 23
A25: =R22 -> HU75 | B25: =VLOOKUP(A25,'Product Backlog HUs(1)'!A$1:M$99,2,FALSE) -> Consultar Información del Tipo Servicio | D25: Sprint 11 | E25: =VLOOKUP(A25,R$1:U$89,3,FALSE) -> 2 | I25: Release 5 | R25: HU72 | S25: XL | T25: =VLOOKUP(S25,Tallas!A$1:D$8,4,FALSE) -> 32 | U25: 24
A26: =R18 -> HU28 | B26: =VLOOKUP(A26,'Product Backlog HUs(1)'!A$1:M$99,2,FALSE) -> Eliminar Información de la Franquicia | C26: Sprint 12 | D26: Sprint 12 | E26: =VLOOKUP(A26,R$1:U$89,3,FALSE) -> 2 | F26: =SUM(E26:E31) -> 18 | G26: =SUM(F26:F35) -> 74 | H26: Release 6 | I26: Release 6 | R26: HU69 | S26: L | T26: =VLOOKUP(S26,Tallas!A$1:D$8,4,FALSE) -> 16 | U26: 25
A27: =R23 -> HU68 | B27: =VLOOKUP(A27,'Product Backlog HUs(1)'!A$1:M$99,2,FALSE) -> Modificar Información del Servicio Sede | D27: Sprint 12 | E27: =VLOOKUP(A27,R$1:U$89,3,FALSE) -> 2 | I27: Release 6 | R27: HU66 | S27: XL | T27: =VLOOKUP(S27,Tallas!A$1:D$8,4,FALSE) -> 32 | U27: 26
A28: =R24 -> HU71 | B28: =VLOOKUP(A28,'Product Backlog HUs(1)'!A$1:M$99,2,FALSE) -> Activar el Servicio Sede | D28: Sprint 12 | E28: =VLOOKUP(A28,R$1:U$89,3,FALSE) -> 8 | I28: Release 6 | R28: HU64 | S28: XS | T28: =VLOOKUP(S28,Tallas!A$1:D$8,4,FALSE) -> 2 | U28: 27
A29: =R28 -> HU64 | B29: =VLOOKUP(A29,'Product Backlog HUs(1)'!A$1:M$99,2,FALSE) -> Registrar Información del Servicio Realizado | D29: Sprint 12 | E29: =VLOOKUP(A29,R$1:U$89,3,FALSE) -> 2 | I29: Release 6 | R29: HU65 | S29: XS | T29: =VLOOKUP(S29,Tallas!A$1:D$8,4,FALSE) -> 2 | U29: 28
A30: =R29 -> HU65 | B30: =VLOOKUP(A30,'Product Backlog HUs(1)'!A$1:M$99,2,FALSE) -> Eliminar Información del Servicio Realizado | D30: Sprint 12 | E30: =VLOOKUP(A30,R$1:U$89,3,FALSE) -> 2 | I30: Release 6 | R30: HU15 | S30: XS | T30: =VLOOKUP(S30,Tallas!A$1:D$8,4,FALSE) -> 2 | U30: 29
A31: =R31 -> HU73 | B31: =VLOOKUP(A31,'Product Backlog HUs(1)'!A$1:M$99,2,FALSE) -> Consultar Información de la Transición Estado Servicio Realizado | D31: Sprint 12 | E31: =VLOOKUP(A31,R$1:U$89,3,FALSE) -> 2 | I31: Release 6 | R31: HU73 | S31: XS | T31: =VLOOKUP(S31,Tallas!A$1:D$8,4,FALSE) -> 2 | U31: 30
A32: =R32 -> HU74 | B32: =VLOOKUP(A32,'Product Backlog HUs(1)'!A$1:M$99,2,FALSE) -> Actualizar la Información de la Transición Estado Servicio Realizado | C32: Sprint 13 | D32: Sprint 13 | E32: =VLOOKUP(A32,R$1:U$89,3,FALSE) -> 32 | F32: =SUM(E32:E33) -> 40 | I32: Release 6 | R32: HU74 | S32: XL | T32: =VLOOKUP(S32,Tallas!A$1:D$8,4,FALSE) -> 32 | U32: 31
A33: =R33 -> HU30 | B33: =VLOOKUP(A33,'Product Backlog HUs(1)'!A$1:M$99,2,FALSE) -> Registrar Información del Horario Sede | D33: Sprint 13 | E33: =VLOOKUP(A33,R$1:U$89,3,FALSE) -> 8 | I33: Release 6 | R33: HU30 | S33: M | T33: =VLOOKUP(S33,Tallas!A$1:D$8,4,FALSE) -> 8 | U33: 32
A34: =R34 -> HU32 | B34: =VLOOKUP(A34,'Product Backlog HUs(1)'!A$1:M$99,2,FALSE) -> Consultar Información del Horario Sede | C34: Sprint 14 | D34: Sprint 14 | E34: =VLOOKUP(A34,R$1:U$89,3,FALSE) -> 8 | F34: =SUM(E34:E35) -> 16 | I34: Release 6 | R34: HU32 | S34: M | T34: =VLOOKUP(S34,Tallas!A$1:D$8,4,FALSE) -> 8 | U34: 33
A35: =R89 -> HU48 | B35: =VLOOKUP(A35,'Product Backlog HUs(1)'!A$1:M$99,2,FALSE) -> Consultar Información del Rango Calificación | D35: Sprint 14 | E35: =VLOOKUP(A35,R$1:U$89,3,FALSE) -> 8 | I35: Release 6 | R35: HU31 | S35: M | T35: =VLOOKUP(S35,Tallas!A$1:D$8,4,FALSE) -> 8 | U35: 34
A36: =R35 -> HU31 | B36: =VLOOKUP(A36,'Product Backlog HUs(1)'!A$1:M$99,2,FALSE) -> Modificar Información del Horario Sede | C36: Sprint 15 | D36: Sprint 15 | E36: =VLOOKUP(A36,R$1:U$89,3,FALSE) -> 8 | F36: =SUM(E36:E41) -> 32 | G36: =SUM(F36:F46) -> 72 | H36: Release 7 | I36: Release 7 | R36: HU34 | S36: XS | T36: =VLOOKUP(S36,Tallas!A$1:D$8,4,FALSE) -> 2 | U36: 35
A37: =R36 -> HU34 | B37: =VLOOKUP(A37,'Product Backlog HUs(1)'!A$1:M$99,2,FALSE) -> Activar el Horario Sede | D37: Sprint 15 | E37: =VLOOKUP(A37,R$1:U$89,3,FALSE) -> 2 | I37: Release 7 | R37: HU35 | S37: XS | T37: =VLOOKUP(S37,Tallas!A$1:D$8,4,FALSE) -> 2 | U37: 36
A38: =R37 -> HU35 | B38: =VLOOKUP(A38,'Product Backlog HUs(1)'!A$1:M$99,2,FALSE) -> Desactivar el Horario Sede | D38: Sprint 15 | E38: =VLOOKUP(A38,R$1:U$89,3,FALSE) -> 2 | I38: Release 7 | R38: HU33 | S38: L | T38: =VLOOKUP(S38,Tallas!A$1:D$8,4,FALSE) -> 16 | U38: 37
A39: =R40 -> HU9 | B39: =VLOOKUP(A39,'Product Backlog HUs(1)'!A$1:M$99,2,FALSE) -> Consultar Información del Detalle Horario | D39: Sprint 15 | E39: =VLOOKUP(A39,R$1:U$89,3,FALSE) -> 8 | I39: Release 7 | R39: HU6 | S39: XL | T39: =VLOOKUP(S39,Tallas!A$1:D$8,4,FALSE) -> 32 | U39: 38
A40: =R41 -> HU7 | B40: =VLOOKUP(A40,'Product Backlog HUs(1)'!A$1:M$99,2,FALSE) -> Modificar Información del Detalle Horario | D40: Sprint 15 | E40: =VLOOKUP(A40,R$1:U$89,3,FALSE) -> 4 | I40: Release 7 | R40: HU9 | S40: M | T40: =VLOOKUP(S40,Tallas!A$1:D$8,4,FALSE) -> 8 | U40: 39
...

Sheet Product Backlog HUs(1)
A1: Identificador | B1: Nombre Comando/Acción | C1: Nombre Historia | D1: Nombre Historia de Usuario | E1: ¿Quién dispara o ejecuta la Historia? | F1: ¿Qué necesita poder llevar a cabo? | G1: ¿Para qué necesita llevar a cabo esa acción? | H1: Card | I1: Talla | J1: Puntos de historia de usuario | K1: ¿Definition of Ready? | L1: ¿Definition of Done? | M1: Prioridad
A2: HU1 | B2: Consultar la Información de una Categoría Motocicleta | C2: =B2 -> Consultar la Información de una Categoría Motocicleta | D2: =A2&"-"&C2 -> HU1-Consultar la Información de una Categoría Motocicleta | E2: Administrador | F2: =C2 -> Consultar la Información de una Categoría Motocicleta | G2: Poder ofrecer información base sobre las caractisticas de las mototcicletas para la gestion de los servicios ofrecidos por las sedes y hacer recomendaciones mas personalizadas a los usuarios | H2: ="Como "&E2&", necesito "&F2&", para "&G2 -> Como Administrador, necesito Consultar la Información de una Categoría Motocicleta, para Poder ofrecer información base sobre las caractisticas de las mototcicletas para la gestion de los servicios ofrecidos por las sedes y hacer recomendaciones mas personalizadas a los usuarios | I2: S | K2: SI | L2: SI | M2: 17 | Q2: Poder ofrecer información base sobre las caractisticas de las mototcicletas para la gestion de los servicios ofrecidos por las sedes y hacer recomendaciones mas personalizadas a los usuarios
A3: HU2 | B3: Registrar Información de la Calificación | C3: =B3 -> Registrar Información de la Calificación | D3: =A3&"-"&C3 -> HU2-Registrar Información de la Calificación | E3: Usuario | F3: =C3 -> Registrar Información de la Calificación | G3: =Q3 -> Poder calificar los servicios realizados a los vehiculos registrados, con el fin de que pueda contribuir a la estadistica y visualizacion de otros usuarios que quieran hacer uso de los mismos | H3: ="Como "&E3&", necesito "&F3&", para "&G3 -> Como Usuario, necesito Registrar Información de la Calificación, para Poder calificar los servicios realizados a los vehiculos registrados, con el fin de que pueda contribuir a la estadistica y visualizacion de otros usuarios que quieran hacer uso de los mismos | I3: XL | K3: SI | L3: SI | M3: 28 | Q3: Poder calificar los servicios realizados a los vehiculos registrados, con el fin de que pueda contribuir a la estadistica y visualizacion de otros usuarios que quieran hacer uso de los mismos
A4: HU3 | B4: Consultar Información de la Calificación | C4: =B4 -> Consultar Información de la Calificación | D4: =A4&"-"&C4 -> HU3-Consultar Información de la Calificación | E4: Usuario/Representante Sede | F4: =C4 -> Consultar Información de la Calificación | G4: =Q4 -> Poder gestionar los datos de los servicios ofrecidos por cada sede o franquicia con el fin de obtener restroalimentacion a través de la evaluación de los usuarios, permitiendo tomar decisiones estratégicas basadas en la experiencia real del cliente, mejorando la oferta de servicios según la demanda y evaluar aquellos que no aportan valor al negocio | H4: ="Como "&E4&", necesito "&F4&", para "&G4 -> Como Usuario/Representante Sede, necesito Consultar Información de la Calificación, para Poder gestionar los datos de los servicios ofrecidos por cada sede o franquicia con el fin de obtener restroalimentacion a través de la evaluación de los usuarios, permitiendo tomar decisiones estratégicas basadas en la experiencia real del cliente, mejorando la oferta de servicios según la demanda y evaluar aquellos que no aportan valor al negocio | I4: M | L4: SI | M4: 29 | Q4: Poder gestionar los datos de los servicios ofrecidos por cada sede o franquicia con el fin de obtener restroalimentacion a través de la evaluación de los usuarios, permitiendo tomar decisiones estratégicas basadas en la experiencia real del cliente, mejorando la oferta de servicios según la demanda y evaluar aquellos que no aportan valor al negocio
A5: HU4 | B5: Consultar Información de la Ciudad | C5: =B5 -> Consultar Información de la Ciudad | D5: =A5&"-"&C5 -> HU4-Consultar Información de la Ciudad | E5: Representante Sede | F5: =C5 -> Consultar Información de la Ciudad | G5: =Q5 -> Poder gestionar los datos relacionados con la ubicacion, los horarios y el contacto de las sedes que ofrecen los servicios,con el fin de que los usuarios finales puedan tener informacion en tiempo real de manera confiable sobre las sedes | H5: ="Como "&E5&", necesito "&F5&", para "&G5 -> Como Representante Sede, necesito Consultar Información de la Ciudad, para Poder gestionar los datos relacionados con la ubicacion, los horarios y el contacto de las sedes que ofrecen los servicios,con el fin de que los usuarios finales puedan tener informacion en tiempo real de manera confiable sobre las sedes | I5: XS | K5: SI | L5: SI | M5: 18 | Q5: Poder gestionar los datos relacionados con la ubicacion, los horarios y el contacto de las sedes que ofrecen los servicios,con el fin de que los usuarios finales puedan tener informacion en tiempo real de manera confiable sobre las sedes
A6: HU5 | B6: Consultar Información del Departamento | C6: =B6 -> Consultar Información del Departamento | D6: =A6&"-"&C6 -> HU5-Consultar Información del Departamento | E6: Representante Sede | F6: =C6 -> Consultar Información del Departamento | G6: =Q5 -> Poder gestionar los datos relacionados con la ubicacion, los horarios y el contacto de las sedes que ofrecen los servicios,con el fin de que los usuarios finales puedan tener informacion en tiempo real de manera confiable sobre las sedes | H6: ="Como "&E6&", necesito "&F6&", para "&G6 -> Como Representante Sede, necesito Consultar Información del Departamento, para Poder gestionar los datos relacionados con la ubicacion, los horarios y el contacto de las sedes que ofrecen los servicios,con el fin de que los usuarios finales puedan tener informacion en tiempo real de manera confiable sobre las sedes | I6: XS | K6: SI | L6: SI | M6: 19
A7: HU6 | B7: Registrar Información del Detalle Horario | C7: =B7 -> Registrar Información del Detalle Horario | D7: =A7&"-"&C7 -> HU6-Registrar Información del Detalle Horario | E7: Representante Sede | F7: =C7 -> Registrar Información del Detalle Horario | G7: =Q5 -> Poder gestionar los datos relacionados con la ubicacion, los horarios y el contacto de las sedes que ofrecen los servicios,con el fin de que los usuarios finales puedan tener informacion en tiempo real de manera confiable sobre las sedes | H7: ="Como "&E7&", necesito "&F7&", para "&G7 -> Como Representante Sede, necesito Registrar Información del Detalle Horario, para Poder gestionar los datos relacionados con la ubicacion, los horarios y el contacto de las sedes que ofrecen los servicios,con el fin de que los usuarios finales puedan tener informacion en tiempo real de manera confiable sobre las sedes | I7: XL | K7: SI | L7: SI | M7: 13
A8: HU7 | B8: Modificar Información del Detalle Horario | C8: =B8 -> Modificar Información del Detalle Horario | D8: =A8&"-"&C8 -> HU7-Modificar Información del Detalle Horario | E8: Representante Sede | F8: =C8 -> Modificar Información del Detalle Horario | G8: =Q5 -> Poder gestionar los datos relacionados con la ubicacion, los horarios y el contacto de las sedes que ofrecen los servicios,con el fin de que los usuarios finales puedan tener informacion en tiempo real de manera confiable sobre las sedes | H8: ="Como "&E8&", necesito "&F8&", para "&G8 -> Como Representante Sede, necesito Modificar Información del Detalle Horario, para Poder gestionar los datos relacionados con la ubicacion, los horarios y el contacto de las sedes que ofrecen los servicios,con el fin de que los usuarios finales puedan tener informacion en tiempo real de manera confiable sobre las sedes | I8: L | K8: SI | L8: SI | M8: 43
A9: HU8 | B9: Eliminar Información del Detalle Horario | C9: =B9 -> Eliminar Información del Detalle Horario | D9: =A9&"-"&C9 -> HU8-Eliminar Información del Detalle Horario | E9: Representante Sede | F9: =C9 -> Eliminar Información del Detalle Horario | G9: =Q5 -> Poder gestionar los datos relacionados con la ubicacion, los horarios y el contacto de las sedes que ofrecen los servicios,con el fin de que los usuarios finales puedan tener informacion en tiempo real de manera confiable sobre las sedes | H9: ="Como "&E9&", necesito "&F9&", para "&G9 -> Como Representante Sede, necesito Eliminar Información del Detalle Horario, para Poder gestionar los datos relacionados con la ubicacion, los horarios y el contacto de las sedes que ofrecen los servicios,con el fin de que los usuarios finales puedan tener informacion en tiempo real de manera confiable sobre las sedes | I9: L | K9: SI | L9: SI | M9: 45
A10: HU9 | B10: Consultar Información del Detalle Horario | C10: =B10 -> Consultar Información del Detalle Horario | D10: =A10&"-"&C10 -> HU9-Consultar Información del Detalle Horario | E10: Usuario/Representante Sede | F10: =C10 -> Consultar Información del Detalle Horario | G10: =Q5 -> Poder gestionar los datos relacionados con la ubicacion, los horarios y el contacto de las sedes que ofrecen los servicios,con el fin de que los usuarios finales puedan tener informacion en tiempo real de manera confiable sobre las sedes | H10: ="Como "&E10&", necesito "&F10&", para "&G10 -> Como Usuario/Representante Sede, necesito Consultar Información del Detalle Horario, para Poder gestionar los datos relacionados con la ubicacion, los horarios y el contacto de las sedes que ofrecen los servicios,con el fin de que los usuarios finales puedan tener informacion en tiempo real de manera confiable sobre las sedes | I10: S | K10: SI | L10: SI | M10: 46
A11: HU10 | B11: Consultar Información del Día | C11: =B11 -> Consultar Información del Día | D11: =A11&"-"&C11 -> HU10-Consultar Información del Día | E11: Usuario/Representante Sede | F11: =C11 -> Consultar Información del Día | G11: =Q5 -> Poder gestionar los datos relacionados con la ubicacion, los horarios y el contacto de las sedes que ofrecen los servicios,con el fin de que los usuarios finales puedan tener informacion en tiempo real de manera confiable sobre las sedes | H11: ="Como "&E11&", necesito "&F11&", para "&G11 -> Como Usuario/Representante Sede, necesito Consultar Información del Día, para Poder gestionar los datos relacionados con la ubicacion, los horarios y el contacto de las sedes que ofrecen los servicios,con el fin de que los usuarios finales puedan tener informacion en tiempo real de manera confiable sobre las sedes | I11: XS | K11: SI | L11: SI | M11: 20
