Workbook

Sheet Diagrama de clases
A2: En esta hoja se ubica la imagen del modelo, asegurando que sea clara y legible

Sheet Structs
A1: Struct | B1: Estereotipo | C1: Desripción | D1: Modificador de acceso | E1: Tipo de Clase
A2: =HYPERLINK("#'"&I2&"'!A1", I2) -> Person | B2: struct | C2: Estructura que representa a una persona registrada en el sistema (usuario, representante o administrador). Contiene información personal, credenciales y rol asignado. | D2: exported | E2: N/A | I2: Person
A3: =HYPERLINK("#'"&I3&"'!A1", I3) -> Branch | B3: struct | C3: Estructura que representa una sede (taller, tienda o taller-tienda). Contiene información del representante, franquicia, ubicación, marcas atendidas y rangos de cilindraje. | D3: exported | E3: N/A | I3: Branch
A4: =HYPERLINK("#'"&I4&"'!A1", I4) -> Franchise | B4: struct | C4: Estructura que representa una franquicia que agrupa múltiples sedes bajo una misma marca comercial. | D4: exported | E4: N/A | I4: Franchise
A5: =HYPERLINK("#'"&I5&"'!A1", I5) -> Location | B5: struct | C5: Estructura que representa la ubicación geográfica de una sede, incluyendo departamento, ciudad, dirección y coordenadas GPS. | D5: exported | E5: N/A | I5: Location
A6: =HYPERLINK("#'"&I6&"'!A1", I6) -> Motorcycle | B6: struct | C6: Estructura que representa una motocicleta registrada por un usuario. Incluye placa, referencia técnica, año, kilometraje y foto de perfil. | D6: exported | E6: N/A | I6: Motorcycle
A7: =HYPERLINK("#'"&I7&"'!A1", I7) -> MotorcycleReference | B7: struct | C7: Estructura que representa la referencia técnica de una motocicleta, incluyendo marca, modelo, categoría y cilindraje del motor. | D7: exported | E7: N/A | I7: MotorcycleReference
A8: =HYPERLINK("#'"&I8&"'!A1", I8) -> MotorcycleEvidence | B8: struct | C8: Estructura que representa una foto de evidencia de una motocicleta, categorizada por ángulo (frontal, lateral, trasera). | D8: exported | E8: N/A | I8: MotorcycleEvidence
A9: =HYPERLINK("#'"&I9&"'!A1", I9) -> Brand | B9: struct | C9: Estructura que representa una marca de motocicleta del catálogo de referencia. | D9: exported | E9: N/A | I9: Brand
A10: =HYPERLINK("#'"&I10&"'!A1", I10) -> City | B10: struct | C10: Estructura que representa una ciudad dentro del catálogo geográfico, asociada a un departamento. | D10: exported | E10: N/A | I10: City
A11: =HYPERLINK("#'"&I11&"'!A1", I11) -> Department | B11: struct | C11: Estructura que representa un departamento dentro del catálogo geográfico nacional. | D11: exported | E11: N/A | I11: Department
A12: =HYPERLINK("#'"&I12&"'!A1", I12) -> Message | B12: struct | C12: Estructura que representa un mensaje del sistema centralizado. Contiene código, tipo, categoría, módulo, título, contenido y estado de activación. | D12: exported | E12: N/A | I12: Message
A13: =HYPERLINK("#'"&I13&"'!A1", I13) -> Diagnostic | B13: struct | C13: Estructura que representa un diagnóstico solicitado para una motocicleta en una sede específica, con descripción del problema y posible solución. | D13: exported | E13: N/A | I13: Diagnostic
... A33: =HYPERLINK("#'"&I33&"'!A1", I33) -> DayOfWeek | B33: enum | C33: Enumeración que define los días de la semana: 0 (Domingo) a 6 (Sábado). | D33: exported | E33: N/A | I33: DayOfWeek

Sheet Person
A1: <-Volver al inicio
A2: =Structs!$A$1 -> Struct | B2: =Structs!I2 -> Person
A3: =Structs!$B$1 -> Estereotipo | B3: =Structs!B2 -> struct
A4: =Structs!$C$1 -> Desripción | B4: =Structs!C2 -> Estructura que representa a una persona registrada en el sistema (usuario, representante o administrador). Contiene información personal, credenciales y rol asignado.
A5: Modificador acceso: | B5: exported
A6: Tipo clase: | B6: N/A
A7: Relaciones
A8: Relación | B8: Tipo relación | E8: Estructura
A9: Necesita de | B9: Asociación | E9: =HYPERLINK("#'"&F9&"'!A1", F9) -> Role | F9: Role
A10: Es usada por | B10: Asociación | E10: =HYPERLINK("#'"&F10&"'!A1", F10) -> Branch | F10: Branch
A11: Es usada por | B11: Asociación | E11: =HYPERLINK("#'"&F11&"'!A1", F11) -> Motorcycle | F11: Motorcycle
A12: Es usada por | B12: Asociación | E12: =HYPERLINK("#'"&F12&"'!A1", F12) -> ServiceStatusHistory | F12: ServiceStatusHistory
A13: Atributos
A14: Modificador de acceso | B14: Nombre | C14: Tipo de dato | E14: Tipo modificación atributo | F14: Tipo acceso atributo | G14: Valor por defecto | J14: Descripción atributo
C15: Tipo de dato | D15: ¿Cuál?
A16: exported | B16: ID | C16: String | E16: N/A | F16: no static | G16: "" | J16: Identificador único UUID de la persona
A17: exported | B17: IdentityNumber | C17: String | E17: N/A | F17: no static | G17: "" | J17: Número de documento de identidad
A18: exported | B18: FirstName | C18: String | E18: N/A | F18: no static | G18: "" | J18: Primer nombre
A19: exported | B19: LastName | C19: String | E19: N/A | F19: no static | G19: "" | J19: Primer apellido
A20: exported | B20: SecondLastName | C20: String | E20: N/A | F20: no static | G20: "" | J20: Segundo apellido
A21: exported | B21: Email | C21: String | E21: N/A | F21: no static | G21: "" | J21: Correo electrónico
A22: exported | B22: PhoneNumber | C22: String | E22: N/A | F22: no static | G22: "" | J22: Número de teléfono
A23: exported | B23: Password | C23: String | E23: N/A | F23: no static | G23: "" | J23: Contraseña (no serializada en JSON)
A24: exported | B24: Role | C24: Otro | D24: Role | E24: N/A | F24: no static | G24: "" | J24: Rol asignado (USER, REPRESENTATIVE, ADMIN)
A25: exported | B25: KeycloakUserID | C25: String | E25: N/A | F25: no static | G25: "" | J25: ID del usuario en Keycloak
A26: Constructores
A27: Modificador de acceso | B27: Nombre | C27: Tipo constructor | D27: Descripción | E27: Parámetros | M27: Excepciones
E28: Nombre | F28: Tipo de dato | G28: ¿Cuál? | H28: Tipo parámetro | I28: Tipo modificación atributo | J28: Descripción
A29: N/A | B29: Person | C29: Defecto (zero value) | D29: Inicialización por zero value de Go. Todos los campos toman su valor por defecto.
A30: exported | B30: SetID | C30: Inyección | D30: Genera y asigna un UUID al campo ID | H30: N/A | I30: N/A | J30: Identificador único UUID de la persona
A31: Métodos accesores
A32: Modificador de acceso | B32: Nombre | C32: Tipo método accesor | D32: Tipo modificación método | E32: Descripción | F32: Parámetros | L32: Tipo dato de retorno | N32: Excepciones
F33: Nombre | G33: Tipo de dato | H33: ¿Cuál? | I33: Tipo parámetro | J33: Tipo modificación atributo | K33: Descripción | L33: Tipo de dato | M33: ¿Cuál?
A34: N/A | B34: N/A | C34: N/A | D34: N/A | E34: En Go los campos exported se acceden directamente (ej: struct.Campo)
A35: Métodos
A36: Modificador de acceso | B36: Nombre | C36: Tipo acceso método | D36: Tipo modificación método | E36: Descripción | F36: Parámetros | L36: Tipo dato de retorno | N36: Excepciones
F37: Nombre | G37: Tipo de dato | H37: ¿Cuál? | I37: Tipo parámetro | J37: Tipo modificación atributo | K37: Descripción | L37: Tipo de dato | M37: ¿Cuál?
A38: N/A | B38: N/A | D38: N/A | E38: N/A | J38: N/A | K38: N/A

Sheet Branch
A1: <-Volver al inicio
A2: =Structs!$A$1 -> Struct | B2: =Structs!I3 -> Branch
A3: =Structs!$B$1 -> Estereotipo | B3: =Structs!B3 -> struct
A4: =Structs!$C$1 -> Desripción | B4: =Structs!C3 -> Estructura que representa una sede (taller, tienda o taller-tienda). Contiene información del representante, franquicia, ubicación, marcas atendidas y rangos de cilindraje.
A5: Modificador acceso: | B5: exported
A6: Tipo clase: | B6: N/A
A7: Relaciones
A8: Relación | B8: Tipo relación | E8: Estructura
A9: Necesita de | B9: Asociación | E9: =HYPERLINK("#'"&F9&"'!A1", F9) -> Person | F9: Person
A10: Necesita de | B10: Asociación | E10: =HYPERLINK("#'"&F10&"'!A1", F10) -> EstablishmentType | F10: EstablishmentType
A11: Necesita de | B11: Asociación | E11: =HYPERLINK("#'"&F11&"'!A1", F11) -> BranchStatus | F11: BranchStatus
A12: Necesita de | B12: Composición | E12: =HYPERLINK("#'"&F12&"'!A1", F12) -> Location | F12: Location
A13: Necesita de | B13: Asociación | E13: =HYPERLINK("#'"&F13&"'!A1", F13) -> DisplacementRange | F13: DisplacementRange
A14: Es usada por | B14: Asociación | E14: =HYPERLINK("#'"&F14&"'!A1", F14) -> Franchise | F14: Franchise
A15: Es usada por | B15: Asociación | E15: =HYPERLINK("#'"&F15&"'!A1", F15) -> BranchSchedule | F15: BranchSchedule
A16: Es usada por | B16: Asociación | E16: =HYPERLINK("#'"&F16&"'!A1", F16) -> Diagnostic | F16: Diagnostic
A17: Es usada por | B17: Asociación | E17: =HYPERLINK("#'"&F17&"'!A1", F17) -> CompletedService | F17: CompletedService
A18: Es usada por | B18: Asociación | E18: =HYPERLINK("#'"&F18&"'!A1", F18) -> BranchServiceInfo | F18: BranchServiceInfo
A19: Es usada por | B19: Asociación | E19: =HYPERLINK("#'"&F19&"'!A1", F19) -> DiagnosticPermission | F19: DiagnosticPermission
A20: Atributos
A21: Modificador de acceso | B21: Nombre | C21: Tipo de dato | E21: Tipo modificación atributo | F21: Tipo acceso atributo | G21: Valor por defecto | J21: Descripción atributo
C22: Tipo de dato | D22: ¿Cuál?
A23: exported | B23: ID | C23: string | E23: N/A | F23: no static | G23: "" | J23: Identificador único UUID de la sede
A24: exported | B24: RepresentativeID | C24: string | E24: N/A | F24: no static | G24: "" | J24: FK al representante (Person)
A25: exported | B25: RepresentativePhone | C25: string | E25: N/A | F25: no static | G25: nil | J25: Teléfono del representante (desde JOIN)
A26: exported | B26: FranchiseID | C26: string | E26: N/A | F26: no static | G26: nil | J26: FK a la franquicia (opcional)
A27: exported | B27: Name | C27: string | E27: N/A | F27: no static | G27: "" | J27: Nombre de la sede
A28: exported | B28: EstablishmentType | C28: Otro | D28: EstablishmentType | E28: N/A | F28: no static | G28: "" | J28: Tipo de establecimiento
A29: exported | B29: ProfileImageURL | C29: string | E29: N/A | F29: no static | G29: nil | J29: URL de imagen de perfil
A30: exported | B30: Status | C30: Otro | D30: BranchStatus | E30: N/A | F30: no static | G30: "" | J30: Estado de la sede (ACTIVE/INACTIVE)
A31: exported | B31: Location | C31: Otro | D31: *Location | E31: N/A | F31: no static | G31: nil | J31: Ubicación geográfica
A32: exported | B32: Brands | C32: string | E32: N/A | F32: no static | G32: nil | J32: Marcas de motocicleta atendidas
A33: exported | B33: DisplacementRanges | C33: Otro | D33: []DisplacementRange | E33: N/A | F33: no static | G33: nil | J33: Rangos de cilindraje atendidos
A34: Constructores
A35: Modificador de acceso | B35: Nombre | C35: Tipo constructor | D35: Descripción | E35: Parámetros | M35: Excepciones
E36: Nombre | F36: Tipo de dato | G36: ¿Cuál? | H36: Tipo parámetro | I36: Tipo modificación atributo | J36: Descripción
A37: N/A | B37: =B2 -> Branch | C37: Defecto (zero value) | D37: Inicialización por zero value de Go. Todos los campos toman su valor por defecto.
A38: exported | B38: SetID | C38: Inyección | D38: Genera y asigna un UUID al campo ID | H38: N/A | I38: N/A | J38: Identificador único UUID de la sede
A39: Métodos accesores
A40: Modificador de acceso | B40: Nombre | C40: Tipo método accesor | D40: Tipo modificación método | E40: Descripción | F40: Parámetros | L40: Tipo dato de retorno | N40: Excepciones
...

Sheet Franchise
A1: <-Volver al inicio
A2: =Structs!$A$1 -> Struct | B2: =Structs!I4 -> Franchise
A3: =Structs!$B$1 -> Estereotipo | B3: =Structs!B4 -> struct
A4: =Structs!$C$1 -> Desripción | B4: =Structs!C4 -> Estructura que representa una franquicia que agrupa múltiples sedes bajo una misma marca comercial.
A5: Modificador acceso: | B5: exported
A6: Tipo clase: | B6: N/A
A7: Relaciones
A8: Relación | B8: Tipo relación | E8: Estructura
A9: Necesita de | B9: Asociación | E9: =HYPERLINK("#'"&F9&"'!A1", F9) -> Branch | F9: Branch
A10: Atributos
A11: Modificador de acceso | B11: Nombre | C11: Tipo de dato | E11: Tipo modificación atributo | F11: Tipo acceso atributo | G11: Valor por defecto | J11: Descripción atributo
C12: Tipo de dato | D12: ¿Cuál?
A13: exported | B13: ID | C13: string | E13: N/A | F13: no static | G13: "" | J13: Identificador único UUID
A14: exported | B14: Name | C14: string | E14: N/A | F14: no static | G14: "" | J14: Nombre de la franquicia
A15: exported | B15: Description | C15: string | E15: N/A | F15: no static | G15: nil | J15: Descripción opcional
A16: exported | B16: Branches | C16: Otro | D16: []Branch | E16: N/A | F16: no static | G16: nil | J16: Lista de sedes asociadas
A17: Constructores
A18: Modificador de acceso | B18: Nombre | C18: Tipo constructor | D18: Descripción | E18: Parámetros | M18: Excepciones
E19: Nombre | F19: Tipo de dato | G19: ¿Cuál? | H19: Tipo parámetro | I19: Tipo modificación atributo | J19: Descripción
A20: N/A | B20: =B2 -> Franchise | C20: Defecto (zero value) | D20: Inicialización por zero value de Go. Todos los campos toman su valor por defecto.
A21: exported | B21: SetID | C21: Inyección | D21: Genera y asigna un UUID al campo ID | H21: N/A | I21: N/A | J21: Identificador único UUID
A22: Métodos accesores
A23: Modificador de acceso | B23: Nombre | C23: Tipo método accesor | D23: Tipo modificación método | E23: Descripción | F23: Parámetros | L23: Tipo dato de retorno | N23: Excepciones
F24: Nombre | G24: Tipo de dato | H24: ¿Cuál? | I24: Tipo parámetro | J24: Tipo modificación atributo | K24: Descripción | L24: Tipo de dato | M24: ¿Cuál?
A25: N/A | B25: N/A | C25: N/A | D25: N/A | E25: En Go los campos exported se acceden directamente (ej: struct.Campo)
A26: Métodos
A27: Modificador de acceso | B27: Nombre | C27: Tipo acceso método | D27: Tipo modificación método | E27: Descripción | F27: Parámetros | L27: Tipo dato de retorno | N27: Excepciones
F28: Nombre | G28: Tipo de dato | H28: ¿Cuál? | I28: Tipo parámetro | J28: Tipo modificación atributo | K28: Descripción | L28: Tipo de dato | M28: ¿Cuál?
A29: exported | B29: SetID | C29: no static | D29: N/A | E29: Genera y asigna un UUID al campo ID | I29: N/A | J29: N/A | L29: void
A30: exported | B30: ToLogger | C30: no static | D30: N/A | E30: Retorna representación para logging | I30: N/A | J30: N/A | L30: String

Sheet Location
A1: <-Volver al inicio
A2: =Structs!$A$1 -> Struct | B2: =Structs!I5 -> Location
A3: =Structs!$B$1 -> Estereotipo | B3: =Structs!B5 -> struct
A4: =Structs!$C$1 -> Desripción | B4: =Structs!C5 -> Estructura que representa la ubicación geográfica de una sede, incluyendo departamento, ciudad, dirección y coordenadas GPS.
A5: Modificador acceso: | B5: exported
A6: Tipo clase: | B6: N/A
A7: Relaciones
A8: Relación | B8: Tipo relación | E8: Estructura
A9: Necesita de | B9: Asociación | E9: =HYPERLINK("#'"&F9&"'!A1", F9) -> Branch | F9: Branch
A10: Necesita de | B10: Asociación | E10: =HYPERLINK("#'"&F10&"'!A1", F10) -> City | F10: City
A11: Necesita de | B11: Asociación | E11: =HYPERLINK("#'"&F11&"'!A1", F11) -> Department | F11: Department
A12: Atributos
A13: Modificador de acceso | B13: Nombre | C13: Tipo de dato | E13: Tipo modificación atributo | F13: Tipo acceso atributo | G13: Valor por defecto | J13: Descripción atributo
C14: Tipo de dato | D14: ¿Cuál?
A15: exported | B15: ID | C15: string | E15: N/A | F15: no static | G15: "" | J15: Identificador único UUID
A16: exported | B16: BranchID | C16: string | E16: N/A | F16: no static | G16: "" | J16: FK a la sede
A17: exported | B17: DepartmentID | C17: string | E17: N/A | F17: no static | G17: "" | J17: FK al departamento
A18: exported | B18: CityID | C18: string | E18: N/A | F18: no static | G18: "" | J18: FK a la ciudad
A19: exported | B19: Address | C19: string | E19: N/A | F19: no static | G19: "" | J19: Dirección completa
A20: exported | B20: Latitude | C20: float/Float | D20: EstablishmentType | E20: N/A | F20: no static | G20: nil | J20: Latitud GPS (opcional)
A21: exported | B21: Longitude | C21: float/Float | E21: N/A | F21: no static | G21: nil | J21: Longitud GPS (opcional)
A22: exported | B22: CityName | C22: Otro | D22: BranchStatus | E22: N/A | F22: no static | G22: "" | J22: Nombre de la ciudad (denormalizado)
A23: exported | B23: DepartmentName | C23: Otro | D23: *Location | E23: N/A | F23: no static | G23: "" | J23: Nombre del departamento (denormalizado)
A24: Constructores
A25: Modificador de acceso | B25: Nombre | C25: Tipo constructor | D25: Descripción | E25: Parámetros | M25: Excepciones
E26: Nombre | F26: Tipo de dato | G26: ¿Cuál? | H26: Tipo parámetro | I26: Tipo modificación atributo | J26: Descripción
A27: N/A | B27: =B2 -> Location | C27: Defecto (zero value) | D27: Inicialización por zero value de Go. Todos los campos toman su valor por defecto.
A28: Métodos accesores
A29: Modificador de acceso | B29: Nombre | C29: Tipo método accesor | D29: Tipo modificación método | E29: Descripción | F29: Parámetros | L29: Tipo dato de retorno | N29: Excepciones
F30: Nombre | G30: Tipo de dato | H30: ¿Cuál? | I30: Tipo parámetro | J30: Tipo modificación atributo | K30: Descripción | L30: Tipo de dato | M30: ¿Cuál?
A31: N/A | B31: N/A | C31: N/A | D31: N/A | E31: En Go los campos exported se acceden directamente (ej: struct.Campo)
A32: Métodos
A33: Modificador de acceso | B33: Nombre | C33: Tipo acceso método | D33: Tipo modificación método | E33: Descripción | F33: Parámetros | L33: Tipo dato de retorno | N33: Excepciones
F34: Nombre | G34: Tipo de dato | H34: ¿Cuál? | I34: Tipo parámetro | J34: Tipo modificación atributo | K34: Descripción | L34: Tipo de dato | M34: ¿Cuál?
A35: N/A | B35: N/A | D35: N/A | E35: N/A | I35: N/A | J35: N/A | N35: N/A

Sheet Motorcycle
A1: <-Volver al inicio
A2: =Structs!$A$1 -> Struct | B2: =Structs!I6 -> Motorcycle
A3: =Structs!$B$1 -> Estereotipo | B3: =Structs!B6 -> struct
A4: =Structs!$C$1 -> Desripción | B4: =Structs!C6 -> Estructura que representa una motocicleta registrada por un usuario. Incluye placa, referencia técnica, año, kilometraje y foto de perfil.
A5: Modificador acceso: | B5: exported
A6: Tipo clase: | B6: N/A
A7: Relaciones
A8: Relación | B8: Tipo relación | E8: Estructura
A9: Necesita de | B9: Asociación | E9: =HYPERLINK("#'"&F9&"'!A1", F9) -> Person | F9: Person
A10: Necesita de | B10: Composición | E10: =HYPERLINK("#'"&F10&"'!A1", F10) -> MotorcycleReference | F10: MotorcycleReference
A11: Es usada por | B11: Asociación | E11: =HYPERLINK("#'"&F11&"'!A1", F11) -> MotorcycleEvidence | F11: MotorcycleEvidence
A12: Es usada por | B12: Asociación | E12: =HYPERLINK("#'"&F12&"'!A1", F12) -> Diagnostic | F12: Diagnostic
A13: Es usada por | B13: Asociación | E13: =HYPERLINK("#'"&F13&"'!A1", F13) -> CompletedService | F13: CompletedService
A14: Es usada por | B14: Asociación | E14: =HYPERLINK("#'"&F14&"'!A1", F14) -> DiagnosticPermission | F14: DiagnosticPermission
A15: Atributos
A16: Modificador de acceso | B16: Nombre | C16: Tipo de dato | E16: Tipo modificación atributo | F16: Tipo acceso atributo | G16: Valor por defecto | J16: Descripción atributo
C17: Tipo de dato | D17: ¿Cuál?
A18: exported | B18: ID | C18: string | E18: N/A | F18: no static | G18: "" | J18: Identificador único UUID
A19: exported | B19: LicensePlate | C19: string | E19: N/A | F19: no static | G19: "" | J19: Placa única de la motocicleta
A20: exported | B20: ReferenceID | C20: string | E20: N/A | F20: no static | G20: "" | J20: FK a la referencia del catálogo
A21: exported | B21: OwnerID | C21: string | E21: N/A | F21: no static | G21: "" | J21: FK al dueño (Person con rol USER)
A22: exported | B22: Year | C22: int/Integer | E22: N/A | F22: no static | G22: nil | J22: Año de la motocicleta (opcional)
A23: exported | B23: CurrentMileage | C23: int/Integer | E23: N/A | F23: no static | G23: nil | J23: Kilometraje actual (opcional)
A24: exported | B24: OwnerNotes | C24: string | E24: N/A | F24: no static | G24: nil | J24: Notas del dueño (opcional)
A25: exported | B25: ProfileImageURL | C25: String | E25: N/A | F25: no static | G25: nil | J25: URL de foto de perfil (Firebase Storage)
A26: exported | B26: Reference | C26: Otro | D26: *MotorcycleReference | E26: N/A | F26: no static | G26: nil | J26: Referencia técnica (poblada en lectura)
A27: Constructores
A28: Modificador de acceso | B28: Nombre | C28: Tipo constructor | D28: Descripción | E28: Parámetros | M28: Excepciones
E29: Nombre | F29: Tipo de dato | G29: ¿Cuál? | H29: Tipo parámetro | I29: Tipo modificación atributo | J29: Descripción
A30: N/A | B30: Motorcycle | C30: Defecto (zero value) | D30: Inicialización por zero value de Go. Todos los campos toman su valor por defecto.
A31: exported | B31: SetID | C31: Inyección | D31: Genera y asigna un UUID al campo ID | H31: N/A | I31: N/A | J31: Identificador único UUID
A32: Métodos accesores
A33: Modificador de acceso | B33: Nombre | C33: Tipo método accesor | D33: Tipo modificación método | E33: Descripción | F33: Parámetros | L33: Tipo dato de retorno | N33: Excepciones
F34: Nombre | G34: Tipo de dato | H34: ¿Cuál? | I34: Tipo parámetro | J34: Tipo modificación atributo | K34: Descripción | L34: Tipo de dato | M34: ¿Cuál?
A35: N/A | B35: N/A | C35: N/A | D35: N/A | E35: En Go los campos exported se acceden directamente (ej: struct.Campo)
A36: Métodos
A37: Modificador de acceso | B37: Nombre | C37: Tipo acceso método | D37: Tipo modificación método | E37: Descripción | F37: Parámetros | L37: Tipo dato de retorno | N37: Excepciones
F38: Nombre | G38: Tipo de dato | H38: ¿Cuál? | I38: Tipo parámetro | J38: Tipo modificación atributo | K38: Descripción | L38: Tipo de dato | M38: ¿Cuál?
A39: exported | B39: SetID | C39: no static | D39: N/A | E39: Genera y asigna un UUID al campo ID | I39: N/A | J39: N/A | L39: void

Sheet MotorcycleReference
A1: <-Volver al inicio
A2: =Structs!$A$1 -> Struct | B2: =Structs!I7 -> MotorcycleReference
A3: =Structs!$B$1 -> Estereotipo | B3: =Structs!B7 -> struct
A4: =Structs!$C$1 -> Desripción | B4: =Structs!C7 -> Estructura que representa la referencia técnica de una motocicleta, incluyendo marca, modelo, categoría y cilindraje del motor.
A5: Modificador acceso: | B5: exported
A6: Tipo clase: | B6: N/A
A7: Relaciones
A8: Relación | B8: Tipo relación | E8: Estructura
A9: Necesita de | B9: Asociación | E9: =HYPERLINK("#'"&F9&"'!A1", F9) -> Brand | F9: Brand
A10: Necesita de | B10: Composición | E10: =HYPERLINK("#'"&F10&"'!A1", F10) -> Motorcycle | F10: Motorcycle
A11: Atributos
A12: Modificador de acceso | B12: Nombre | C12: Tipo de dato | E12: Tipo modificación atributo | F12: Tipo acceso atributo | G12: Valor por defecto | J12: Descripción atributo
C13: Tipo de dato | D13: ¿Cuál?
A14: exported | B14: ID | C14: string | E14: N/A | F14: no static | G14: "" | J14: Identificador único UUID
A15: exported | B15: BrandID | C15: string | E15: N/A | F15: no static | G15: "" | J15: FK a la marca del catálogo
A16: exported | B16: BrandName | C16: string | E16: N/A | F16: no static | G16: "" | J16: Nombre de la marca (denormalizado)
A17: exported | B17: Model | C17: string | E17: N/A | F17: no static | G17: "" | J17: Nombre del modelo (ej: CB 190R)
A18: exported | B18: Category | C18: String | E18: N/A | F18: no static | G18: nil | J18: Categoría (Sport, Scooter, etc.)
A19: exported | B19: EngineDisplacement | C19: int/Integer | E19: N/A | F19: no static | G19: 0 | J19: Cilindraje del motor en cc
A20: Constructores
A21: Modificador de acceso | B21: Nombre | C21: Tipo constructor | D21: Descripción | E21: Parámetros | M21: Excepciones
E22: Nombre | F22: Tipo de dato | G22: ¿Cuál? | H22: Tipo parámetro | I22: Tipo modificación atributo | J22: Descripción
A23: N/A | B23: =B2 -> MotorcycleReference | C23: Defecto (zero value) | D23: Inicialización por zero value de Go. Todos los campos toman su valor por defecto.
A24: Métodos accesores
A25: Modificador de acceso | B25: Nombre | C25: Tipo método accesor | D25: Tipo modificación método | E25: Descripción | F25: Parámetros | L25: Tipo dato de retorno | N25: Excepciones
F26: Nombre | G26: Tipo de dato | H26: ¿Cuál? | I26: Tipo parámetro | J26: Tipo modificación atributo | K26: Descripción | L26: Tipo de dato | M26: ¿Cuál?
A27: N/A | B27: N/A | C27: N/A | D27: N/A | E27: En Go los campos exported se acceden directamente (ej: struct.Campo)
A28: Métodos
A29: Modificador de acceso | B29: Nombre | C29: Tipo acceso método | D29: Tipo modificación método | E29: Descripción | F29: Parámetros | L29: Tipo dato de retorno | N29: Excepciones
F30: Nombre | G30: Tipo de dato | H30: ¿Cuál? | I30: Tipo parámetro | J30: Tipo modificación atributo | K30: Descripción | L30: Tipo de dato | M30: ¿Cuál?
A31: N/A | B31: N/A | C31: N/A | D31: N/A | E31: N/A | F31: N/A | G31: N/A | H31: N/A | I31: N/A | J31: N/A | K31: N/A | L31: N/A | M31: N/A | N31: N/A

Sheet MotorcycleEvidence
A1: <-Volver al inicio
A2: =Structs!$A$1 -> Struct | B2: =Structs!I8 -> MotorcycleEvidence
A3: =Structs!$B$1 -> Estereotipo | B3: =Structs!B8 -> struct
A4: =Structs!$C$1 -> Desripción | B4: =Structs!C8 -> Estructura que representa una foto de evidencia de una motocicleta, categorizada por ángulo (frontal, lateral, trasera).
A5: Modificador acceso: | B5: exported
A6: Tipo clase: | B6: N/A
A7: Relaciones
A8: Relación | B8: Tipo relación | E8: Estructura
A9: Necesita de | B9: Asociación | E9: =HYPERLINK("#'"&F9&"'!A1", F9) -> Motorcycle | F9: Motorcycle
A10: Necesita de | B10: Asociación | E10: =HYPERLINK("#'"&F10&"'!A1", F10) -> EvidenceAngle | F10: EvidenceAngle
A11: Atributos
A12: Modificador de acceso | B12: Nombre | C12: Tipo de dato | E12: Tipo modificación atributo | F12: Tipo acceso atributo | G12: Valor por defecto | J12: Descripción atributo
C13: Tipo de dato | D13: ¿Cuál?
A14: exported | B14: ID | C14: string | E14: N/A | F14: no static | G14: "" | J14: Identificador único UUID
A15: exported | B15: MotorcycleID | C15: string | E15: N/A | F15: no static | G15: "" | J15: FK a la motocicleta
A16: exported | B16: Angle | C16: Otro | D16: *EvidenceAngle | E16: N/A | F16: no static | G16: nil | J16: Ángulo de la foto (FRONTAL, LATERAL, REAR)
A17: exported | B17: ImageURL | C17: string | E17: N/A | F17: no static | G17: "" | J17: URL de la imagen (Firebase Storage)
A18: exported | B18: Description | C18: String | E18: N/A | F18: no static | G18: nil | J18: Descripción opcional
A19: exported | B19: CreatedAt | C19: Otro | D19: time.Time | E19: N/A | F19: no static | G19: "" | J19: Fecha de subida
A20: Constructores
A21: Modificador de acceso | B21: Nombre | C21: Tipo constructor | D21: Descripción | E21: Parámetros | M21: Excepciones
E22: Nombre | F22: Tipo de dato | G22: ¿Cuál? | H22: Tipo parámetro | I22: Tipo modificación atributo | J22: Descripción
A23: N/A | B23: MotorcycleEvidence | C23: Defecto (zero value) | D23: Inicialización por zero value de Go. Todos los campos toman su valor por defecto.
A24: exported | B24: SetID | C24: Inyección | D24: Genera y asigna un UUID al campo ID | G24: N/A | H24: N/A | I24: N/A | J24: Identificador único UUID
A25: Métodos accesores
A26: Modificador de acceso | B26: Nombre | C26: Tipo método accesor | D26: Tipo modificación método | E26: Descripción | F26: Parámetros | L26: Tipo dato de retorno | N26: Excepciones
F27: Nombre | G27: Tipo de dato | H27: ¿Cuál? | I27: Tipo parámetro | J27: Tipo modificación atributo | K27: Descripción | L27: Tipo de dato | M27: ¿Cuál?
A28: N/A | B28: N/A | C28: N/A | D28: N/A | E28: En Go los campos exported se acceden directamente (ej: struct.Campo)
A29: Métodos
A30: Modificador de acceso | B30: Nombre | C30: Tipo acceso método | D30: Tipo modificación método | E30: Descripción | F30: Parámetros | L30: Tipo dato de retorno | N30: Excepciones
F31: Nombre | G31: Tipo de dato | H31: ¿Cuál? | I31: Tipo parámetro | J31: Tipo modificación atributo | K31: Descripción | L31: Tipo de dato | M31: ¿Cuál?
A32: exported | B32: SetID | C32: no static | D32: N/A | E32: Genera y asigna un UUID al campo ID | I32: N/A | J32: N/A | L32: void | M32: N/A | N32: N/A

Sheet Brand
A1: <-Volver al inicio
A2: =Structs!$A$1 -> Struct | B2: =Structs!I9 -> Brand
A3: =Structs!$B$1 -> Estereotipo | B3: =Structs!B9 -> struct
A4: =Structs!$C$1 -> Desripción | B4: =Structs!C9 -> Estructura que representa una marca de motocicleta del catálogo de referencia.
A5: Modificador acceso: | B5: exported
A6: Tipo clase: | B6: N/A
A7: Relaciones
A8: Relación | B8: Tipo relación | E8: Estructura
A9: Es usada por | B9: Asociación | E9: =HYPERLINK("#'"&F9&"'!A1", F9) -> MotorcycleReference | F9: MotorcycleReference
A10: Es usada por | B10: Asociación | E10: =HYPERLINK("#'"&F10&"'!A1", F10) -> Branch | F10: Branch
A11: Atributos
A12: Modificador de acceso | B12: Nombre | C12: Tipo de dato | E12: Tipo modificación atributo | F12: Tipo acceso atributo | G12: Valor por defecto | J12: Descripción atributo
C13: Tipo de dato | D13: ¿Cuál?
A14: exported | B14: ID | C14: string | E14: N/A | F14: no static | G14: "" | J14: Identificador único UUID
A15: exported | B15: Name | C15: string | E15: N/A | F15: no static | G15: "" | J15: Nombre de la marca
A16: Constructores
A17: Modificador de acceso | B17: Nombre | C17: Tipo constructor | D17: Descripción | E17: Parámetros | M17: Excepciones
E18: Nombre | F18: Tipo de dato | G18: ¿Cuál? | H18: Tipo parámetro | I18: Tipo modificación atributo | J18: Descripción
A19: N/A | B19: MotorcycleEvidence | C19: Defecto (zero value) | D19: Inicialización por zero value de Go. Todos los campos toman su valor por defecto.
A20: exported | B20: SetID | C20: Inyección | D20: Genera y asigna un UUID al campo ID | G20: N/A | H20: N/A | I20: N/A | J20: Identificador único UUID
A21: Métodos accesores
A22: Modificador de acceso | B22: Nombre | C22: Tipo método accesor | D22: Tipo modificación método | E22: Descripción | F22: Parámetros | L22: Tipo dato de retorno | N22: Excepciones
F23: Nombre | G23: Tipo de dato | H23: ¿Cuál? | I23: Tipo parámetro | J23: Tipo modificación atributo | K23: Descripción | L23: Tipo de dato | M23: ¿Cuál?
A24: N/A | B24: N/A | C24: N/A | D24: N/A | E24: En Go los campos exported se acceden directamente (ej: struct.Campo)
A25: Métodos
A26: Modificador de acceso | B26: Nombre | C26: Tipo acceso método | D26: Tipo modificación método | E26: Descripción | F26: Parámetros | L26: Tipo dato de retorno | N26: Excepciones
F27: Nombre | G27: Tipo de dato | H27: ¿Cuál? | I27: Tipo parámetro | J27: Tipo modificación atributo | K27: Descripción | L27: Tipo de dato | M27: ¿Cuál?
A28: N/A | B28: N/A | C28: N/A | D28: N/A | E28: N/A | F28: N/A | G28: N/A | H28: N/A | I28: N/A | J28: N/A | K28: N/A | L28: N/A | M28: N/A | N28: N/A

Sheet City
A1: <-Volver al inicio
A2: =Structs!$A$1 -> Struct | B2: =Structs!I10 -> City
A3: =Structs!$B$1 -> Estereotipo | B3: =Structs!B10 -> struct
A4: =Structs!$C$1 -> Desripción | B4: =Structs!C10 -> Estructura que representa una ciudad dentro del catálogo geográfico, asociada a un departamento.
A5: Modificador acceso: | B5: exported
A6: Tipo clase: | B6: N/A
A7: Relaciones
A8: Relación | B8: Tipo relación | E8: Estructura
A9: Necesita de | B9: Asociación | E9: =HYPERLINK("#'"&F9&"'!A1", F9) -> Department | F9: Department
A10: Es usada por | B10: Asociación | E10: =HYPERLINK("#'"&F10&"'!A1", F10) -> Location | F10: Location
A11: Atributos
A12: Modificador de acceso | B12: Nombre | C12: Tipo de dato | E12: Tipo modificación atributo | F12: Tipo acceso atributo | G12: Valor por defecto | J12: Descripción atributo
C13: Tipo de dato | D13: ¿Cuál?
A14: exported | B14: ID | C14: string | E14: N/A | F14: no static | G14: "" | J14: Identificador único UUID
A15: exported | B15: Name | C15: string | E15: N/A | F15: no static | G15: "" | J15: Nombre de la ciudad
A16: exported | B16: DepartmentID | C16: string | E16: N/A | F16: no static | G16: "" | J16: FK al departamento
A17: Constructores
A18: Modificador de acceso | B18: Nombre | C18: Tipo constructor | D18: Descripción | E18: Parámetros | M18: Excepciones
E19: Nombre | F19: Tipo de dato | G19: ¿Cuál? | H19: Tipo parámetro | I19: Tipo modificación atributo | J19: Descripción
A20: N/A | B20: =B2 -> City | C20: Defecto (zero value) | D20: Inicialización por zero value de Go. Todos los campos toman su valor por defecto.
A21: Métodos accesores
A22: Modificador de acceso | B22: Nombre | C22: Tipo método accesor | D22: Tipo modificación método | E22: Descripción | F22: Parámetros | L22: Tipo dato de retorno | N22: Excepciones
F23: Nombre | G23: Tipo de dato | H23: ¿Cuál? | I23: Tipo parámetro | J23: Tipo modificación atributo | K23: Descripción | L23: Tipo de dato | M23: ¿Cuál?
A24: N/A | B24: N/A | C24: N/A | D24: N/A | E24: En Go los campos exported se acceden directamente (ej: struct.Campo)
A25: Métodos
A26: Modificador de acceso | B26: Nombre | C26: Tipo acceso método | D26: Tipo modificación método | E26: Descripción | F26: Parámetros | L26: Tipo dato de retorno | N26: Excepciones
F27: Nombre | G27: Tipo de dato | H27: ¿Cuál? | I27: Tipo parámetro | J27: Tipo modificación atributo | K27: Descripción | L27: Tipo de dato | M27: ¿Cuál?
A28: N/A | B28: N/A | D28: N/A | E28: N/A | I28: N/A | J28: N/A | N28: N/A

Sheet Department
A1: <-Volver al inicio
A2: =Structs!$A$1 -> Struct | B2: =Structs!I11 -> Department
A3: =Structs!$B$1 -> Estereotipo | B3: =Structs!B11 -> struct
A4: =Structs!$C$1 -> Desripción | B4: =Structs!C11 -> Estructura que representa un departamento dentro del catálogo geográfico nacional.
A5: Modificador acceso: | B5: exported
A6: Tipo clase: | B6: N/A
A7: Relaciones
A8: Relación | B8: Tipo relación | E8: Estructura
A9: Es usada por | B9: Asociación | E9: =HYPERLINK("#'"&F9&"'!A1", F9) -> City | F9: City
A10: Es usada por | B10: Asociación | E10: =HYPERLINK("#'"&F10&"'!A1", F10) -> Location | F10: Location
A11: Atributos
A12: Modificador de acceso | B12: Nombre | C12: Tipo de dato | E12: Tipo modificación atributo | F12: Tipo acceso atributo | G12: Valor por defecto | J12: Descripción atributo
C13: Tipo de dato | D13: ¿Cuál?
A14: exported | B14: ID | C14: string | E14: N/A | F14: no static | G14: "" | J14: Identificador único UUID
A15: exported | B15: Name | C15: string | E15: N/A | F15: no static | G15: "" | J15: Nombre de la ciudad
A16: Constructores
A17: Modificador de acceso | B17: Nombre | C17: Tipo constructor | D17: Descripción | E17: Parámetros | M17: Excepciones
E18: Nombre | F18: Tipo de dato | G18: ¿Cuál? | H18: Tipo parámetro | I18: Tipo modificación atributo | J18: Descripción
A19: N/A | B19: =B2 -> Department | C19: Defecto (zero value) | D19: Inicialización por zero value de Go. Todos los campos toman su valor por defecto.
A20: Métodos accesores
A21: Modificador de acceso | B21: Nombre | C21: Tipo método accesor | D21: Tipo modificación método | E21: Descripción | F21: Parámetros | L21: Tipo dato de retorno | N21: Excepciones
F22: Nombre | G22: Tipo de dato | H22: ¿Cuál? | I22: Tipo parámetro | J22: Tipo modificación atributo | K22: Descripción | L22: Tipo de dato | M22: ¿Cuál?
A23: N/A | B23: N/A | C23: N/A | D23: N/A | E23: En Go los campos exported se acceden directamente (ej: struct.Campo)
A24: Métodos
A25: Modificador de acceso | B25: Nombre | C25: Tipo acceso método | D25: Tipo modificación método | E25: Descripción | F25: Parámetros | L25: Tipo dato de retorno | N25: Excepciones
F26: Nombre | G26: Tipo de dato | H26: ¿Cuál? | I26: Tipo parámetro | J26: Tipo modificación atributo | K26: Descripción | L26: Tipo de dato | M26: ¿Cuál?
A27: N/A | B27: N/A | D27: N/A | E27: N/A | I27: N/A | J27: N/A | N27: N/A

Sheet Message
A1: <-Volver al inicio
A2: =Structs!$A$1 -> Struct | B2: =Structs!I12 -> Message
A3: =Structs!$B$1 -> Estereotipo | B3: =Structs!B12 -> struct
A4: =Structs!$C$1 -> Desripción | B4: =Structs!C12 -> Estructura que representa un mensaje del sistema centralizado. Contiene código, tipo, categoría, módulo, título, contenido y estado de activación.
A5: Modificador acceso: | B5: exported
A6: Tipo clase: | B6: N/A
A7: Relaciones
A8: Relación | B8: Tipo relación | E8: Estructura
A9: Necesita de | B9: Asociación | E9: =HYPERLINK("#'"&F9&"'!A1", F9) -> MessageType | F9: MessageType
A10: Atributos
A11: Modificador de acceso | B11: Nombre | C11: Tipo de dato | E11: Tipo modificación atributo | F11: Tipo acceso atributo | G11: Valor por defecto | J11: Descripción atributo
C12: Tipo de dato | D12: ¿Cuál?
A13: exported | B13: ID | C13: string | E13: N/A | F13: no static | G13: "" | J13: Identificador único UUID
A14: exported | B14: Code | C14: string | E14: N/A | F14: no static | G14: "" | J14: Código único del mensaje
A15: exported | B15: Type | C15: Otro | D15: MessageType | E15: N/A | F15: no static | G15: "" | J15: Tipo de mensaje (ERROR, EXITO, WARNING, INFO)
A16: exported | B16: Category | C16: string | E16: N/A | F16: no static | G16: "" | J16: Categoría del mensaje
A17: exported | B17: Module | C17: string | E17: N/A | F17: no static | G17: "" | J17: Módulo al que pertenece
A18: exported | B18: Title | C18: Otro | E18: N/A | F18: no static | G18: "" | J18: Título del mensaje
A19: exported | B19: Content | C19: string | E19: N/A | F19: no static | G19: "" | J19: Contenido del mensaje
A20: exported | B20: Active | C20: boolean/Boolean | E20: N/A | F20: no static | G20: false | J20: Estado de activación
A21: exported | B21: CreatedAt | C21: Otro | D21: time.time | E21: N/A | F21: no static | G21: "" | J21: Fecha de creación
A22: exported | B22: UpdatedAt | C22: Otro | D22: time.time | E22: N/A | F22: no static | G22: "" | J22: Fecha de última actualización
A23: Constructores
A24: Modificador de acceso | B24: Nombre | C24: Tipo constructor | D24: Descripción | E24: Parámetros | M24: Excepciones
E25: Nombre | F25: Tipo de dato | G25: ¿Cuál? | H25: Tipo parámetro | I25: Tipo modificación atributo | J25: Descripción
A26: N/A | B26: =B2 -> Message | C26: Defecto (zero value) | D26: Inicialización por zero value de Go. Todos los campos toman su valor por defecto.
A27: exported | B27: SetID | C27: Inyección | D27: Genera y asigna un UUID al campo ID | H27: N/A | I27: N/A | J27: Identificador único UUID de la sede
A28: Métodos accesores
A29: Modificador de acceso | B29: Nombre | C29: Tipo método accesor | D29: Tipo modificación método | E29: Descripción | F29: Parámetros | L29: Tipo dato de retorno | N29: Excepciones
F30: Nombre | G30: Tipo de dato | H30: ¿Cuál? | I30: Tipo parámetro | J30: Tipo modificación atributo | K30: Descripción | L30: Tipo de dato | M30: ¿Cuál?
A31: N/A | B31: N/A | C31: N/A | D31: N/A | E31: En Go los campos exported se acceden directamente (ej: struct.Campo)
A32: Métodos
A33: Modificador de acceso | B33: Nombre | C33: Tipo acceso método | D33: Tipo modificación método | E33: Descripción | F33: Parámetros | L33: Tipo dato de retorno | N33: Excepciones
F34: Nombre | G34: Tipo de dato | H34: ¿Cuál? | I34: Tipo parámetro | J34: Tipo modificación atributo | K34: Descripción | L34: Tipo de dato | M34: ¿Cuál?
A35: exported | B35: SetID | C35: no static | D35: N/A | E35: Genera y asigna un UUID al campo ID | I35: N/A | J35: N/A | L35: void
A36: exported | B36: ToLogger | C36: no static | D36: N/A | E36: Retorna representación para logging | I36: N/A | J36: N/A | L36: String

Sheet Diagnostic
A1: <-Volver al inicio
A2: =Structs!$A$1 -> Struct | B2: =Structs!I13 -> Diagnostic
A3: =Structs!$B$1 -> Estereotipo | B3: =Structs!B13 -> struct
A4: =Structs!$C$1 -> Desripción | B4: =Structs!C13 -> Estructura que representa un diagnóstico solicitado para una motocicleta en una sede específica, con descripción del problema y posible solución.
A5: Modificador acceso: | B5: exported
A6: Tipo clase: | B6: N/A
A7: Relaciones
A8: Relación | B8: Tipo relación | E8: Estructura
A9: Necesita de | B9: Asociación | E9: =HYPERLINK("#'"&F9&"'!A1", F9) -> Motorcycle | F9: Motorcycle
A10: Necesita de | B10: Asociación | E10: =HYPERLINK("#'"&F10&"'!A1", F10) -> Branch | F10: Branch
A11: Es usada por | B11: Asociación | E11: =HYPERLINK("#'"&F11&"'!A1", F11) -> CompletedService | F11: CompletedService
A12: Es usada por | B12: Asociación | E12: =HYPERLINK("#'"&F12&"'!A1", F12) -> DiagnosticPermission | F12: DiagnosticPermission
A13: Atributos
A14: Modificador de acceso | B14: Nombre | C14: Tipo de dato | E14: Tipo modificación atributo | F14: Tipo acceso atributo | G14: Valor por defecto | J14: Descripción atributo
C15: Tipo de dato | D15: ¿Cuál?
A16: exported | B16: ID | C16: String | E16: N/A | F16: no static | G16: "" | J16: Identificador único UUID
A17: exported | B17: MotorcycleID | C17: String | E17: N/A | F17: no static | G17: "" | J17: FK a la motocicleta
A18: exported | B18: BranchID | C18: String | E18: N/A | F18: no static | G18: "" | J18: FK a la sede que emite el diagnóstico
A19: exported | B19: BranchName | C19: String | E19: N/A | F19: no static | G19: "" | J19: Nombre de la sede (desde JOIN)
A20: exported | B20: Date | C20: Otro | D20: time.time | E20: N/A | F20: no static | G20: "" | J20: Fecha del diagnóstico
A21: exported | B21: ProblemDescription | C21: String | E21: N/A | F21: no static | G21: nil | J21: Descripción del problema
A22: exported | B22: PossibleSolution | C22: String | E22: N/A | F22: no static | G22: nil | J22: Posible solución propuesta
A23: Constructores
A24: Modificador de acceso | B24: Nombre | C24: Tipo constructor | D24: Descripción | E24: Parámetros | M24: Excepciones
E25: Nombre | F25: Tipo de dato | G25: ¿Cuál? | H25: Tipo parámetro | I25: Tipo modificación atributo | J25: Descripción
A26: N/A | B26: =B2 -> Diagnostic | C26: Defecto (zero value) | D26: Inicialización por zero value de Go. Todos los campos toman su valor por defecto.
A27: exported | B27: SetID | C27: Inyección | D27: Genera y asigna un UUID al campo ID | H27: N/A | I27: N/A | J27: Identificador único UUID
A28: Métodos accesores
A29: Modificador de acceso | B29: Nombre | C29: Tipo método accesor | D29: Tipo modificación método | E29: Descripción | F29: Parámetros | L29: Tipo dato de retorno | N29: Excepciones
F30: Nombre | G30: Tipo de dato | H30: ¿Cuál? | I30: Tipo parámetro | J30: Tipo modificación atributo | K30: Descripción | L30: Tipo de dato | M30: ¿Cuál?
A31: N/A | B31: N/A | C31: N/A | D31: N/A | E31: En Go los campos exported se acceden directamente (ej: struct.Campo)
A32: Métodos
A33: Modificador de acceso | B33: Nombre | C33: Tipo acceso método | D33: Tipo modificación método | E33: Descripción | F33: Parámetros | L33: Tipo dato de retorno | N33: Excepciones
F34: Nombre | G34: Tipo de dato | H34: ¿Cuál? | I34: Tipo parámetro | J34: Tipo modificación atributo | K34: Descripción | L34: Tipo de dato | M34: ¿Cuál?
A35: exported | B35: SetID | C35: no static | D35: N/A | E35: Genera y asigna un UUID al campo ID | I35: N/A | J35: N/A | L35: void

Sheet DiagnosticPermission
A1: <-Volver al inicio
A2: =Structs!$A$1 -> Struct | B2: =Structs!I14 -> DiagnosticPermission
A3: =Structs!$B$1 -> Estereotipo | B3: =Structs!B14 -> struct
A4: =Structs!$C$1 -> Desripción | B4: =Structs!C14 -> Estructura que representa los permisos de un diagnóstico, controlando qué acciones pueden realizarse sobre él.
A5: Modificador acceso: | B5: exported
A6: Tipo clase: | B6: N/A
A7: Relaciones
A8: Relación | B8: Tipo relación | E8: Estructura
A9: Necesita de | B9: Asociación | E9: =HYPERLINK("#'"&F9&"'!A1", F9) -> Motorcycle | F9: Motorcycle
A10: Necesita de | B10: Asociación | E10: =HYPERLINK("#'"&F10&"'!A1", F10) -> Branch | F10: Branch
A11: Atributos
A12: Modificador de acceso | B12: Nombre | C12: Tipo de dato | E12: Tipo modificación atributo | F12: Tipo acceso atributo | G12: Valor por defecto | J12: Descripción atributo
C13: Tipo de dato | D13: ¿Cuál?
A14: exported | B14: ID | C14: String | E14: N/A | F14: no static | G14: "" | J14: Identificador único UUID
A15: exported | B15: MotorcycleID | C15: String | E15: N/A | F15: no static | G15: "" | J15: FK a la motocicleta
A16: exported | B16: BranchID | C16: String | E16: N/A | F16: no static | G16: "" | J16: FK a la sede autorizada
A17: exported | B17: Active | C17: String | E17: N/A | F17: no static | G17: false | J17: Si el permiso está activo
A18: Constructores
A19: Modificador de acceso | B19: Nombre | C19: Tipo constructor | D19: Descripción | E19: Parámetros | M19: Excepciones
E20: Nombre | F20: Tipo de dato | G20: ¿Cuál? | H20: Tipo parámetro | I20: Tipo modificación atributo | J20: Descripción
A21: N/A | B21: =B2 -> DiagnosticPermission | C21: Defecto (zero value) | D21: Inicialización por zero value de Go. Todos los campos toman su valor por defecto.
A22: exported | B22: SetID | C22: Inyección | D22: Genera y asigna un UUID al campo ID | H22: N/A | I22: N/A | J22: Identificador único UUID
A23: Métodos accesores
A24: Modificador de acceso | B24: Nombre | C24: Tipo método accesor | D24: Tipo modificación método | E24: Descripción | F24: Parámetros | L24: Tipo dato de retorno | N24: Excepciones
F25: Nombre | G25: Tipo de dato | H25: ¿Cuál? | I25: Tipo parámetro | J25: Tipo modificación atributo | K25: Descripción | L25: Tipo de dato | M25: ¿Cuál?
A26: N/A | B26: N/A | C26: N/A | D26: N/A | E26: En Go los campos exported se acceden directamente (ej: struct.Campo)
A27: Métodos
A28: Modificador de acceso | B28: Nombre | C28: Tipo acceso método | D28: Tipo modificación método | E28: Descripción | F28: Parámetros | L28: Tipo dato de retorno | N28: Excepciones
F29: Nombre | G29: Tipo de dato | H29: ¿Cuál? | I29: Tipo parámetro | J29: Tipo modificación atributo | K29: Descripción | L29: Tipo de dato | M29: ¿Cuál?
A30: exported | B30: SetID | C30: no static | D30: N/A | E30: Genera y asigna un UUID al campo ID | I30: N/A | J30: N/A | L30: void

Sheet CompletedService
A1: <-Volver al inicio
A2: =Structs!$A$1 -> Struct | B2: =Structs!I15 -> CompletedService
A3: =Structs!$B$1 -> Estereotipo | B3: =Structs!B15 -> struct
A4: =Structs!$C$1 -> Desripción | B4: =Structs!C15 -> Estructura que representa un servicio completado (realizado) sobre una motocicleta en una sede. Incluye estado, precios, notas y lista de ítems de servicio.
A5: Modificador acceso: | B5: exported
A6: Tipo clase: | B6: N/A
A7: Relaciones
A8: Relación | B8: Tipo relación | E8: Estructura
A9: Necesita de | B9: Asociación | E9: =HYPERLINK("#'"&F9&"'!A1", F9) -> Branch | F9: Branch
A10: Necesita de | B10: Asociación | E10: =HYPERLINK("#'"&F10&"'!A1", F10) -> Motorcycle | F10: Motorcycle
A11: Necesita de | B11: Asociación | E11: =HYPERLINK("#'"&F11&"'!A1", F11) -> Diagnostic | F11: Diagnostic
A12: Necesita de | B12: Asociación | E12: =HYPERLINK("#'"&F12&"'!A1", F12) -> ServiceStatus | F12: ServiceStatus
A13: Necesita de | B13: Agregación | E13: =HYPERLINK("#'"&F13&"'!A1", F13) -> CompletedServiceItem | F13: CompletedServiceItem
A14: Es usada por | B14: Asociación | E14: =HYPERLINK("#'"&F14&"'!A1", F14) -> ServiceStatusHistory | F14: ServiceStatusHistory
A15: Atributos
A16: Modificador de acceso | B16: Nombre | C16: Tipo de dato | E16: Tipo modificación atributo | F16: Tipo acceso atributo | G16: Valor por defecto | J16: Descripción atributo
C17: Tipo de dato | D17: ¿Cuál?
A18: exported | B18: ID | C18: string | E18: N/A | F18: no static | G18: "" | J18: Identificador único UUID
A19: exported | B19: BranchID | C19: string | E19: N/A | F19: no static | G19: "" | J19: FK a la sede (del token del representante)
A20: exported | B20: BranchName | C20: string | E20: N/A | F20: no static | G20: nil | J20: Nombre de la sede (desde JOIN)
A21: exported | B21: MotorcycleID | C21: string | E21: N/A | F21: no static | G21: " | J21: FK a la motocicleta
A22: exported | B22: DiagnosticID | C22: string | E22: N/A | F22: no static | G22: nil | J22: FK al diagnóstico (opcional)
A23: exported | B23: RequestDate | C23: Otro | D23: time.Time | E23: N/A | F23: no static | G23: "" | J23: Fecha de solicitud del servicio
A24: exported | B24: CompletionDate | C24: Otro | D24: time.Time | E24: N/A | F24: no static | G24: nil | J24: Fecha de finalización
A25: exported | B25: Status | C25: Otro | D25: ServiceStatus | E25: N/A | F25: no static | G25: "" | J25: Estado del servicio
A26: exported | B26: QuotedPrice | C26: float/Float | E26: N/A | F26: no static | G26: nil | J26: Precio cotizado
A27: exported | B27: FinalPrice | C27: float/Float | E27: N/A | F27: no static | G27: nil | J27: Precio final cobrado
A28: exported | B28: RepresentativeNotes | C28: String | E28: N/A | F28: no static | G28: nil | J28: Notas del representante
B29: Services | C29: Otro | D29: []CompletedServiceItem | E29: N/A | F29: no static | G29: nil | J29: Ítems de servicio asociados
B30: DeletedAt | C30: Otro | D30: time.Time | E30: N/A | F30: no static | G30: nil | J30: Marca de borrado suave
B31: CreatedAt | C31: Otro | D31: time.Time | E31: N/A | F31: no static | G31: "" | J31: Fecha de creación
B32: UpdatedAt | C32: Otro | D32: time.Time | E32: N/A | F32: no static | G32: "" | J32: Fecha de última actualización
A33: Constructores
A34: Modificador de acceso | B34: Nombre | C34: Tipo constructor | D34: Descripción | E34: Parámetros | M34: Excepciones
E35: Nombre | F35: Tipo de dato | G35: ¿Cuál? | H35: Tipo parámetro | I35: Tipo modificación atributo | J35: Descripción
A36: N/A | B36: =B2 -> CompletedService | C36: Defecto (zero value) | D36: Inicialización por zero value de Go. Todos los campos toman su valor por defecto.
A37: exported | B37: SetID | C37: Inyección | D37: Genera y asigna un UUID al campo ID | H37: N/A | I37: N/A | J37: Identificador único UUID de la sede
A38: Métodos accesores
A39: Modificador de acceso | B39: Nombre | C39: Tipo método accesor | D39: Tipo modificación método | E39: Descripción | F39: Parámetros | L39: Tipo dato de retorno | N39: Excepciones
F40: Nombre | G40: Tipo de dato | H40: ¿Cuál? | I40: Tipo parámetro | J40: Tipo modificación atributo | K40: Descripción | L40: Tipo de dato | M40: ¿Cuál?
...

Sheet CompletedServiceItem
A1: <-Volver al inicio
A2: =Structs!$A$1 -> Struct | B2: =Structs!I16 -> CompletedServiceItem
A3: =Structs!$B$1 -> Estereotipo | B3: =Structs!B16 -> struct
A4: =Structs!$C$1 -> Desripción | B4: =Structs!C16 -> Estructura que representa un ítem individual dentro de un servicio completado, incluyendo calificación y comentario del usuario.
A5: Modificador acceso: | B5: exported
A6: Tipo clase: | B6: N/A
A7: Relaciones
A8: Relación | B8: Tipo relación | E8: Estructura
A9: Necesita de | B9: Asociación | E9: =HYPERLINK("#'"&F9&"'!A1", F9) -> CompletedService | F9: CompletedService
A10: Necesita de | B10: Asociación | E10: =HYPERLINK("#'"&F10&"'!A1", F10) -> Service | F10: Service
A11: Atributos
A12: Modificador de acceso | B12: Nombre | C12: Tipo de dato | E12: Tipo modificación atributo | F12: Tipo acceso atributo | G12: Valor por defecto | J12: Descripción atributo
C13: Tipo de dato | D13: ¿Cuál?
A14: exported | B14: ID | C14: string | E14: N/A | F14: no static | G14: "" | J14: Identificador único UUID
A15: exported | B15: CompletedServiceID | C15: string | E15: N/A | F15: no static | G15: "" | J15: FK al servicio completado
A16: exported | B16: ServiceID | C16: string | E16: N/A | F16: no static | G16: "" | J16: FK al servicio del catálogo
A17: exported | B17: ServiceName | C17: string | E17: N/A | F17: no static | G17: nil | J17: Nombre del servicio (desde JOIN)
A18: exported | B18: Rating | C18: int/Integer | E18: N/A | F18: no static | G18: nil | J18: Calificación 1-5 (NULL hasta que califique)
A19: exported | B19: Comment | C19: String | E19: N/A | F19: no static | G19: nil | J19: Comentario de reseña del cliente
A20: exported | B20: RatedAt | C20: Otro | D20: time.Time | E20: N/A | F20: no static | G20: nil | J20: Fecha de calificación
A21: exported | B21: IsOffensiveComment | C21: boolean/Boolean | E21: N/A | F21: no static | G21: false | J21: Bandera de comentario ofensivo
A22: Constructores
A23: Modificador de acceso | B23: Nombre | C23: Tipo constructor | D23: Descripción | E23: Parámetros | M23: Excepciones
E24: Nombre | F24: Tipo de dato | G24: ¿Cuál? | H24: Tipo parámetro | I24: Tipo modificación atributo | J24: Descripción
A25: N/A | B25: =B2 -> CompletedServiceItem | C25: Defecto (zero value) | D25: Inicialización por zero value de Go. Todos los campos toman su valor por defecto.
A26: exported | B26: SetID | C26: Inyección | D26: Genera y asigna un UUID al campo ID | H26: N/A | I26: N/A | J26: Identificador único UUID de la sede
A27: Métodos accesores
A28: Modificador de acceso | B28: Nombre | C28: Tipo método accesor | D28: Tipo modificación método | E28: Descripción | F28: Parámetros | L28: Tipo dato de retorno | N28: Excepciones
F29: Nombre | G29: Tipo de dato | H29: ¿Cuál? | I29: Tipo parámetro | J29: Tipo modificación atributo | K29: Descripción | L29: Tipo de dato | M29: ¿Cuál?
A30: N/A | B30: N/A | C30: N/A | D30: N/A | E30: En Go los campos exported se acceden directamente (ej: struct.Campo)
A31: Métodos
A32: Modificador de acceso | B32: Nombre | C32: Tipo acceso método | D32: Tipo modificación método | E32: Descripción | F32: Parámetros | L32: Tipo dato de retorno | N32: Excepciones
F33: Nombre | G33: Tipo de dato | H33: ¿Cuál? | I33: Tipo parámetro | J33: Tipo modificación atributo | K33: Descripción | L33: Tipo de dato | M33: ¿Cuál?
A34: exported | B34: SetID | C34: no static | D34: N/A | E34: Genera y asigna un UUID al campo ID | I34: N/A | J34: N/A | L34: void

Sheet ServiceStatusHistory
A1: <-Volver al inicio
A2: =Structs!$A$1 -> Struct | B2: =Structs!I17 -> ServiceStatusHistory
A3: =Structs!$B$1 -> Estereotipo | B3: =Structs!B17 -> struct
A4: =Structs!$C$1 -> Desripción | B4: =Structs!C17 -> Estructura que registra el historial de cambios de estado de un servicio completado, con el estado anterior, nuevo, autor y fecha.
A5: Modificador acceso: | B5: exported
A6: Tipo clase: | B6: N/A
A7: Relaciones
A8: Relación | B8: Tipo relación | E8: Estructura
A9: Necesita de | B9: Asociación | E9: =HYPERLINK("#'"&F9&"'!A1", F9) -> CompletedService | F9: CompletedService
A10: Necesita de | B10: Asociación | E10: =HYPERLINK("#'"&F10&"'!A1", F10) -> ServiceStatus | F10: ServiceStatus
A11: Necesita de | B11: Asociación | E11: =HYPERLINK("#'"&F11&"'!A1", F11) -> Person | F11: Person
A12: Atributos
A13: Modificador de acceso | B13: Nombre | C13: Tipo de dato | E13: Tipo modificación atributo | F13: Tipo acceso atributo | G13: Valor por defecto | J13: Descripción atributo
C14: Tipo de dato | D14: ¿Cuál?
A15: exported | B15: ID | C15: String | E15: N/A | F15: no static | G15: "" | J15: Identificador único UUID
A16: exported | B16: CompletedServiceID | C16: String | E16: N/A | F16: no static | G16: "" | J16: FK al servicio completado
A17: exported | B17: PreviousStatus | C17: Otro | D17: *ServiceStatus | E17: N/A | F17: no static | G17: nil | J17: Estado anterior (nil en creación)
A18: exported | B18: NewStatus | C18: Otro | D18: ServiceStatus | E18: N/A | F18: no static | G18: "" | J18: Nuevo estado asignado
A19: exported | B19: CreatedBy | C19: String | E19: N/A | F19: no static | G19: "" | J19: FK a la persona que realizó el cambio
A20: exported | B20: CreatedAt | C20: Otro | D20: time.Time | E20: N/A | F20: no static | G20: "" | J20: Fecha del cambio de estado
A21: Constructores
A22: Modificador de acceso | B22: Nombre | C22: Tipo constructor | D22: Descripción | E22: Parámetros | M22: Excepciones
E23: Nombre | F23: Tipo de dato | G23: ¿Cuál? | H23: Tipo parámetro | I23: Tipo modificación atributo | J23: Descripción
A24: N/A | B24: =B2 -> ServiceStatusHistory | C24: Defecto (zero value) | D24: Inicialización por zero value de Go. Todos los campos toman su valor por defecto.
A25: exported | B25: SetID | C25: Inyección | D25: Genera y asigna un UUID al campo ID | H25: N/A | I25: N/A | J25: Identificador único UUID
A26: Métodos accesores
A27: Modificador de acceso | B27: Nombre | C27: Tipo método accesor | D27: Tipo modificación método | E27: Descripción | F27: Parámetros | L27: Tipo dato de retorno | N27: Excepciones
F28: Nombre | G28: Tipo de dato | H28: ¿Cuál? | I28: Tipo parámetro | J28: Tipo modificación atributo | K28: Descripción | L28: Tipo de dato | M28: ¿Cuál?
A29: N/A | B29: N/A | C29: N/A | D29: N/A | E29: En Go los campos exported se acceden directamente (ej: struct.Campo)
A30: Métodos
A31: Modificador de acceso | B31: Nombre | C31: Tipo acceso método | D31: Tipo modificación método | E31: Descripción | F31: Parámetros | L31: Tipo dato de retorno | N31: Excepciones
F32: Nombre | G32: Tipo de dato | H32: ¿Cuál? | I32: Tipo parámetro | J32: Tipo modificación atributo | K32: Descripción | L32: Tipo de dato | M32: ¿Cuál?
A33: exported | B33: SetID | C33: no static | D33: N/A | E33: Genera y asigna un UUID al campo ID | I33: N/A | J33: N/A | L33: void

Sheet Service
A1: <-Volver al inicio
A2: =Structs!$A$1 -> Struct | B2: =Structs!I18 -> Service
A3: =Structs!$B$1 -> Estereotipo | B3: =Structs!B18 -> struct
A4: =Structs!$C$1 -> Desripción | B4: =Structs!C18 -> Estructura que representa un servicio del catálogo global (por ejemplo: cambio de aceite, revisión de frenos). Incluye nombre, descripción, tipo y estado.
A5: Modificador acceso: | B5: exported
A6: Tipo clase: | B6: N/A
A7: Relaciones
A8: Relación | B8: Tipo relación | E8: Estructura
A9: Necesita de | B9: Asociación | E9: =HYPERLINK("#'"&F9&"'!A1", F9) -> ServiceType | F9: ServiceType
A10: Es usada por | B10: Asociación | E10: =HYPERLINK("#'"&F10&"'!A1", F10) -> BranchServiceInfo | F10: BranchServiceInfo
A11: Es usada por | B11: Asociación | E11: =HYPERLINK("#'"&F11&"'!A1", F11) -> CompletedServiceItem | F11: CompletedServiceItem
A12: Es usada por | B12: Asociación | E12: =HYPERLINK("#'"&F12&"'!A1", F12) -> ServiceReviewSummary | F12: ServiceReviewSummary
A13: Atributos
A14: Modificador de acceso | B14: Nombre | C14: Tipo de dato | E14: Tipo modificación atributo | F14: Tipo acceso atributo | G14: Valor por defecto | J14: Descripción atributo
C15: Tipo de dato | D15: ¿Cuál?
A16: exported | B16: ID | C16: string | E16: N/A | F16: no static | G16: "" | J16: Identificador único UUID
A17: exported | B17: Name | C17: string | E17: N/A | F17: no static | G17: "" | J17: Nombre del servicio
A18: exported | B18: Description | C18: string | E18: N/A | F18: no static | G18: "" | J18: Descripción del servicio
A19: exported | B19: ServiceType | C19: Otro | D19: ServiceType | E19: N/A | F19: no static | G19: "" | J19: Tipo de servicio del catálogo
A20: exported | B20: IsActive | C20: boolean/Boolean | E20: N/A | F20: no static | G20: false | J20: Estado de activación
A21: Constructores
A22: Modificador de acceso | B22: Nombre | C22: Tipo constructor | D22: Descripción | E22: Parámetros | M22: Excepciones
E23: Nombre | F23: Tipo de dato | G23: ¿Cuál? | H23: Tipo parámetro | I23: Tipo modificación atributo | J23: Descripción
A24: N/A | B24: =B2 -> Service | C24: Defecto (zero value) | D24: Inicialización por zero value de Go. Todos los campos toman su valor por defecto.
A25: Métodos accesores
A26: Modificador de acceso | B26: Nombre | C26: Tipo método accesor | D26: Tipo modificación método | E26: Descripción | F26: Parámetros | L26: Tipo dato de retorno | N26: Excepciones
F27: Nombre | G27: Tipo de dato | H27: ¿Cuál? | I27: Tipo parámetro | J27: Tipo modificación atributo | K27: Descripción | L27: Tipo de dato | M27: ¿Cuál?
A28: N/A | B28: N/A | C28: N/A | D28: N/A | E28: En Go los campos exported se acceden directamente (ej: struct.Campo)
A29: Métodos
A30: Modificador de acceso | B30: Nombre | C30: Tipo acceso método | D30: Tipo modificación método | E30: Descripción | F30: Parámetros | L30: Tipo dato de retorno | N30: Excepciones
F31: Nombre | G31: Tipo de dato | H31: ¿Cuál? | I31: Tipo parámetro | J31: Tipo modificación atributo | K31: Descripción | L31: Tipo de dato | M31: ¿Cuál?
A32: N/A | B32: N/A | C32: N/A | D32: N/A | E32: N/A | F32: N/A | G32: N/A | H32: N/A | I32: N/A | J32: N/A | K32: N/A | L32: N/A | M32: N/A | N32: N/A

Sheet ServiceReview
A1: <-Volver al inicio
A2: =Structs!$A$1 -> Struct | B2: =Structs!I19 -> ServiceReview
A3: =Structs!$B$1 -> Estereotipo | B3: =Structs!B19 -> struct
A4: =Structs!$C$1 -> Desripción | B4: =Structs!C19 -> Estructura que representa una reseña individual de un servicio, con nombre del revisor, calificación, comentario y modelo de moto.
A5: Modificador acceso: | B5: exported
A6: Tipo clase: | B6: N/A
A7: Relaciones
A8: Relación | B8: Tipo relación | E8: Estructura
