Workbook

Sheet Mapa empatía
A1: Atributos de calidad | B1: Administrador | C1: Representantre Sede | D1: Usuario | E1: Total | F1: Porcentaje | G1: Total Características | H1: Total votos | I1: Administrador | J1: Representante Sede | K1: Usuario
A2: Disponibilidad | B2: 9 | C2: 14 | D2: 14 | E2: =B2+C2+D2 -> 37 | F2: =E2/$E$17 -> 0.10277778 | G2: =COUNTA(Disponibilidad!A2:A3) -> 1 | H2: =G17/2+1 -> 19 | I2: =SUM(Disponibilidad!C2:C3) -> 2 | J2: =SUM(Disponibilidad!D2:D3) -> 2 | K2: =SUM(Disponibilidad!E2:E3) -> 2
A3: Confiabilidad | B3: 7 | C3: 15 | D3: 15 | E3: =B3+C3+D3 -> 37 | F3: =E3/$E$17 -> 0.10277778 | G3: =COUNTA(Confiabilidad!A2:A6) -> 4 | I3: =SUM(Confiabilidad!C2:C6) -> 4 | J3: =SUM(Confiabilidad!D2:D6) -> 4 | K3: =SUM(Confiabilidad!E2:E6) -> 4
A4: Seguridad | B4: 11 | C4: 11 | D4: 11 | E4: =B4+C4+D4 -> 33 | F4: =E4/$E$17 -> 0.091666667 | G4: =COUNTA(Seguridad!A2:A8) -> 6 | I4: =SUM(Seguridad!C2:C8) -> 8 | J4: =SUM(Seguridad!D2:D8) -> 12 | K4: =SUM(Seguridad!E2:E8) -> 12
A5: Rendimiento | B5: 12 | C5: 10 | D5: 10 | E5: =B5+C5+D5 -> 32 | F5: =E5/$E$17 -> 0.088888889 | G5: =COUNTA(Rendimiento!A2:A12) -> 10 | I5: =SUM(Rendimiento!C2:C12) -> 14 | J5: =SUM(Rendimiento!D2:D12) -> 8 | K5: =SUM(Rendimiento!E2:E12) -> 8 | M5: Nota: Esta votado de 1 a 15 donde a mayor numero tiene un mayor impacto
A6: Experiencia de usuario | B6: 2 | C6: 13 | D6: 13 | E6: =B6+C6+D6 -> 28 | F6: =E6/$E$17 -> 0.077777778 | G6: =COUNTA('Experiencia de usuario'!A2:A12) -> 10 | I6: =SUM('Experiencia de usuario'!C2:C12) -> 2 | J6: =SUM('Experiencia de usuario'!D2:D12) -> 20 | K6: =SUM('Experiencia de usuario'!E2:E12) -> 20
A7: Accesibilidad | B7: 3 | C7: 12 | D7: 12 | E7: =B7+C7+D7 -> 27 | F7: =E7/$E$17 -> 0.075 | G7: =COUNTA(Accesibilidad!A2:A5) -> 3 | I7: =SUM(Accesibilidad!C2:C5) -> 0 | J7: =SUM(Accesibilidad!D2:D5) -> 6 | K7: =SUM(Accesibilidad!E2:E5) -> 6
A8: Capacidad de ser administrado | B8: 15 | C8: 5 | D8: 5 | E8: =B8+C8+D8 -> 25 | F8: =E8/$E$17 -> 0.069444444 | G8: 0 | I8: 0 | J8: 0 | K8: 0
A9: Conformidad | B9: 5 | C9: 9 | D9: 9 | E9: =B9+C9+D9 -> 23 | F9: =E9/$E$17 -> 0.063888889 | G9: =COUNTA(Conformidad!A2:A4) -> 2 | I9: =SUM(Conformidad!C2:C4) -> 4 | J9: =SUM(Conformidad!D2:D4) -> 0 | K9: =SUM(Conformidad!E2:E4) -> 2
A10: Capacidad para ser probado | B10: 14 | C10: 4 | D10: 4 | E10: =B10+C10+D10 -> 22 | F10: =E10/$E$17 -> 0.061111111 | G10: 0 | I10: 0 | J10: 0 | K10: 0
A11: Mantenibilidad | B11: 6 | C11: 7 | D11: 7 | E11: =B11+C11+D11 -> 20 | F11: =E11/$E$17 -> 0.055555556 | G11: 0 | I11: 0 | J11: 0 | K11: 0
A12: Interoperabilidad | B12: 8 | C12: 6 | D12: 6 | E12: =B12+C12+D12 -> 20 | F12: =E12/$E$17 -> 0.055555556 | G12: 0 | I12: 0 | J12: 0 | K12: 0
A13: Escalabilidad | B13: 4 | C13: 8 | D13: 8 | E13: =B13+C13+D13 -> 20 | F13: =E13/$E$17 -> 0.055555556 | G13: 0 | I13: 0 | J13: 0 | K13: 0
A14: Capacidad para ser soportado | B14: 13 | C14: 3 | D14: 3 | E14: =B14+C14+D14 -> 19 | F14: =E14/$E$17 -> 0.052777778 | G14: 0 | I14: 0 | J14: 0 | K14: 0
A15: Flexibilidad | B15: 10 | C15: 2 | D15: 2 | E15: =B15+C15+D15 -> 14 | F15: =E15/$E$17 -> 0.038888889 | G15: 0 | I15: 0 | J15: 0 | K15: 0
A16: Internacionalización | B16: 1 | C16: 1 | D16: 1 | E16: =B16+C16+D16 -> 3 | F16: =E16/$E$17 -> 0.0083333333 | G16: 0 | I16: 0 | J16: 0 | K16: 0
A17: Total | B17: =SUM(B2:B16) -> 120 | C17: =SUM(C2:C16) -> 120 | D17: =SUM(D2:D16) -> 120 | E17: =SUM(E2:E16) -> 360 | F17: =SUM(F2:F16) -> 1 | G17: =SUM(G2:G16) -> 36 | I17: =SUM(I2:I16) -> 34 | J17: =SUM(J2:J16) -> 52 | K17: =SUM(K2:K16) -> 54

Sheet Accesibilidad
A1: Características | C1: Administrador | D1: Representante Sede | E1: Usuario | F1: Priorizacion
A2: Se requiere que la aplicación ofrezca una navegación clara, estructurada y lógica, permitiendo a los usuarios orientarse fácilmente dentro del sistema sin confusión. | B2: Escenarios | C2: 0 | D2: 1 | E2: 1 | F2: =SUM(C2:E2) -> 2
A3: Se requiere que los elementos visuales cumplan con estándares mínimos de contraste y tamaño de fuente, asegurando la lectura cómoda para todo tipo de usuario. | B3: Escenarios | C3: 0 | D3: 1 | E3: 1 | F3: =SUM(C3:E3) -> 2
A4: Se requiere que la aplicación emplee un lenguaje sencillo, directo y sin tecnicismos innecesarios, favoreciendo la comprensión de todos los usuarios. | B4: Escenarios | C4: 0 | D4: 1 | E4: 1 | F4: =SUM(C4:E4) -> 2
C5: =SUM(C2:C4) -> 0 | D5: =SUM(D2:D4) -> 3 | E5: =SUM(E2:E4) -> 3 | F5: =SUM(F2:F4) -> 6

Sheet Confiabilidad
A1: Características | B1: Escenarios | C1: Administrador | D1: Representante Sede | E1: Usuario | F1: Priorización
A2: Se requiere que la aplicación mantenga un nivel de disponibilidad mínimo del 99% durante el horario operativo, garantizando su acceso y uso continuo por parte de los usuarios. | B2: Escenarios | C2: 0 | D2: 1 | E2: 1 | F2: =SUM(C2:E2) -> 2
A3: Se requiere que la aplicación incorpore mecanismos de tolerancia a fallos que permitan continuar su funcionamiento ante errores parciales o interrupciones de componentes individuales. | B3: Escenarios | C3: 0 | D3: 0 | E3: 0 | F3: =SUM(C3:E3) -> 0
A4: Se requiere que la aplicación gestione los errores de forma controlada, mostrando mensajes comprensibles al usuario y evitando cierres inesperados o pérdida de información. | B4: Escenarios | C4: 1 | D4: 1 | E4: 1 | F4: =SUM(C4:E4) -> 3
A5: Se requiere que la aplicación valide de forma estricta las entradas de datos en operaciones críticas, reduciendo el riesgo de fallos por datos incorrectos o malformados. | B5: Escenarios | C5: 1 | D5: 0 | E5: 0 | F5: =SUM(C5:E5) -> 1 | H5: NOTA: es la habilidad de un sistema para mantener operacional en el tiempo. La confiabilidad se mide como la probabilidad de que un sistema no falle en ejecutar la función para la que fue construido dentro de un periodo especifico de tiempo.
C6: =SUM(C2:C5) -> 2 | D6: =SUM(D2:D5) -> 2 | E6: =SUM(E2:E5) -> 2 | F6: =SUM(F2:F5) -> 6

Sheet Conformidad
A1: Características | B1: Escenario | C1: Administrador | D1: Representante Sede | E1: Usuario | F1: Priorización
A2: Se requiere que la aplicación cumpla con las normativas nacionales e internacionales aplicables al tipo de sistema, garantizando su operación dentro del marco legal vigente. | B2: Escenarios | C2: 1 | D2: 0 | E2: 1 | F2: =SUM(C2:E2) -> 2
A3: Se requiere que la aplicación respete las leyes de protección de datos personales (como la Ley 1581 de 2012 en Colombia o el RGPD en Europa), asegurando el tratamiento ético y seguro de la información. | B3: Escenarios | C3: 1 | D3: 0 | E3: 0 | F3: =SUM(C3:E3) -> 1
C4: =SUM(C2:C3) -> 2 | D4: =SUM(D2:D3) -> 0 | E4: =SUM(E2:E3) -> 1 | F4: =SUM(F2:F3) -> 3

Sheet Disponibilidad
A1: Característica | B1: Escenarios | C1: Administrador | D1: Representante Sede | E1: Usuario | F1: Priorización
A2: Se requiere que la aplicación mantenga un nivel de disponibilidad mínimo del 99% durante los periodos de operación, garantizando su acceso continuo por parte de los usuarios. | B2: Escenarios | C2: 1 | D2: 1 | E2: 1 | F2: =SUM(C2:E2) -> 3
C3: =SUM(C2:C2) -> 1 | D3: =SUM(D2:D2) -> 1 | E3: =SUM(E2:E2) -> 1 | F3: =SUM(F2:F2) -> 3

Sheet Experiencia de usuario
A1: Características | B1: Escenarios | C1: Administrador | D1: Representante Sede | E1: Usuario | F1: Priorización | H1: NOTA: se define como el conjunto de factores y elementos relacionados con el proceso de interacción de un usuario respecto a un producto o servicio.
A2: Se requiere que la aplicación cuente con una interfaz clara, sencilla e intuitiva, que permita a los usuarios comprender y ejecutar sus tareas sin necesidad de capacitación previa. | B2: Escenarios | C2: 1 | D2: 1 | E2: 1 | F2: =SUM(C2:E2) -> 3
A3: Se requiere que la aplicación mantenga coherencia en sus elementos visuales, iconografía, tipografía y comportamientos interactivos en todas sus secciones. | B3: Escenarios | C3: 0 | D3: 1 | E3: 1 | F3: =SUM(C3:E3) -> 2
A4: Se requiere que las acciones del usuario obtengan una respuesta del sistema en un tiempo menor a dos segundos, garantizando fluidez y satisfacción en la interacción. | B4: Escenarios | C4: 0 | D4: 1 | E4: 1 | F4: =SUM(C4:E4) -> 2
A5: Se requiere que la aplicación brinde mensajes claros de confirmación, error o advertencia ante cada acción del usuario, evitando la incertidumbre durante la navegación. | B5: Escenarios | C5: 0 | D5: 1 | E5: 1 | F5: =SUM(C5:E5) -> 2
A6: Se requiere que la aplicación se adapte correctamente a diferentes tamaños de pantalla y dispositivos, conservando su funcionalidad y estética en todos los entornos. | B6: Escenarios | C6: 0 | D6: 1 | E6: 1 | F6: =SUM(C6:E6) -> 2
A7: Se requiere que la aplicación anticipe y prevenga errores mediante validaciones, sugerencias o restricciones que orienten al usuario hacia acciones correctas. | B7: Escenarios | C7: 0 | D7: 1 | E7: 1 | F7: =SUM(C7:E7) -> 2
A8: Se requiere que la aplicación cumpla con los principios de accesibilidad digital, permitiendo el uso a personas con diferentes niveles de habilidad o discapacidad. | B8: Escenarios | C8: 0 | D8: 1 | E8: 1 | F8: =SUM(C8:E8) -> 2
A9: Se requiere que la aplicación mantenga un diseño visual agradable, alineado con la identidad visual de la marca, fomentando la confianza y la recordación del usuario. | B9: Escenarios | C9: 0 | D9: 1 | E9: 1 | F9: =SUM(C9:E9) -> 2
A10: Se requiere que la aplicación permita adaptar ciertos aspectos de la interfaz o las notificaciones según las preferencias del usuario, mejorando la sensación de control y confort. | B10: Escenarios | C10: 0 | D10: 1 | E10: 1 | F10: =SUM(C10:E10) -> 2
A11: Se requiere que la aplicación mida periódicamente la satisfacción del usuario mediante encuestas o métricas de uso, utilizando los resultados para mejorar la experiencia ofrecida. | B11: Escenarios | C11: 0 | D11: 1 | E11: 1 | F11: =SUM(C11:E11) -> 2
C12: =SUM(C2:C11) -> 1 | D12: =SUM(D2:D11) -> 10 | E12: =SUM(E2:E11) -> 10 | F12: =SUM(F2:F11) -> 21

Sheet Rendimiento
A1: Características | B1: Escenario | C1: Administrador | D1: Representante Sede | E1: Usuario | F1: Priorización
A2: Se requiere que la aplicación cargue rápidamente y responda sin demoras a las acciones del usuario (menor a 2 segundos). | B2: Escenarios | C2: 1 | D2: 1 | E2: 1 | F2: =SUM(C2:E2) -> 3
A3: Se requiere que el tiempo de espera entre pantallas o procesos sea mínimo para mantener una buena experiencia de uso. | B3: Escenarios | C3: 0 | D3: 1 | E3: 1 | F3: =SUM(C3:E3) -> 2
A4: Se requiere que la aplicación use de forma eficiente los recursos del dispositivo, como la memoria o el procesador. | B4: Escenarios | C4: 1 | D4: 0 | E4: 0 | F4: =SUM(C4:E4) -> 1 | H4: NOTA: es un indicador de la capacidad de respuesta del sistema para ejecutar una acción dentro de un intervalo de tiempo dado. Puede ser medida en términos de latencia o de respuesta.
A5: Se requiere que la aplicación pueda manejar grandes volúmenes de información sin disminuir su velocidad. | B5: Escenarios | C5: 1 | D5: 0 | E5: 0 | F5: =SUM(C5:E5) -> 1
A6: Se requiere que las operaciones más frecuentes (inicio de sesión, búsqueda, carga de datos) se realicen en el menor tiempo posible( menor a 5 segundos). | B6: Escenarios | C6: 0 | D6: 1 | E6: 1 | F6: =SUM(C6:E6) -> 2
A7: Se requiere que la aplicación mantenga un desempeño estable sin importar el tipo de conexión a internet. | B7: Escenarios | C7: 0 | D7: 1 | E7: 1 | F7: =SUM(C7:E7) -> 2
A8: Se requiere que la aplicación aproveche la memoria disponible del dispositivo sin generar bloqueos ni cierres inesperados. | B8: Escenarios | C8: 1 | D8: 0 | E8: 0 | F8: =SUM(C8:E8) -> 1
A9: Se requiere que las actualizaciones o sincronizaciones se realicen sin afectar la fluidez del sistema. | B9: Escenarios | C9: 1 | D9: 0 | E9: 0 | F9: =SUM(C9:E9) -> 1
A10: Se requiere que los tiempos de carga de imágenes, videos o documentos sean reducidos y estables. | B10: Escenarios | C10: 1 | D10: 0 | E10: 0 | F10: =SUM(C10:E10) -> 1
A11: Se requiere que la aplicación pueda adaptarse a distintos niveles de rendimiento de los dispositivos (gama alta, media o baja). | B11: Escenarios | C11: 1 | D11: 0 | E11: 0 | F11: =SUM(C11:E11) -> 1
C12: =SUM(C2:C11) -> 7 | D12: =SUM(D2:D11) -> 4 | E12: =SUM(E2:E11) -> 4 | F12: =SUM(F2:F11) -> 15

Sheet Seguridad
A1: Característica | B1: Escenarios | C1: Administrador | D1: Representante Sede | E1: Usuario | F1: Priorización
A2: Se requiere que la aplicación proteja la información personal de los usuarios frente a accesos no autorizados. | B2: Escenarios | C2: 1 | D2: 1 | E2: 1 | F2: =SUM(C2:E2) -> 3
A3: Se requiere que solo las personas con los permisos adecuados puedan acceder a funciones o datos confidenciales. | B3: Escenarios | C3: 1 | D3: 1 | E3: 1 | F3: =SUM(C3:E3) -> 3
A4: Se requiere que la aplicación cierre automáticamente la sesión después de un tiempo prolongado sin actividad. | B4: Escenarios | C4: 1 | D4: 1 | E4: 1 | F4: =SUM(C4:E4) -> 3
A5: Se requiere que los usuarios puedan cambiar su contraseña de manera fácil y segura. | B5: Escenarios | C5: 0 | D5: 1 | E5: 1 | F5: =SUM(C5:E5) -> 2
A6: Se requiere que la aplicación bloquee temporalmente una cuenta tras varios intentos fallidos de inicio de sesión. | B6: Escenarios | C6: 0 | D6: 1 | E6: 1 | F6: =SUM(C6:E6) -> 2
A7: Se requiere que la aplicación solicite confirmación antes de realizar acciones que puedan afectar los datos del usuario. | B7: Escenarios | C7: 1 | D7: 1 | E7: 1 | F7: =SUM(C7:E7) -> 3
C8: =SUM(C2:C7) -> 4 | D8: =SUM(D2:D7) -> 6 | E8: =SUM(E2:E7) -> 6 | F8: =SUM(F2:F7) -> 16

Sheet ESC-CAL-ACCESIBILIDAD
A1: Accesibilidad
A3: Atributo de calidad: | D3: =A1 -> Accesibilidad
A4: Característica: | D4: Se requiere que la aplicación ofrezca una navegación clara, estructurada y lógica, permitiendo a los usuarios orientarse fácilmente dentro del sistema sin confusión.
A5: Identificador del escenario de calidad: | D5: ESC-CAL-ACC-0001
A6: Nombre del escenario de calidad: | D6: Navegación clara y estructurada dentro de la aplicación
A7: Tipo escenario: | D7: Básico
A8: Objetivo: | D8: Garantizar que la aplicación ofrezca una navegación intuitiva, organizada y coherente, permitiendo que los usuarios comprendan fácilmente la estructura del sistema y localicen las funcionalidades o contenidos que necesitan sin confusión.
A9: Descripción: | D9: Escenario donde los usuarios interactúan con la interfaz principal de la aplicación para acceder a diferentes secciones o módulos. La disposición de menús, botones y enlaces sigue una jerarquía lógica y coherente con el flujo natural de uso. Los elementos de navegación son consistentes en todas las pantallas, y las rutas de acceso están claramente identificadas mediante etiquetas descriptivas o íconos reconocibles.
A10: Criterio de éxito: | D10: Los usuarios pueden desplazarse entre las secciones del sistema sin experimentar desorientación ni necesidad de asistencia externa. Se considera exitoso cuando la mayoría de los usuarios completa las tareas principales sin errores de navegación ni tiempos de búsqueda prolongados.
A11: Fuente del estímulo | C11: Estímulo | E11: Ambiente | G11: Artefacto | I11: Respuesta | K11: Medida de la respuesta | M11: ¿Cumplió? | N11: Tácticas y estrategia
A12: Usuarios finales o evaluadores de experiencia de usuario (UX). | C12: Interacción del usuario con los menús, rutas y elementos de navegación del sistema. | E12: Producción (dispositivos reales con conexión a internet) | G12: Sistema | I12: El sistema guía al usuario a través de una estructura clara y predecible, donde los elementos mantienen coherencia visual y funcional. Las rutas son comprensibles y el usuario puede regresar fácilmente a pantallas anteriores o al inicio sin perder el contexto. | K12: Se asegura que las pruebas de usabilidad reflejan que al menos el 90% de los usuarios localiza correctamente las funciones principales sin ayuda. Los tiempos promedio de navegación no superan los 5 segundos por interacción, y las encuestas de satisfacción muestran una calificación igual o superior al 4/5 en claridad de navegación. | N12: Implementación de diseño responsivo con Flutter LayoutBuilder Pattern y MediaQuery. Uso de Material Design 3 para coherencia visual. Pruebas en múltiples resoluciones (phones/tablets).
A14: Atributo de calidad: | D14: =A1 -> Accesibilidad
A15: Característica: | D15: Se requiere que la aplicación ofrezca una navegación clara, estructurada y lógica, permitiendo a los usuarios orientarse fácilmente dentro del sistema sin confusión.
A16: Identificador del escenario de calidad: | D16: ESC-CAL-ACC-0002
A17: Nombre del escenario de calidad: | D17: Corrección de inconsistencias o confusiones en la navegación del sistema
A18: Tipo escenario: | D18: Alternativo
A19: Objetivo: | D19: Asegurar que, ante la detección de rutas confusas, redundantes o inconsistentes en la navegación, el sistema y el equipo de diseño puedan corregirlas de forma controlada, mejorando la coherencia estructural sin afectar otras funcionalidades.
A20: Descripción: | D20: Escenario donde las pruebas de usabilidad o retroalimentaciones de los usuarios evidencian que algunas rutas o menús no son intuitivos, generando confusión o errores al intentar acceder a ciertas funciones. El equipo de diseño revisa la arquitectura de información, ajusta la jerarquía de menús, reorganiza etiquetas o agrupa funciones relacionadas, manteniendo la coherencia con los estándares de navegación establecidos.
A21: Criterio de éxito: | D21: Las inconsistencias de navegación son identificadas y corregidas sin alterar la estructura funcional de la aplicación. Se considera exitoso cuando las pruebas posteriores confirman una mejora significativa en la orientación del usuario y una reducción en los errores o tiempos de búsqueda.
A22: Fuente del estímulo | C22: Estímulo | E22: Ambiente | G22: Artefacto | I22: Respuesta | K22: Medida de la respuesta | M22: ¿Cumplió? | N22: Tácticas y estrategia
A23: Usuario final | C23: Reporte o detección de rutas confusas o poco intuitivas dentro de la aplicación. | E23: Producción (dispositivos móviles con diferentes versiones del sistema operativo) | G23: Sistema | I23: El equipo técnico analiza las observaciones, ajusta la estructura de navegación, actualiza los menús y etiquetas, y valida nuevamente la experiencia de usuario mediante pruebas controladas. | K23: Se asegura que el número de errores de navegación disminuye en al menos un 80% tras la corrección, que los usuarios identifican las rutas principales en menos de 3 segundos, y que las encuestas de usabilidad confirman un aumento en la satisfacción general respecto a la claridad del sistema. | N23: Ciclo de retroalimentación UX → corrección → validación. Monitoreo de métricas de usabilidad post-despliegue. Pruebas de regresión visual.
A25: Atributo de calidad: | D25: =A1 -> Accesibilidad
A26: Característica: | D26: Se requiere que la aplicación ofrezca una navegación clara, estructurada y lógica, permitiendo a los usuarios orientarse fácilmente dentro del sistema sin confusión.
A27: Identificador del escenario de calidad: | D27: ESC-CAL-ACC-0003
A28: Nombre del escenario de calidad: | D28: Navegación clara, estructurada y lógica dentro de la aplicación
A29: Tipo escenario: | D29: Básico
A30: Objetivo: | D30: Garantizar que la aplicación ofrezca una navegación intuitiva, coherente y organizada, de modo que los usuarios puedan orientarse fácilmente, comprender la estructura del sistema y acceder rápidamente a las funciones o contenidos que necesiten sin experimentar confusión.
A31: Descripción: | D31: Escenario donde un usuario interactúa con la aplicación y puede desplazarse entre las distintas secciones de manera fluida gracias a una estructura lógica y consistente. Los menús están organizados jerárquicamente, las etiquetas son claras y descriptivas, y los botones conducen a las secciones esperadas. La interfaz sigue patrones de diseño coherentes que permiten al usuario predecir la ubicación de las funciones principales, reduciendo errores de navegación y mejorando la experiencia de uso.
A32: Criterio de éxito: | D32: El usuario logra desplazarse por todas las secciones principales sin requerir asistencia externa ni mostrar signos de desorientación. Las pruebas de usabilidad indican que al menos el 90% de los usuarios completan tareas de navegación sin errores o confusión.
A33: Fuente del estímulo | C33: Estímulo | E33: Ambiente | G33: Artefacto | I33: Respuesta | K33: Medida de la respuesta | M33: ¿Cumplió? | N33: Tácticas y estrategia
A34: Usuario final | C34: Interacción del usuario con la interfaz de navegación, explorando diferentes secciones o funciones de la aplicación. | E34: Producción (dispositivo móvil sin acceso a internet) | G34: Sistema | I34: El sistema presenta una estructura de navegación clara, con elementos fácilmente identificables y consistentes en su posición y comportamiento. Se dispone de indicadores visuales del contexto actual (por ejemplo, resaltado de la sección activa o breadcrumbs), y las transiciones entre pantallas mantienen la coherencia semántica y funcional. | K34: Asegura que las pruebas de usabilidad reflejan una tasa de éxito superior al 90% en tareas de navegación, con un tiempo promedio de aprendizaje inferior a los 3 minutos. No se registran reportes de desorientación ni errores de navegación en las pruebas con usuarios reales, cumpliendo con los principios de usabilidad y diseño centrado en el usuario (ISO 9241-210). | N34: Implementación de diseño responsivo con Flutter LayoutBuilder Pattern y MediaQuery. Uso de Material Design 3 para coherencia visual. Pruebas en múltiples resoluciones (phones/tablets).
A36: Atributo de calidad: | D36: =A1 -> Accesibilidad
A37: Característica: | D37: Se requiere que los elementos visuales cumplan con estándares mínimos de contraste y tamaño de fuente, asegurando la lectura cómoda para todo tipo de usuario.
A38: Identificador del escenario de calidad: | D38: ESC-CAL-ACC-0004
A39: Nombre del escenario de calidad: | D39: Corrección de problemas de navegación confusa o estructura no intuitiva
A40: Tipo escenario: | D40: Alternativo
A41: Objetivo: | D41: Asegurar que, en caso de detectarse dificultades de orientación, rutas poco claras o inconsistencias en la estructura de navegación, el sistema sea ajustado para ofrecer una experiencia más intuitiva y coherente, reduciendo la confusión del usuario y mejorando la eficiencia en la interacción.
A42: Descripción: | D42: Escenario donde durante una prueba de usabilidad o mediante retroalimentación de usuarios, se identifica que ciertas secciones de la aplicación presentan navegación confusa, etiquetas poco descriptivas o falta de consistencia en los botones y menús. El equipo de diseño y desarrollo analiza los patrones de interacción, detecta los puntos de fricción y redefine la estructura de navegación. Se actualizan las etiquetas, la disposición de los menús y los flujos de acceso, validando los cambios mediante nuevas pruebas con usuarios reales.
A43: Criterio de éxito: | D43: Las dificultades de navegación reportadas son eliminadas, y los usuarios logran completar las mismas tareas con una tasa de éxito del 95% o superior después de la corrección. Se considera exitoso cuando las pruebas posteriores muestran una reducción significativa en los errores o tiempos de búsqueda dentro del sistema.
A44: Fuente del estímulo | C44: Estímulo | E44: Ambiente | G44: Artefacto | I44: Respuesta | K44: Medida de la respuesta | M44: ¿Cumplió? | N44: Tácticas y estrategia
...

Sheet ESC-CAL-CONFIABILIDAD
A1: Confiabilidad
A3: Atributo de calidad: | D3: =$A$1 -> Confiabilidad
A4: Característica: | D4: Se requiere que la aplicación mantenga un nivel de disponibilidad mínimo del 99% durante el horario operativo, garantizando su acceso y uso continuo por parte de los usuarios.
A5: Identificador del escenario de calidad: | D5: ESC-CAL-CONFI-0001
A6: Nombre del escenario de calidad: | D6: Disponibilidad continua del sistema durante el horario operativo
A7: Tipo escenario: | D7: Básico
A8: Objetivo | D8: Garantizar que la aplicación mantenga un nivel de disponibilidad mínimo del 99% durante el horario operativo, asegurando que los usuarios puedan acceder y utilizar el sistema de forma ininterrumpida.
A9: Descripción: | D9: Escenario donde el sistema se encuentra en funcionamiento durante las horas definidas como operativas. Los servicios de backend, la base de datos y la infraestructura de red operan correctamente, procesando las solicitudes de los usuarios con tiempos de respuesta dentro de los umbrales esperados. El monitoreo confirma la estabilidad del sistema y la ausencia de interrupciones imprevistas.
A10: Criterio de éxito: | D10: El sistema se mantiene accesible y funcional durante el horario operativo, sin interrupciones significativas que afecten la experiencia del usuario.
A11: Fuente del estímulo | C11: Estímulo | E11: Ambiente | G11: Artefacto | I11: Respuesta | K11: Medida de la respuesta | M11: ¿Cumplió? | N11: Tácticas y estrategia
A12: Usuario final | C12: Solicitud de acceso o uso de las funciones de la aplicación durante el horario operativo. | E12: Operación normal | G12: Sistema | I12: El sistema procesa las solicitudes de los usuarios sin interrupciones, manteniendo la estabilidad, la conectividad y la capacidad de respuesta esperada. | K12: Asegura que el sistema permanezca disponible durante las horas operativas definidas, que las interrupciones no afecten la experiencia del usuario y que el monitoreo confirme un nivel de disponibilidad estable conforme a los parámetros establecidos. | N12: Input Sanitization 100% en POST/PUT. Manejo de errores controlado con Result Container Pattern. Validación por JSON Schema. Mensajes de sistema informativos (Authoritative Backend Messaging).
A14: Atributo de calidad: | D14: =$A$1 -> Confiabilidad
A15: Característica: | D15: Se requiere que la aplicación mantenga un nivel de disponibilidad mínimo del 99% durante el horario operativo, garantizando su acceso y uso continuo por parte de los usuarios.
A16: Identificador del escenario de calidad: | D16: ESC-CAL-CONFI-0002
A17: Nombre del escenario de calidad: | D17: Gestión de interrupciones imprevistas durante el horario operativo
A18: Tipo escenario: | D18: Alternativo
A19: Objetivo | D19: Asegurar que, en caso de presentarse interrupciones o caídas del servicio durante el horario operativo, el sistema pueda detectarlas, registrarlas y restaurar su funcionamiento en el menor tiempo posible.
A20: Descripción: | D20: Escenario donde ocurre una interrupción imprevista del servicio causada por fallas en el servidor, red o base de datos. El contenedor del servicio se reinicia automáticamente vía Docker restart policy, y el sistema restablece la operación normal para los usuarios.
A21: Criterio de éxito: | D21: El sistema detecta y recupera su disponibilidad de manera oportuna, garantizando la continuidad del servicio y la integridad de la información.
A22: Fuente del estímulo | C22: Estímulo | E22: Ambiente | G22: Artefacto | I22: Respuesta | K22: Medida de la respuesta | M22: ¿Cumplió? | N22: Tácticas y estrategia
A23: Usuario final | C23: Falla que interrumpe el acceso o funcionamiento normal del sistema. | E23: Operación normal | G23: Sistema | I23: El sistema identifica la interrupción, activa el proceso de recuperación, notifica al personal técnico y restablece el servicio de forma controlada. | K23: Asegura que las interrupciones sean detectadas de inmediato, que la recuperación se realice en el menor tiempo posible y que la estabilidad del sistema se restablezca sin pérdida de datos ni afectación prolongada a los usuarios. | N23: Pruebas de carga y estrés con k6. Reinicio automático del contenedor vía Docker restart policy en Dokploy. Manejo controlado de errores con ErrorHandler middleware.
A25: Atributo de calidad: | D25: =$A$1 -> Confiabilidad
A26: Característica: | D26: Se requiere que la aplicación incorpore mecanismos de tolerancia a fallos que permitan continuar su funcionamiento ante errores parciales o interrupciones de componentes individuales.
A27: Identificador del escenario de calidad: | D27: ESC-CAL-CONFI-0003
A28: Nombre del escenario de calidad: | D28: Operatividad continua ante fallos parciales del sistema
A29: Tipo escenario: | D29: Básico
A30: Objetivo | D30: Garantizar que la aplicación mantenga su funcionamiento general ante la ocurrencia de errores parciales o la interrupción de componentes individuales.
A31: Descripción: | D31: Escenario donde uno o varios módulos o servicios presentan fallas leves o desconexiones temporales. El sistema, mediante sus mecanismos de tolerancia a fallos, detecta el problema y reencamina las operaciones hacia componentes disponibles o ejecuta procesos alternos, manteniendo la estabilidad y continuidad del servicio.
A32: Criterio de éxito: | D32: El sistema continúa operativo y disponible ante errores parciales, sin afectar las funciones críticas ni la experiencia de los usuarios.
A33: Fuente del estímulo | C33: Estímulo | E33: Ambiente | G33: Artefacto | I33: Respuesta | K33: Medida de la respuesta | M33: ¿Cumplió? | N33: Tácticas y estrategia
A34: Configuración automática del sistema | C34: Falla o mal funcionamiento de un componente no crítico dentro del sistema. | E34: Operación normal | G34: Sistema | I34: El sistema detecta el fallo parcial, aplica medidas de contingencia y mantiene su operación normal o con degradación mínima de rendimiento. | K34: El sistema conserva al menos el 95% de sus funciones operativas ante fallas parciales y garantiza la disponibilidad del servicio sin interrupciones completas. | N34: Input Sanitization 100% en POST/PUT. Manejo de errores controlado con Result Container Pattern. Validación por JSON Schema. Mensajes de sistema informativos (Authoritative Backend Messaging).
A36: Atributo de calidad: | D36: =$A$1 -> Confiabilidad
A37: Característica: | D37: Se requiere que la aplicación incorpore mecanismos de tolerancia a fallos que permitan continuar su funcionamiento ante errores parciales o interrupciones de componentes individuales.
A38: Identificador del escenario de calidad: | D38: ESC-CAL-CONFI-0004
A39: Nombre del escenario de calidad: | D39: Recuperación automática ante fallos de componentes críticos
A40: Tipo escenario: | D40: Alternativo
A41: Objetivo | D41: Asegurar que, en caso de una falla crítica en un componente o servicio esencial, la aplicación pueda recuperarse automáticamente mediante el reinicio del contenedor en Dokploy, evitando una caída prolongada del sistema.
A42: Descripción: | D42: Escenario donde un componente clave del sistema, como el servidor backend o la base de datos, presenta una interrupción. El contenedor se reinicia automáticamente vía Dokploy y el sistema restablece las operaciones, garantizando la continuidad del servicio y la integridad de los datos.
A43: Criterio de éxito: | D43: El sistema se recupera automáticamente de la falla, manteniendo la disponibilidad de las funciones críticas y evitando la pérdida de información.
A44: Fuente del estímulo | C44: Estímulo | E44: Ambiente | G44: Artefacto | I44: Respuesta | K44: Medida de la respuesta | M44: ¿Cumplió? | N44: Tácticas y estrategia
...

Sheet ESC-CAL-CONFORMIDAD
A1: Conformidad
A3: Atributo de calidad: | D3: =$A$1 -> Conformidad
A4: Característica: | D4: Se requiere que la aplicación cumpla con las normativas nacionales e internacionales aplicables al tipo de sistema, garantizando su operación dentro del marco legal vigente.
A5: Identificador del escenario de calidad: | D5: ESC-CAL-CONFO-0001
A6: Nombre del escenario de calidad: | D6: Cumplimiento normativo integral del sistema
A7: Tipo escenario: | D7: Básico
A8: Objetivo | D8: Garantizar que la aplicación cumpla con todas las normativas nacionales e internacionales aplicables, operando dentro del marco legal vigente y asegurando la protección de los datos, la transparencia de los procesos y la responsabilidad organizacional.
A9: Descripción: | D9: El sistema debe cumplir con las disposiciones legales y reglamentarias aplicables a su naturaleza, incluyendo leyes de protección de datos personales, propiedad intelectual, accesibilidad, ciberseguridad y transparencia. Se implementan mecanismos técnicos, administrativos y de auditoría que validan la conformidad legal antes, durante y después del despliegue del sistema.
A10: Criterio de éxito: | D10: La aplicación mantiene su conformidad con el 100 % de las normas vigentes y supera satisfactoriamente todas las auditorías internas y externas sin registrar hallazgos críticos.
A11: Fuente del estímulo | C11: Estímulo | E11: Ambiente | G11: Artefacto | I11: Respuesta | K11: Medida de la respuesta | M11: ¿Cumplió? | N11: Tácticas y estrategia
A12: Auditor interno o externo, entidad reguladora o área de cumplimiento normativo. | C12: Se realiza una revisión o auditoría del sistema para verificar el cumplimiento de las regulaciones aplicables. | E12: Operación normal | G12: Sistema | I12: El sistema demuestra cumplimiento con las normas aplicables, proporciona la documentación requerida, evidencia trazabilidad de los procesos y garantiza que su operación se ajusta a las disposiciones legales vigentes. | K12: Se asegura que la aplicación cumple los requisitos legales y normativos aplicables, dispone de la documentación de soporte actualizada y mantiene trazabilidad verificable en auditorías internas o externas. | N12: Cumplimiento regulatorio: Ley 1581 de 2012 (protección de datos), control de accesos con JWT + RBAC, cifrado de contraseñas bcrypt. Versionamiento semántico con Git Flow. Documentación Swagger/OpenAPI (Documentation Parity).
A14: Atributo de calidad: | D14: =$A$1 -> Conformidad
A15: Característica: | D15: Se requiere que la aplicación cumpla con las normativas nacionales e internacionales aplicables al tipo de sistema, garantizando su operación dentro del marco legal vigente.
A16: Identificador del escenario de calidad: | D16: ESC-CAL-CONFO-0002
A17: Nombre del escenario de calidad: | D17: Detección y manejo de incumplimientos normativos
A18: Tipo escenario: | D18: Alternativo
A19: Objetivo | D19: Detectar oportunamente cualquier incumplimiento o desviación respecto a las normativas nacionales e internacionales aplicables, permitiendo tomar acciones correctivas inmediatas para restablecer la conformidad legal y operativa del sistema.
A20: Descripción: | D20: Escenario en el que se identifica una posible infracción o incumplimiento normativo (por ejemplo, tratamiento inadecuado de datos personales, falta de consentimiento, almacenamiento no autorizado de información sensible o ausencia de trazabilidad en las operaciones). El sistema o los mecanismos de auditoría detectan la desviación, notifican al responsable de cumplimiento y bloquean las operaciones que impliquen riesgo legal hasta su corrección. Se generan reportes detallados para las áreas técnicas y legales.
A21: Criterio de éxito: | D21: Los incumplimientos normativos se detectan de forma temprana, las operaciones de riesgo son bloqueadas o suspendidas, y se activan los procedimientos de corrección sin afectar la integridad o disponibilidad del sistema.
A22: Fuente del estímulo | C22: Estímulo | E22: Ambiente | G22: Artefacto | I22: Respuesta | K22: Medida de la respuesta | M22: ¿Cumplió? | N22: Tácticas y estrategia
A23: Usuario final | C23: Se detecta un proceso o módulo que no cumple con la normativa vigente (por ejemplo, falta de consentimiento expreso del usuario o transferencia de datos a jurisdicciones no permitidas). | E23: Operación normal | G23: Sistema | I23: El sistema genera una alerta, bloquea temporalmente la funcionalidad afectada, registra el evento en los logs con detalle (fecha, hora, responsable, causa), y notifica a los responsables legales y técnicos. Se inician procedimientos automáticos o manuales de mitigación y se actualiza el estado de cumplimiento tras la corrección. | K23: El tiempo de detección del incumplimiento no supera los 10 segundos desde su ocurrencia; la mitigación se inicia en menos de 1 hora; y el 100 % de los eventos quedan registrados con trazabilidad completa y evidencia de cierre. | N23: Auditorías periódicas de cumplimiento. Control de licencias de dependencias (go.mod). Trazabilidad de cambios con conventional commits y releases documentados.
A25: Atributo de calidad: | D25: =$A$1 -> Conformidad
A26: Característica: | D26: Se requiere que la aplicación respete las leyes de protección de datos personales (como la Ley 1581 de 2012 en Colombia o el RGPD en Europa), asegurando el tratamiento ético y seguro de la información.
A27: Identificador del escenario de calidad: | D27: ESC-CAL-CONFO-0009
A28: Nombre del escenario de calidad: | D28: Cumplimiento normativo en el tratamiento de datos personales
A29: Tipo escenario: | D29: Básico
A30: Objetivo | D30: Garantizar que la aplicación cumpla con las leyes y normativas vigentes sobre protección de datos personales (como la Ley 1581 de 2012 en Colombia o el RGPD en Europa), promoviendo el tratamiento ético, seguro y transparente de la información de los usuarios.
A31: Descripción: | D31: Escenario donde la aplicación recolecta, almacena o procesa datos personales de usuarios. El sistema debe garantizar que dichos datos sean tratados conforme a los principios de legalidad, finalidad, libertad, veracidad, transparencia, acceso y seguridad. Cualquier operación sobre la información debe realizarse bajo consentimiento informado y mecanismos de protección adecuados, evitando accesos no autorizados o usos indebidos.
A32: Criterio de éxito: | D32: El tratamiento de datos personales cumple con las normativas aplicables y las políticas internas de privacidad, sin que se presenten incidentes de uso indebido, filtración o pérdida de información.
A33: Fuente del estímulo | C33: Estímulo | E33: Ambiente | G33: Artefacto | I33: Respuesta | K33: Medida de la respuesta | M33: ¿Cumplió? | N33: Tácticas y estrategia
A34: Autoridades regulatorias, área jurídica, usuarios finales o auditores internos. | C34: Solicitud de acceso, modificación o eliminación de datos personales, o auditoría de cumplimiento legal relacionada con la protección de información. | E34: Operación normal | G34: Sistema | I34: El sistema gestiona los datos conforme a las leyes de protección de datos, garantizando mecanismos de consentimiento, rectificación, eliminación y acceso por parte del titular. Además, implementa controles de seguridad (encriptación, anonimización y auditoría) y genera evidencia verificable de cumplimiento. | K34: Se puede asegurar que el 100 % de los datos personales tratados cuentan con consentimiento documentado, que las solicitudes de los titulares se gestionan en un plazo máximo de 5 días hábiles, y que no se registran incidentes de seguridad o sanciones legales derivadas del incumplimiento de las normas de protección de datos. | N34: Cumplimiento regulatorio: Ley 1581 de 2012 (protección de datos), control de accesos con JWT + RBAC, cifrado de contraseñas bcrypt. Versionamiento semántico con Git Flow. Documentación Swagger/OpenAPI (Documentation Parity).
A36: Atributo de calidad: | D36: =$A$1 -> Conformidad
A37: Característica: | D37: Se requiere que la aplicación respete las leyes de protección de datos personales (como la Ley 1581 de 2012 en Colombia o el RGPD en Europa), asegurando el tratamiento ético y seguro de la información.
A38: Identificador del escenario de calidad: | D38: ESC-CAL-CONFO-0010
A39: Nombre del escenario de calidad: | D39: Auditoría y trazabilidad de operaciones sensibles
A40: Tipo escenario: | D40: Alternativo
A41: Objetivo | D41: Garantizar que todas las operaciones críticas realizadas en la aplicación queden registradas de forma íntegra, verificable y accesible para auditoría, permitiendo la trazabilidad completa de acciones sobre los datos y configuraciones del sistema.
A42: Descripción: | D42: Escenario donde la aplicación ejecuta operaciones sensibles, como modificaciones de información, cambios de configuración, o accesos privilegiados. El sistema debe generar registros detallados (logs) que incluyan usuario, acción, fecha, hora, resultado y contexto. Estos registros deben ser inmutables, protegidos contra alteraciones y disponibles para revisión durante auditorías internas o externas.
A43: Criterio de éxito: | D43: Todas las operaciones sensibles se registran automáticamente con integridad comprobada y disponibilidad para consulta dentro de los periodos de retención definidos por la organización o la normativa aplicable.
A44: Fuente del estímulo | C44: Estímulo | E44: Ambiente | G44: Artefacto | I44: Respuesta | K44: Medida de la respuesta | M44: ¿Cumplió? | N44: Tácticas y estrategia
...

Sheet ESC-CAL-DISPONIBILIDAD
A1: Disponibilidad
A3: Atributo de calidad: | D3: =$A$1 -> Disponibilidad
A4: Característica: | D4: Se requiere que la aplicación mantenga un nivel de disponibilidad mínimo del 99% durante los periodos de operación, garantizando su acceso continuo por parte de los usuarios.
A5: Identificador del escenario de calidad: | D5: ESC-CAL-DISP-0001
A6: Nombre del escenario de calidad: | D6: Mantenimiento de alta disponibilidad del sistema
A7: Tipo escenario: | D7: Básico
A8: Objetivo | D8: Garantizar que la aplicación mantenga un nivel de disponibilidad mínimo del 99 % durante los periodos de operación, asegurando el acceso continuo de los usuarios sin interrupciones significativas del servicio.
A9: Descripción: | D9: Escenario donde la aplicación opera de manera estable en condiciones normales, soportando las solicitudes de los usuarios sin degradación del servicio. El sistema utiliza un servidor stateless basado en JWT que no almacena sesiones en memoria, facilitando la disponibilidad del servicio.
A10: Criterio de éxito: | D10: La aplicación permanece disponible y funcional durante al menos el 99 % del tiempo de operación mensual, sin interrupciones críticas que impidan el acceso o uso normal por parte de los usuarios.
A11: Fuente del estímulo | C11: Estímulo | E11: Ambiente | G11: Artefacto | I11: Respuesta | K11: Medida de la respuesta | M11: ¿Cumplió? | N11: Tácticas y estrategia
A12: Usuarios finales o sistemas dependientes que acceden a la aplicación. | C12: Solicitudes de acceso, consulta o interacción con el sistema durante su operación normal. | E12: Operación normal | G12: Sistema | I12: El sistema procesa las solicitudes de los usuarios de forma continua, mantiene el servicio operativo mediante un esquema stateless con JWT, y verifica su estado a través del endpoint /health. | K12: Se puede asegurar que la aplicación mantiene una disponibilidad superior al 99 % en los periodos de operación, que las interrupciones no superan los 7 horas mensuales, y que los eventos de indisponibilidad se registran y analizan para mejora continua. | N12: Endpoint /health para verificación de estado del servicio. Servidor stateless con JWT que permite disponibilidad sin sesiones en memoria. Pruebas de carga y estrés con k6 para validar capacidad.

Sheet ESC-CAL-EXPERIENCIA DE USUARIO
A1: Experiencia de Usuario
A3: Atributo de calidad: | D3: =$A$1 -> Experiencia de Usuario
A4: Característica: | D4: Se requiere que la aplicación cuente con una interfaz clara, sencilla e intuitiva, que permita a los usuarios comprender y ejecutar sus tareas sin necesidad de capacitación previa.
A5: Identificador del escenario de calidad: | D5: ESC-CAL-EXPU-0001
A6: Nombre del escenario de calidad: | D6: Interfaz intuitiva y fácil de usar
A7: Tipo escenario: | D7: Básico
A8: Objetivo | D8: Garantizar que los usuarios puedan entender y utilizar la aplicación fácilmente, sin necesidad de recibir capacitación o instrucciones adicionales.
A9: Descripción: | D9: Escenario donde un usuario ingresa por primera vez a la aplicación para realizar una tarea (por ejemplo, registrar un dato, buscar información o usar una función principal). La interfaz presenta los elementos de forma clara, con botones, íconos y textos comprensibles. El usuario puede completar su tarea sin dificultad y sin requerir asistencia.
A10: Criterio de éxito: | D10: El usuario logra realizar la tarea correctamente en su primer intento, sin confusión ni errores.
A11: Fuente del estímulo | C11: Estímulo | E11: Ambiente | G11: Artefacto | I11: Respuesta | K11: Medida de la respuesta | M11: ¿Cumplió? | N11: Tácticas y estrategia
A12: Usuario nuevo o con poca experiencia. | C12: Interacción inicial del usuario con la aplicación. | E12: Operación normal | G12: Sistema | I12: La aplicación guía al usuario de forma natural, mostrando instrucciones claras y retroalimentación inmediata ante cada acción. | K12: Se asegura que un usuario nuevo pueda completar una tarea básica sin ayuda y en menos de 3 minutos, demostrando comprensión del uso de la aplicación desde el primer intento. | N12: Flutter con Material Design 3 para interfaz clara e intuitiva. Zero Hardcoding Policy (Feature-Based Constants). One Event One Message para feedback claro. Adaptive Data Display Pattern (tabla/cards). Validaciones inline en formularios.
A14: Atributo de calidad: | D14: =$A$1 -> Experiencia de Usuario
A15: Característica: | D15: Se requiere que la aplicación cuente con una interfaz clara, sencilla e intuitiva, que permita a los usuarios comprender y ejecutar sus tareas sin necesidad de capacitación previa.
A16: Identificador del escenario de calidad: | D16: ESC-CAL-EXPU-0002
A17: Nombre del escenario de calidad: | D17: Prevención y corrección de errores por confusión en la interfaz
A18: Tipo escenario: | D18: Alternativo
A19: Objetivo | D19: Reducir los errores del usuario ocasionados por confusión o mala interpretación de los elementos visuales, proporcionando mensajes claros que lo ayuden a corregir sus acciones.
A20: Descripción: | D20: Escenario donde un usuario intenta realizar una tarea y comete un error debido a una interpretación incorrecta de los botones, campos o mensajes en pantalla (por ejemplo, presionar el botón equivocado o ingresar información en el lugar incorrecto). El sistema detecta la acción, muestra una explicación clara del error y guía al usuario para corregirlo sin perder su progreso.
A21: Criterio de éxito: | D21: El usuario comprende el motivo del error y logra completar la tarea después de recibir la orientación del sistema, sin necesitar asistencia externa.
A22: Fuente del estímulo | C22: Estímulo | E22: Ambiente | G22: Artefacto | I22: Respuesta | K22: Medida de la respuesta | M22: ¿Cumplió? | N22: Tácticas y estrategia
A23: Usuario que comete un error durante la interacción con la aplicación. | C23: Acción incorrecta o incompleta realizada dentro de la aplicación (por ejemplo, dejar un campo vacío o usar un formato no válido). | E23: Operación normal | G23: Sistema | I23: La aplicación muestra un mensaje claro indicando el error y cómo solucionarlo, mantiene los datos que el usuario ya ingresó y le permite continuar sin tener que empezar de nuevo. | K23: Se asegura que el mensaje de corrección aparece en menos de 2 segundos, que el usuario entiende cómo resolver el problema y logra completar la tarea sin repetir el error. | N23: Ciclos de mejora basados en retroalimentación UX. Standard/Destruction Guard Confirmation Dialogs. Post-Success Automatic Redirection. Corrección de inconsistencias visuales con hot reload.
A25: Atributo de calidad: | D25: =$A$1 -> Experiencia de Usuario
A26: Característica: | D26: Se requiere que la aplicación mantenga coherencia en sus elementos visuales, iconografía, tipografía y comportamientos interactivos en todas sus secciones.
A27: Identificador del escenario de calidad: | D27: ESC-CAL-EXPU-0003
A28: Nombre del escenario de calidad: | D28: Coherencia visual e interactiva en toda la aplicación
A29: Tipo escenario: | D29: Básico
A30: Objetivo | D30: Garantizar que la aplicación mantenga una apariencia uniforme y un comportamiento coherente en todas sus pantallas, facilitando la comprensión y el uso por parte del usuario.
A31: Descripción: | D31: Escenario donde el usuario navega por diferentes secciones de la aplicación (inicio, perfil, ayuda, configuración) y encuentra los mismos estilos visuales, íconos, colores, tipografías y comportamientos en botones, menús o formularios. Esta coherencia permite que el usuario reconozca los elementos fácilmente y use la aplicación sin confusión.
A32: Criterio de éxito: | D32: El usuario puede moverse entre distintas secciones sin notar cambios bruscos de diseño ni comportamiento, comprendiendo de inmediato cómo interactuar con cada parte.
A33: Fuente del estímulo | C33: Estímulo | E33: Ambiente | G33: Artefacto | I33: Respuesta | K33: Medida de la respuesta | M33: ¿Cumplió? | N33: Tácticas y estrategia
A34: Usuario navegando por distintas secciones de la aplicación. | C34: Cambio de sección o función dentro de la aplicación. | E34: Operación normal | G34: Sistema | I34: La aplicación mantiene una apariencia visual coherente y los mismos patrones de interacción en todas las pantallas, reforzando la experiencia del usuario. | K34: Se asegura que el diseño y el comportamiento de los elementos sean consistentes en el 100 % de las pantallas, sin variaciones que confundan al usuario. | N34: Flutter con Material Design 3 para interfaz clara e intuitiva. Zero Hardcoding Policy (Feature-Based Constants). One Event One Message para feedback claro. Adaptive Data Display Pattern (tabla/cards). Validaciones inline en formularios.
A36: Atributo de calidad: | D36: =$A$1 -> Experiencia de Usuario
A37: Característica: | D37: Se requiere que la aplicación mantenga coherencia en sus elementos visuales, iconografía, tipografía y comportamientos interactivos en todas sus secciones.
A38: Identificador del escenario de calidad: | D38: ESC-CAL-EXPU-0004
A39: Nombre del escenario de calidad: | D39: Corrección de incoherencias visuales o de comportamiento
A40: Tipo escenario: | D40: Alternativo
A41: Objetivo | D41: Detectar y corregir posibles diferencias de diseño o comportamiento entre secciones, evitando que el usuario experimente confusión o errores de navegación.
A42: Descripción: | D42: Escenario donde se detectan diferencias en los estilos visuales o en la forma en que ciertos elementos funcionan (por ejemplo, botones con distinto color o comportamiento en páginas similares). El equipo de diseño o soporte las identifica y aplica correcciones para unificar la apariencia y la experiencia de uso.
A43: Criterio de éxito: | D43: Las incoherencias son detectadas y corregidas sin afectar la navegación ni generar errores en otras partes del sistema.
A44: Fuente del estímulo | C44: Estímulo | E44: Ambiente | G44: Artefacto | I44: Respuesta | K44: Medida de la respuesta | M44: ¿Cumplió? | N44: Tácticas y estrategia
...

Sheet ESC-CAL-RENDIMIENTO
A1: Rendimiento
A2: Atributo de calidad: | D2: Rendimiento
A3: Característica: | D3: Se requiere que la aplicación cargue rápidamente y responda sin demoras a las acciones del usuario (menor a 2 segundos).
A4: Identificador del escenario de calidad: | D4: ESC-CAL-REN-0001
A5: Nombre del escenario de calidad: | D5: Tiempo de respuesta óptimo en la interacción del usuario
A6: Tipo escenario: | D6: Básico
A7: Objetivo | D7: Garantizar que la aplicación responda de forma rápida y fluida a las acciones del usuario, mejorando la experiencia de uso y evitando tiempos de espera perceptibles.
A8: Descripción: | D8: Escenario donde el usuario realiza una acción dentro de la aplicación (por ejemplo, abrir una página, enviar un formulario o consultar datos). El sistema procesa la solicitud y muestra la respuesta en pantalla sin demoras notorias, manteniendo la fluidez en la interacción.
A9: Criterio de éxito: | D9: El tiempo de carga o respuesta ante cualquier acción del usuario no supera los 2 segundos.
A10: Fuente del estímulo | C10: Estímulo | E10: Ambiente | G10: Artefacto | I10: Respuesta | K10: Medida de la respuesta | M10: ¿Cumplió? | N10: Tácticas y estrategia
A11: Usuario final. | C11: Interacción directa del usuario con la interfaz (clic, toque, consulta o navegación). | E11: Operación normal | G11: Sistema | I11: El sistema procesa la acción y muestra el resultado en pantalla sin retrasos perceptibles, garantizando una navegación fluida. | K11: Se asegura que el tiempo promedio de respuesta a las acciones del usuario sea menor o igual a 2 segundos en el 95 % de las operaciones realizadas bajo condiciones normales. | N11: Tiempo de respuesta API menor a 2 segundos. Queries SQL optimizadas con JOINs para evitar consultas N+1. In-Memory Caching Pattern en DataSources Flutter. Filtrado local en listados.
A13: Atributo de calidad: | D13: Rendimiento
A14: Característica: | D14: Se requiere que la aplicación cargue rápidamente y responda sin demoras a las acciones del usuario (menor a 2 segundos).
A15: Identificador del escenario de calidad: | D15: ESC-CAL-REN-0002
A16: Nombre del escenario de calidad: | D16: Manejo eficiente de demoras o sobrecarga en el tiempo de respuesta
A17: Tipo escenario: | D17: Alternativo
A18: Objetivo | D18: Minimizar el impacto en la experiencia del usuario cuando se presenten demoras ocasionales por alta carga del sistema o lentitud en la red.
A19: Descripción: | D19: Escenario donde el usuario ejecuta una acción mientras el sistema experimenta un pico de carga o una conexión de red lenta. La aplicación gestiona la situación mostrando indicadores de progreso o mensajes informativos para mantener la percepción de fluidez.
A20: Criterio de éxito: | D20: El sistema mantiene su estabilidad y comunica al usuario el estado de la acción sin generar frustración ni errores aparentes.
A21: Fuente del estímulo | C21: Estímulo | E21: Ambiente | G21: Artefacto | I21: Respuesta | K21: Medida de la respuesta | M21: ¿Cumplió? | N21: Tácticas y estrategia
A22: Usuario final o condiciones de red adversas. | C22: Ejecución de acciones durante una sobrecarga del sistema o ralentización temporal. | E22: Operación normal | G22: Sistema | I22: El sistema muestra mensajes de espera o carga visual, evita bloqueos y completa la acción tan pronto como los recursos lo permiten. | K22: Se asegura que ante demoras superiores a 2 segundos, el sistema notifique visualmente al usuario en menos de 1 segundo, manteniendo la estabilidad y sin pérdida de información. | N22: Queries SQL con JOINs para evitar consultas N+1. In-Memory Caching en Flutter para reducir llamadas de red. Pruebas de carga y estrés con k6.
A24: Atributo de calidad: | D24: Rendimiento
A25: Característica: | D25: Se requiere que el tiempo de espera entre pantallas o procesos sea mínimo para mantener una buena experiencia de uso.
A26: Identificador del escenario de calidad: | D26: ESC-CAL-REN-0005
A27: Nombre del escenario de calidad: | D27: Minimización del tiempo de espera entre pantallas o procesos
A28: Tipo escenario: | D28: Básico
A29: Objetivo | D29: Garantizar que las transiciones entre pantallas o procesos se realicen de manera ágil, reduciendo los tiempos de espera y mejorando la experiencia del usuario.
A30: Descripción: | D30: Escenario donde el usuario navega entre diferentes pantallas o ejecuta procesos dentro de la aplicación (por ejemplo, carga de datos o consulta de información). El sistema optimiza el procesamiento y la transferencia de datos para que las transiciones sean rápidas y fluidas.
A31: Criterio de éxito: | D31: El tiempo de carga o cambio entre pantallas no supera los 2 segundos bajo condiciones normales de operación.
A32: Fuente del estímulo | C32: Estímulo | E32: Ambiente | G32: Artefacto | I32: Respuesta | K32: Medida de la respuesta | M32: ¿Cumplió? | N32: Tácticas y estrategia
A33: Usuario final. | C33: Interacción del usuario que desencadena una transición de pantalla o ejecución de un proceso. | E33: Operación normal | G33: Sistema | I33: El sistema procesa la solicitud y muestra la nueva pantalla o resultado del proceso de forma fluida, sin interrupciones ni retardos perceptibles. | K33: Se asegura que el 95 % de las transiciones entre pantallas o procesos se ejecuten en menos de 2 segundos, manteniendo una experiencia fluida y continua para el usuario. | N33: Tiempo de respuesta API menor a 2 segundos. Queries SQL optimizadas con JOINs para evitar consultas N+1. In-Memory Caching Pattern en DataSources Flutter. Filtrado local en listados.
A35: Atributo de calidad: | D35: Rendimiento
A36: Característica: | D36: Se requiere que el tiempo de espera entre pantallas o procesos sea mínimo para mantener una buena experiencia de uso.
A37: Identificador del escenario de calidad: | D37: ESC-CAL-REN-0006
A38: Nombre del escenario de calidad: | D38: Gestión de demoras durante la carga de pantallas o procesos
A39: Tipo escenario: | D39: Alternativo
A40: Objetivo | D40: Evitar frustración o pérdida de interacción cuando se presenten tiempos de espera prolongados, mostrando indicadores visuales o mensajes informativos al usuario.
A41: Descripción: | D41: Escenario donde la carga de una pantalla o proceso tarda más de lo esperado debido a una conexión lenta o alta demanda del sistema. La aplicación muestra un indicador de progreso o mensaje de espera que mantiene informado al usuario y evita cierres inesperados o reintentos innecesarios.
A42: Criterio de éxito: | D42: El usuario comprende que el sistema sigue procesando su solicitud, sin percibir fallos ni pérdida de control.
A43: Fuente del estímulo | C43: Estímulo | E43: Ambiente | G43: Artefacto | I43: Respuesta | K43: Medida de la respuesta | M43: ¿Cumplió? | N43: Tácticas y estrategia
...

Sheet ESC-CAL-SEGURIDAD
A1: Seguridad
A3: Atributo de calidad: | D3: Seguridad
A4: Característica: | D4: Se requiere que la aplicación proteja la información personal de los usuarios frente a accesos no autorizados.
A5: Identificador del escenario de calidad: | D5: ESC-CAL-SEG-0001
A6: Nombre del escenario de calidad: | D6: Protección de la información personal frente a accesos no autorizados
A7: Tipo escenario: | D7: Básico
A8: Objetivo | D8: Garantizar que la información personal de los usuarios esté protegida y solo pueda ser vista o modificada por quienes tengan permiso.
A9: Descripción: | D9: Escenario donde un usuario accede a la aplicación e ingresa datos personales como nombre, correo o contraseña. El sistema guarda esta información de manera segura y verifica que solo el propio usuario o personal autorizado puedan consultarla o modificarla, evitando que terceros accedan sin permiso.
A10: Criterio de éxito: | D10: La información personal se mantiene segura y solo es accesible mediante credenciales válidas.
A11: Fuente del estímulo | C11: Estímulo | E11: Ambiente | G11: Artefacto | I11: Respuesta | K11: Medida de la respuesta | M11: ¿Cumplió? | N11: Tácticas y estrategia
A12: Usuario final. | C12: Intento de acceso o consulta de información personal del usuario. | E12: Operación normal | G12: Sistema | I12: El sistema valida la identidad del usuario antes de permitir el acceso y protege los datos mediante mecanismos seguros, impidiendo accesos no autorizados. | K12: Se asegura que el 100 % de los accesos a información personal se realicen solo tras una verificación válida de identidad, manteniendo los datos cifrados y protegidos en todo momento. | N12: Autenticación JWT con JWKS validation + RBAC (RequireRole middleware). Contraseñas cifradas con bcrypt. HTTPS obligatorio. Input Sanitization 100% (string trimming). Session timeout automático (Atomic Refresh pattern).
A14: Atributo de calidad: | D14: Seguridad
A15: Característica: | D15: Se requiere que la aplicación proteja la información personal de los usuarios frente a accesos no autorizados.
A16: Identificador del escenario de calidad: | D16: ESC-CAL-SEG-0002
A17: Nombre del escenario de calidad: | D17: Gestión ante intento de acceso no autorizado a información personal
A18: Tipo escenario: | D18: Alternativo
A19: Objetivo: | D19: Evitar que la información personal se vea comprometida en caso de que alguien intente acceder sin permiso.
